<sdf version='1.4'>
  <world name='default'>
    <light name='sun' type='directional'>
      <cast_shadows>1</cast_shadows>
      <pose>2 0 10 0 -0 0</pose>
      <diffuse>0.8 0.8 0.8 1</diffuse>
      <specular>0.2 0.2 0.2 1</specular>
      <attenuation>
        <range>1000</range>
        <constant>0.9</constant>
        <linear>0.01</linear>
        <quadratic>0.001</quadratic>
      </attenuation>
      <direction>-0.5 0.1 -0.9</direction>
    </light>
    <model name='ground_plane'>
      <static>1</static>
      <link name='link'>
        <collision name='collision'>
          <geometry>
            <plane>
              <normal>0 0 1</normal>
              <size>100 100</size>
            </plane>
          </geometry>
          <surface>
            <friction>
              <ode>
                <mu>100</mu>
                <mu2>50</mu2>
              </ode>
            </friction>
            <bounce/>
            <contact>
              <ode/>
            </contact>
          </surface>
          <max_contacts>10</max_contacts>
        </collision>
        <visual name='visual'>
          <cast_shadows>0</cast_shadows>
          <geometry>
            <plane>
              <normal>0 0 1</normal>
              <size>100 100</size>
            </plane>
          </geometry>
          <material>
            <script>
              <uri>file://media/materials/scripts/gazebo.material</uri>
              <name>Gazebo/Grey</name>
            </script>
          </material>
        </visual>
        <velocity_decay>
          <linear>0</linear>
          <angular>0</angular>
        </velocity_decay>
        <self_collide>0</self_collide>
        <kinematic>0</kinematic>
        <gravity>0</gravity>
      </link>
    </model>
    <physics type='ode'>
      <max_step_size>0.001</max_step_size>
      <real_time_factor>1</real_time_factor>
      <real_time_update_rate>1000</real_time_update_rate>
      <gravity>0 0 -9.8</gravity>
    </physics>
    <scene>
      <ambient>0.4 0.4 0.4 1</ambient>
      <background>0.7 0.7 0.7 1</background>
      <shadows>1</shadows>
    </scene>
    <model name='fire_hose_long_curled_1'>
      <pose>4 -3 0.055 0 -0 0</pose>
      <link name='coupling'>
        <inertial>
          <pose>-0.07 0 0 0 -0 0</pose>
          <mass>0.1</mass>
          <inertia>
            <ixx>0.01</ixx>
            <ixy>0</ixy>
            <ixz>0</ixz>
            <iyy>0.01</iyy>
            <iyz>0</iyz>
            <izz>0.01</izz>
          </inertia>
        </inertial>
        <visual name='coupling_vis'>
          <pose>-0.01 0 0 0 -1.57079 0</pose>
          <geometry>
            <mesh>
              <scale>0.4 0.4 0.8</scale>
              <uri>model://fire_hose_long_curled/meshes/coupling_hexagon.dae</uri>
            </mesh>
          </geometry>
          <material>
            <script>
              <uri>model://fire_hose_long_curled/materials/scripts</uri>
              <uri>model://fire_hose_long_curled/materials/textures</uri>
              <name>fire_hose_long_curled/fire_hose_coupling</name>
            </script>
          </material>
        </visual>
        <visual name='attachment_vis'>
          <pose>-0.1225 0 0 0 -1.57079 0</pose>
          <geometry>
            <mesh>
              <uri>model://fire_hose_long_curled/meshes/connector.dae</uri>
            </mesh>
          </geometry>
          <material>
            <script>
              <uri>model://fire_hose_long_curled/materials/scripts</uri>
              <uri>model://fire_hose_long_curled/materials/textures</uri>
              <name>fire_hose_long_curled/fire_hose_red_coupling</name>
            </script>
          </material>
        </visual>
        <velocity_decay>
          <linear>0</linear>
          <angular>0</angular>
        </velocity_decay>
        <self_collide>0</self_collide>
        <kinematic>0</kinematic>
        <gravity>0</gravity>
      </link>
      <link name='link_00'>
        <gravity>0</gravity>
        <pose>0.1 0 0 0 -0 0</pose>
        <inertial>
          <mass>0.1</mass>
          <pose>0.1 0 0 0 -0 0</pose>
          <inertia>
            <ixx>0.01</ixx>
            <ixy>0</ixy>
            <ixz>0</ixz>
            <iyy>0.01</iyy>
            <iyz>0</iyz>
            <izz>0.01</izz>
          </inertia>
        </inertial>
        <visual name='sphere'>
          <geometry>
            <sphere>
              <radius>0.025</radius>
            </sphere>
          </geometry>
          <material>
            <script>
              <uri>model://fire_hose_long_curled/materials/scripts</uri>
              <uri>model://fire_hose_long_curled/materials/textures</uri>
              <name>fire_hose_long_curled/fire_hose_canvas</name>
            </script>
          </material>
        </visual>
        <velocity_decay>
          <linear>0</linear>
          <angular>0</angular>
        </velocity_decay>
        <self_collide>0</self_collide>
        <kinematic>0</kinematic>
      </link>
      <link name='link_01'>
        <gravity>0</gravity>
        <pose>0.1 0 0 0 -0 0</pose>
        <inertial>
          <mass>0.1</mass>
          <pose>0.1 0 0 0 -0 0</pose>
          <inertia>
            <ixx>0.01</ixx>
            <ixy>0</ixy>
            <ixz>0</ixz>
            <iyy>0.01</iyy>
            <iyz>0</iyz>
            <izz>0.01</izz>
          </inertia>
        </inertial>
        <visual name='visual'>
          <pose>0.1 0 0 0 1.57079 0</pose>
          <geometry>
            <cylinder>
              <length>0.2</length>
              <radius>0.025</radius>
            </cylinder>
          </geometry>
          <material>
            <script>
              <uri>model://fire_hose_long_curled/materials/scripts</uri>
              <uri>model://fire_hose_long_curled/materials/textures</uri>
              <name>fire_hose_long_curled/fire_hose_canvas</name>
            </script>
          </material>
        </visual>
        <velocity_decay>
          <linear>0</linear>
          <angular>0</angular>
        </velocity_decay>
        <self_collide>0</self_collide>
        <kinematic>0</kinematic>
      </link>
      <link name='link_02'>
        <gravity>0</gravity>
        <pose>0.3 0 0 0 -0 0</pose>
        <inertial>
          <mass>0.1</mass>
          <pose>0.1 0 0 0 -0 0</pose>
          <inertia>
            <ixx>0.01</ixx>
            <ixy>0</ixy>
            <ixz>0</ixz>
            <iyy>0.01</iyy>
            <iyz>0</iyz>
            <izz>0.01</izz>
          </inertia>
        </inertial>
        <visual name='visual'>
          <pose>0.1 0 0 0 1.57079 0</pose>
          <geometry>
            <cylinder>
              <length>0.2</length>
              <radius>0.025</radius>
            </cylinder>
          </geometry>
          <material>
            <script>
              <uri>model://fire_hose_long_curled/materials/scripts</uri>
              <uri>model://fire_hose_long_curled/materials/textures</uri>
              <name>fire_hose_long_curled/fire_hose_canvas</name>
            </script>
          </material>
        </visual>
        <visual name='sphere'>
          <geometry>
            <sphere>
              <radius>0.025</radius>
            </sphere>
          </geometry>
          <material>
            <script>
              <uri>model://fire_hose_long_curled/materials/scripts</uri>
              <uri>model://fire_hose_long_curled/materials/textures</uri>
              <name>fire_hose_long_curled/fire_hose_canvas</name>
            </script>
          </material>
        </visual>
        <velocity_decay>
          <linear>0</linear>
          <angular>0</angular>
        </velocity_decay>
        <self_collide>0</self_collide>
        <kinematic>0</kinematic>
      </link>
      <link name='link_03'>
        <gravity>0</gravity>
        <pose>0.5 0 0 0 -0 0</pose>
        <inertial>
          <mass>0.1</mass>
          <pose>0.1 0 0 0 -0 0</pose>
          <inertia>
            <ixx>0.01</ixx>
            <ixy>0</ixy>
            <ixz>0</ixz>
            <iyy>0.01</iyy>
            <iyz>0</iyz>
            <izz>0.01</izz>
          </inertia>
        </inertial>
        <visual name='visual'>
          <pose>0.1 0 0 0 1.57079 0</pose>
          <geometry>
            <cylinder>
              <length>0.2</length>
              <radius>0.025</radius>
            </cylinder>
          </geometry>
          <material>
            <script>
              <uri>model://fire_hose_long_curled/materials/scripts</uri>
              <uri>model://fire_hose_long_curled/materials/textures</uri>
              <name>fire_hose_long_curled/fire_hose_canvas</name>
            </script>
          </material>
        </visual>
        <visual name='sphere'>
          <geometry>
            <sphere>
              <radius>0.025</radius>
            </sphere>
          </geometry>
          <material>
            <script>
              <uri>model://fire_hose_long_curled/materials/scripts</uri>
              <uri>model://fire_hose_long_curled/materials/textures</uri>
              <name>fire_hose_long_curled/fire_hose_canvas</name>
            </script>
          </material>
        </visual>
        <velocity_decay>
          <linear>0</linear>
          <angular>0</angular>
        </velocity_decay>
        <self_collide>0</self_collide>
        <kinematic>0</kinematic>
      </link>
      <link name='link_04'>
        <gravity>0</gravity>
        <pose>0.7 0 0 0 -0 0</pose>
        <inertial>
          <mass>0.1</mass>
          <pose>0.1 0 0 0 -0 0</pose>
          <inertia>
            <ixx>0.01</ixx>
            <ixy>0</ixy>
            <ixz>0</ixz>
            <iyy>0.01</iyy>
            <iyz>0</iyz>
            <izz>0.01</izz>
          </inertia>
        </inertial>
        <visual name='visual'>
          <pose>0.1 0 0 0 1.57079 0</pose>
          <geometry>
            <cylinder>
              <length>0.2</length>
              <radius>0.025</radius>
            </cylinder>
          </geometry>
          <material>
            <script>
              <uri>model://fire_hose_long_curled/materials/scripts</uri>
              <uri>model://fire_hose_long_curled/materials/textures</uri>
              <name>fire_hose_long_curled/fire_hose_canvas</name>
            </script>
          </material>
        </visual>
        <visual name='sphere'>
          <geometry>
            <sphere>
              <radius>0.025</radius>
            </sphere>
          </geometry>
          <material>
            <script>
              <uri>model://fire_hose_long_curled/materials/scripts</uri>
              <uri>model://fire_hose_long_curled/materials/textures</uri>
              <name>fire_hose_long_curled/fire_hose_canvas</name>
            </script>
          </material>
        </visual>
        <velocity_decay>
          <linear>0</linear>
          <angular>0</angular>
        </velocity_decay>
        <self_collide>0</self_collide>
        <kinematic>0</kinematic>
      </link>
      <link name='link_05'>
        <gravity>0</gravity>
        <pose>0.9 0 0 0 -0 0</pose>
        <inertial>
          <mass>0.1</mass>
          <pose>0.1 0 0 0 -0 0</pose>
          <inertia>
            <ixx>0.01</ixx>
            <ixy>0</ixy>
            <ixz>0</ixz>
            <iyy>0.01</iyy>
            <iyz>0</iyz>
            <izz>0.01</izz>
          </inertia>
        </inertial>
        <visual name='visual'>
          <pose>0.1 0 0 0 1.57079 0</pose>
          <geometry>
            <cylinder>
              <length>0.2</length>
              <radius>0.025</radius>
            </cylinder>
          </geometry>
          <material>
            <script>
              <uri>model://fire_hose_long_curled/materials/scripts</uri>
              <uri>model://fire_hose_long_curled/materials/textures</uri>
              <name>fire_hose_long_curled/fire_hose_canvas</name>
            </script>
          </material>
        </visual>
        <visual name='sphere'>
          <geometry>
            <sphere>
              <radius>0.025</radius>
            </sphere>
          </geometry>
          <material>
            <script>
              <uri>model://fire_hose_long_curled/materials/scripts</uri>
              <uri>model://fire_hose_long_curled/materials/textures</uri>
              <name>fire_hose_long_curled/fire_hose_canvas</name>
            </script>
          </material>
        </visual>
        <velocity_decay>
          <linear>0</linear>
          <angular>0</angular>
        </velocity_decay>
        <self_collide>0</self_collide>
        <kinematic>0</kinematic>
      </link>
      <link name='link_06'>
        <gravity>0</gravity>
        <pose>1.1 0 0 0 0 -0.785</pose>
        <inertial>
          <mass>0.1</mass>
          <pose>0.0875 0 0 0 -0 0</pose>
          <inertia>
            <ixx>0.01</ixx>
            <ixy>0</ixy>
            <ixz>0</ixz>
            <iyy>0.01</iyy>
            <iyz>0</iyz>
            <izz>0.01</izz>
          </inertia>
        </inertial>
        <visual name='visual'>
          <pose>0.0875 0 0 0 1.57079 0</pose>
          <geometry>
            <cylinder>
              <length>0.175</length>
              <radius>0.025</radius>
            </cylinder>
          </geometry>
          <material>
            <script>
              <uri>model://fire_hose_long_curled/materials/scripts</uri>
              <uri>model://fire_hose_long_curled/materials/textures</uri>
              <name>fire_hose_long_curled/fire_hose_canvas</name>
            </script>
          </material>
        </visual>
        <visual name='sphere'>
          <geometry>
            <sphere>
              <radius>0.025</radius>
            </sphere>
          </geometry>
          <material>
            <script>
              <uri>model://fire_hose_long_curled/materials/scripts</uri>
              <uri>model://fire_hose_long_curled/materials/textures</uri>
              <name>fire_hose_long_curled/fire_hose_canvas</name>
            </script>
          </material>
        </visual>
        <velocity_decay>
          <linear>0</linear>
          <angular>0</angular>
        </velocity_decay>
        <self_collide>0</self_collide>
        <kinematic>0</kinematic>
      </link>
      <link name='link_07'>
        <gravity>0</gravity>
        <pose>1.227 -0.127 0 0 0 -2.3415</pose>
        <inertial>
          <mass>0.1</mass>
          <pose>0.0875 0 0 0 -0 0</pose>
          <inertia>
            <ixx>0.01</ixx>
            <ixy>0</ixy>
            <ixz>0</ixz>
            <iyy>0.01</iyy>
            <iyz>0</iyz>
            <izz>0.01</izz>
          </inertia>
        </inertial>
        <visual name='visual'>
          <pose>0.0875 0 0 0 1.57079 0</pose>
          <geometry>
            <cylinder>
              <length>0.175</length>
              <radius>0.025</radius>
            </cylinder>
          </geometry>
          <material>
            <script>
              <uri>model://fire_hose_long_curled/materials/scripts</uri>
              <uri>model://fire_hose_long_curled/materials/textures</uri>
              <name>fire_hose_long_curled/fire_hose_canvas</name>
            </script>
          </material>
        </visual>
        <visual name='sphere'>
          <geometry>
            <sphere>
              <radius>0.025</radius>
            </sphere>
          </geometry>
          <material>
            <script>
              <uri>model://fire_hose_long_curled/materials/scripts</uri>
              <uri>model://fire_hose_long_curled/materials/textures</uri>
              <name>fire_hose_long_curled/fire_hose_canvas</name>
            </script>
          </material>
        </visual>
        <velocity_decay>
          <linear>0</linear>
          <angular>0</angular>
        </velocity_decay>
        <self_collide>0</self_collide>
        <kinematic>0</kinematic>
      </link>
      <link name='link_08'>
        <gravity>0</gravity>
        <pose>1.1 -0.254 0 0 0 -3.1415</pose>
        <inertial>
          <mass>0.1</mass>
          <pose>0.1 0 0 0 -0 0</pose>
          <inertia>
            <ixx>0.01</ixx>
            <ixy>0</ixy>
            <ixz>0</ixz>
            <iyy>0.01</iyy>
            <iyz>0</iyz>
            <izz>0.01</izz>
          </inertia>
        </inertial>
        <visual name='visual'>
          <pose>0.1 0 0 0 1.57079 0</pose>
          <geometry>
            <cylinder>
              <length>0.2</length>
              <radius>0.025</radius>
            </cylinder>
          </geometry>
          <material>
            <script>
              <uri>model://fire_hose_long_curled/materials/scripts</uri>
              <uri>model://fire_hose_long_curled/materials/textures</uri>
              <name>fire_hose_long_curled/fire_hose_canvas</name>
            </script>
          </material>
        </visual>
        <visual name='sphere'>
          <geometry>
            <sphere>
              <radius>0.025</radius>
            </sphere>
          </geometry>
          <material>
            <script>
              <uri>model://fire_hose_long_curled/materials/scripts</uri>
              <uri>model://fire_hose_long_curled/materials/textures</uri>
              <name>fire_hose_long_curled/fire_hose_canvas</name>
            </script>
          </material>
        </visual>
        <velocity_decay>
          <linear>0</linear>
          <angular>0</angular>
        </velocity_decay>
        <self_collide>0</self_collide>
        <kinematic>0</kinematic>
      </link>
      <link name='link_09'>
        <gravity>0</gravity>
        <pose>0.9 -0.254 0 0 0 -3.1415</pose>
        <inertial>
          <mass>0.1</mass>
          <pose>0.1 0 0 0 -0 0</pose>
          <inertia>
            <ixx>0.01</ixx>
            <ixy>0</ixy>
            <ixz>0</ixz>
            <iyy>0.01</iyy>
            <iyz>0</iyz>
            <izz>0.01</izz>
          </inertia>
        </inertial>
        <visual name='visual'>
          <pose>0.1 0 0 0 1.57079 0</pose>
          <geometry>
            <cylinder>
              <length>0.2</length>
              <radius>0.025</radius>
            </cylinder>
          </geometry>
          <material>
            <script>
              <uri>model://fire_hose_long_curled/materials/scripts</uri>
              <uri>model://fire_hose_long_curled/materials/textures</uri>
              <name>fire_hose_long_curled/fire_hose_canvas</name>
            </script>
          </material>
        </visual>
        <visual name='sphere'>
          <geometry>
            <sphere>
              <radius>0.025</radius>
            </sphere>
          </geometry>
          <material>
            <script>
              <uri>model://fire_hose_long_curled/materials/scripts</uri>
              <uri>model://fire_hose_long_curled/materials/textures</uri>
              <name>fire_hose_long_curled/fire_hose_canvas</name>
            </script>
          </material>
        </visual>
        <velocity_decay>
          <linear>0</linear>
          <angular>0</angular>
        </velocity_decay>
        <self_collide>0</self_collide>
        <kinematic>0</kinematic>
      </link>
      <link name='link_10'>
        <gravity>0</gravity>
        <pose>0.7 -0.254 0 0 0 -3.1415</pose>
        <inertial>
          <mass>0.1</mass>
          <pose>0.1 0 0 0 -0 0</pose>
          <inertia>
            <ixx>0.01</ixx>
            <ixy>0</ixy>
            <ixz>0</ixz>
            <iyy>0.01</iyy>
            <iyz>0</iyz>
            <izz>0.01</izz>
          </inertia>
        </inertial>
        <visual name='visual'>
          <pose>0.1 0 0 0 1.57079 0</pose>
          <geometry>
            <cylinder>
              <length>0.2</length>
              <radius>0.025</radius>
            </cylinder>
          </geometry>
          <material>
            <script>
              <uri>model://fire_hose_long_curled/materials/scripts</uri>
              <uri>model://fire_hose_long_curled/materials/textures</uri>
              <name>fire_hose_long_curled/fire_hose_canvas</name>
            </script>
          </material>
        </visual>
        <visual name='sphere'>
          <geometry>
            <sphere>
              <radius>0.025</radius>
            </sphere>
          </geometry>
          <material>
            <script>
              <uri>model://fire_hose_long_curled/materials/scripts</uri>
              <uri>model://fire_hose_long_curled/materials/textures</uri>
              <name>fire_hose_long_curled/fire_hose_canvas</name>
            </script>
          </material>
        </visual>
        <velocity_decay>
          <linear>0</linear>
          <angular>0</angular>
        </velocity_decay>
        <self_collide>0</self_collide>
        <kinematic>0</kinematic>
      </link>
      <link name='link_11'>
        <gravity>0</gravity>
        <pose>0.5 -0.254 0 0 0 -3.1415</pose>
        <inertial>
          <mass>0.1</mass>
          <pose>0.1 0 0 0 -0 0</pose>
          <inertia>
            <ixx>0.01</ixx>
            <ixy>0</ixy>
            <ixz>0</ixz>
            <iyy>0.01</iyy>
            <iyz>0</iyz>
            <izz>0.01</izz>
          </inertia>
        </inertial>
        <visual name='visual'>
          <pose>0.1 0 0 0 1.57079 0</pose>
          <geometry>
            <cylinder>
              <length>0.2</length>
              <radius>0.025</radius>
            </cylinder>
          </geometry>
          <material>
            <script>
              <uri>model://fire_hose_long_curled/materials/scripts</uri>
              <uri>model://fire_hose_long_curled/materials/textures</uri>
              <name>fire_hose_long_curled/fire_hose_canvas</name>
            </script>
          </material>
        </visual>
        <visual name='sphere'>
          <geometry>
            <sphere>
              <radius>0.025</radius>
            </sphere>
          </geometry>
          <material>
            <script>
              <uri>model://fire_hose_long_curled/materials/scripts</uri>
              <uri>model://fire_hose_long_curled/materials/textures</uri>
              <name>fire_hose_long_curled/fire_hose_canvas</name>
            </script>
          </material>
        </visual>
        <velocity_decay>
          <linear>0</linear>
          <angular>0</angular>
        </velocity_decay>
        <self_collide>0</self_collide>
        <kinematic>0</kinematic>
      </link>
      <link name='link_12'>
        <gravity>0</gravity>
        <pose>0.3 -0.254 0 0 0 -3.1415</pose>
        <inertial>
          <mass>0.1</mass>
          <pose>0.1 0 0 0 -0 0</pose>
          <inertia>
            <ixx>0.01</ixx>
            <ixy>0</ixy>
            <ixz>0</ixz>
            <iyy>0.01</iyy>
            <iyz>0</iyz>
            <izz>0.01</izz>
          </inertia>
        </inertial>
        <visual name='visual'>
          <pose>0.1 0 0 0 1.57079 0</pose>
          <geometry>
            <cylinder>
              <length>0.2</length>
              <radius>0.025</radius>
            </cylinder>
          </geometry>
          <material>
            <script>
              <uri>model://fire_hose_long_curled/materials/scripts</uri>
              <uri>model://fire_hose_long_curled/materials/textures</uri>
              <name>fire_hose_long_curled/fire_hose_canvas</name>
            </script>
          </material>
        </visual>
        <visual name='sphere'>
          <geometry>
            <sphere>
              <radius>0.025</radius>
            </sphere>
          </geometry>
          <material>
            <script>
              <uri>model://fire_hose_long_curled/materials/scripts</uri>
              <uri>model://fire_hose_long_curled/materials/textures</uri>
              <name>fire_hose_long_curled/fire_hose_canvas</name>
            </script>
          </material>
        </visual>
        <velocity_decay>
          <linear>0</linear>
          <angular>0</angular>
        </velocity_decay>
        <self_collide>0</self_collide>
        <kinematic>0</kinematic>
      </link>
      <link name='link_13'>
        <gravity>0</gravity>
        <pose>0.1 -0.254 0 0 0 -2.356</pose>
        <inertial>
          <mass>0.1</mass>
          <pose>0.0875 0 0 0 -0 0</pose>
          <inertia>
            <ixx>0.01</ixx>
            <ixy>0</ixy>
            <ixz>0</ixz>
            <iyy>0.01</iyy>
            <iyz>0</iyz>
            <izz>0.01</izz>
          </inertia>
        </inertial>
        <visual name='visual'>
          <pose>0.0875 0 0 0 1.57079 0</pose>
          <geometry>
            <cylinder>
              <length>0.175</length>
              <radius>0.025</radius>
            </cylinder>
          </geometry>
          <material>
            <script>
              <uri>model://fire_hose_long_curled/materials/scripts</uri>
              <uri>model://fire_hose_long_curled/materials/textures</uri>
              <name>fire_hose_long_curled/fire_hose_canvas</name>
            </script>
          </material>
        </visual>
        <visual name='sphere'>
          <geometry>
            <sphere>
              <radius>0.025</radius>
            </sphere>
          </geometry>
          <material>
            <script>
              <uri>model://fire_hose_long_curled/materials/scripts</uri>
              <uri>model://fire_hose_long_curled/materials/textures</uri>
              <name>fire_hose_long_curled/fire_hose_canvas</name>
            </script>
          </material>
        </visual>
        <velocity_decay>
          <linear>0</linear>
          <angular>0</angular>
        </velocity_decay>
        <self_collide>0</self_collide>
        <kinematic>0</kinematic>
      </link>
      <link name='link_14'>
        <gravity>0</gravity>
        <pose>-0.027 -0.381 0 0 0 -0.785</pose>
        <inertial>
          <mass>0.1</mass>
          <pose>0.0875 0 0 0 -0 0</pose>
          <inertia>
            <ixx>0.01</ixx>
            <ixy>0</ixy>
            <ixz>0</ixz>
            <iyy>0.01</iyy>
            <iyz>0</iyz>
            <izz>0.01</izz>
          </inertia>
        </inertial>
        <visual name='visual'>
          <pose>0.0875 0 0 0 1.57079 0</pose>
          <geometry>
            <cylinder>
              <length>0.175</length>
              <radius>0.025</radius>
            </cylinder>
          </geometry>
          <material>
            <script>
              <uri>model://fire_hose_long_curled/materials/scripts</uri>
              <uri>model://fire_hose_long_curled/materials/textures</uri>
              <name>fire_hose_long_curled/fire_hose_canvas</name>
            </script>
          </material>
        </visual>
        <visual name='sphere'>
          <geometry>
            <sphere>
              <radius>0.025</radius>
            </sphere>
          </geometry>
          <material>
            <script>
              <uri>model://fire_hose_long_curled/materials/scripts</uri>
              <uri>model://fire_hose_long_curled/materials/textures</uri>
              <name>fire_hose_long_curled/fire_hose_canvas</name>
            </script>
          </material>
        </visual>
        <velocity_decay>
          <linear>0</linear>
          <angular>0</angular>
        </velocity_decay>
        <self_collide>0</self_collide>
        <kinematic>0</kinematic>
      </link>
      <link name='link_15'>
        <gravity>0</gravity>
        <pose>0.1 -0.508 0 0 -0 0</pose>
        <inertial>
          <mass>0.1</mass>
          <pose>0.1 0 0 0 -0 0</pose>
          <inertia>
            <ixx>0.01</ixx>
            <ixy>0</ixy>
            <ixz>0</ixz>
            <iyy>0.01</iyy>
            <iyz>0</iyz>
            <izz>0.01</izz>
          </inertia>
        </inertial>
        <visual name='visual'>
          <pose>0.1 0 0 0 1.57079 0</pose>
          <geometry>
            <cylinder>
              <length>0.2</length>
              <radius>0.025</radius>
            </cylinder>
          </geometry>
          <material>
            <script>
              <uri>model://fire_hose_long_curled/materials/scripts</uri>
              <uri>model://fire_hose_long_curled/materials/textures</uri>
              <name>fire_hose_long_curled/fire_hose_canvas</name>
            </script>
          </material>
        </visual>
        <visual name='sphere'>
          <geometry>
            <sphere>
              <radius>0.025</radius>
            </sphere>
          </geometry>
          <material>
            <script>
              <uri>model://fire_hose_long_curled/materials/scripts</uri>
              <uri>model://fire_hose_long_curled/materials/textures</uri>
              <name>fire_hose_long_curled/fire_hose_canvas</name>
            </script>
          </material>
        </visual>
        <velocity_decay>
          <linear>0</linear>
          <angular>0</angular>
        </velocity_decay>
        <self_collide>0</self_collide>
        <kinematic>0</kinematic>
      </link>
      <link name='link_16'>
        <gravity>0</gravity>
        <pose>0.3 -0.508 0 0 -0 0</pose>
        <inertial>
          <mass>0.1</mass>
          <pose>0.1 0 0 0 -0 0</pose>
          <inertia>
            <ixx>0.01</ixx>
            <ixy>0</ixy>
            <ixz>0</ixz>
            <iyy>0.01</iyy>
            <iyz>0</iyz>
            <izz>0.01</izz>
          </inertia>
        </inertial>
        <visual name='visual'>
          <pose>0.1 0 0 0 1.57079 0</pose>
          <geometry>
            <cylinder>
              <length>0.2</length>
              <radius>0.025</radius>
            </cylinder>
          </geometry>
          <material>
            <script>
              <uri>model://fire_hose_long_curled/materials/scripts</uri>
              <uri>model://fire_hose_long_curled/materials/textures</uri>
              <name>fire_hose_long_curled/fire_hose_canvas</name>
            </script>
          </material>
        </visual>
        <visual name='sphere'>
          <geometry>
            <sphere>
              <radius>0.025</radius>
            </sphere>
          </geometry>
          <material>
            <script>
              <uri>model://fire_hose_long_curled/materials/scripts</uri>
              <uri>model://fire_hose_long_curled/materials/textures</uri>
              <name>fire_hose_long_curled/fire_hose_canvas</name>
            </script>
          </material>
        </visual>
        <velocity_decay>
          <linear>0</linear>
          <angular>0</angular>
        </velocity_decay>
        <self_collide>0</self_collide>
        <kinematic>0</kinematic>
      </link>
      <link name='link_17'>
        <gravity>0</gravity>
        <pose>0.5 -0.508 0 0 -0 0</pose>
        <inertial>
          <mass>0.1</mass>
          <pose>0.1 0 0 0 -0 0</pose>
          <inertia>
            <ixx>0.01</ixx>
            <ixy>0</ixy>
            <ixz>0</ixz>
            <iyy>0.01</iyy>
            <iyz>0</iyz>
            <izz>0.01</izz>
          </inertia>
        </inertial>
        <visual name='visual'>
          <pose>0.1 0 0 0 1.57079 0</pose>
          <geometry>
            <cylinder>
              <length>0.2</length>
              <radius>0.025</radius>
            </cylinder>
          </geometry>
          <material>
            <script>
              <uri>model://fire_hose_long_curled/materials/scripts</uri>
              <uri>model://fire_hose_long_curled/materials/textures</uri>
              <name>fire_hose_long_curled/fire_hose_canvas</name>
            </script>
          </material>
        </visual>
        <visual name='sphere'>
          <geometry>
            <sphere>
              <radius>0.025</radius>
            </sphere>
          </geometry>
          <material>
            <script>
              <uri>model://fire_hose_long_curled/materials/scripts</uri>
              <uri>model://fire_hose_long_curled/materials/textures</uri>
              <name>fire_hose_long_curled/fire_hose_canvas</name>
            </script>
          </material>
        </visual>
        <velocity_decay>
          <linear>0</linear>
          <angular>0</angular>
        </velocity_decay>
        <self_collide>0</self_collide>
        <kinematic>0</kinematic>
      </link>
      <link name='link_18'>
        <gravity>0</gravity>
        <pose>0.7 -0.508 0 0 -0 0</pose>
        <inertial>
          <mass>0.1</mass>
          <pose>0.1 0 0 0 -0 0</pose>
          <inertia>
            <ixx>0.01</ixx>
            <ixy>0</ixy>
            <ixz>0</ixz>
            <iyy>0.01</iyy>
            <iyz>0</iyz>
            <izz>0.01</izz>
          </inertia>
        </inertial>
        <visual name='visual'>
          <pose>0.1 0 0 0 1.57079 0</pose>
          <geometry>
            <cylinder>
              <length>0.2</length>
              <radius>0.025</radius>
            </cylinder>
          </geometry>
          <material>
            <script>
              <uri>model://fire_hose_long_curled/materials/scripts</uri>
              <uri>model://fire_hose_long_curled/materials/textures</uri>
              <name>fire_hose_long_curled/fire_hose_canvas</name>
            </script>
          </material>
        </visual>
        <visual name='sphere'>
          <geometry>
            <sphere>
              <radius>0.025</radius>
            </sphere>
          </geometry>
          <material>
            <script>
              <uri>model://fire_hose_long_curled/materials/scripts</uri>
              <uri>model://fire_hose_long_curled/materials/textures</uri>
              <name>fire_hose_long_curled/fire_hose_canvas</name>
            </script>
          </material>
        </visual>
        <velocity_decay>
          <linear>0</linear>
          <angular>0</angular>
        </velocity_decay>
        <self_collide>0</self_collide>
        <kinematic>0</kinematic>
      </link>
      <link name='link_19'>
        <gravity>0</gravity>
        <pose>0.9 -0.508 0 0 -0 0</pose>
        <inertial>
          <mass>0.1</mass>
          <pose>0.1 0 0 0 -0 0</pose>
          <inertia>
            <ixx>0.01</ixx>
            <ixy>0</ixy>
            <ixz>0</ixz>
            <iyy>0.01</iyy>
            <iyz>0</iyz>
            <izz>0.01</izz>
          </inertia>
        </inertial>
        <visual name='visual'>
          <pose>0.1 0 0 0 1.57079 0</pose>
          <geometry>
            <cylinder>
              <length>0.2</length>
              <radius>0.025</radius>
            </cylinder>
          </geometry>
          <material>
            <script>
              <uri>model://fire_hose_long_curled/materials/scripts</uri>
              <uri>model://fire_hose_long_curled/materials/textures</uri>
              <name>fire_hose_long_curled/fire_hose_canvas</name>
            </script>
          </material>
        </visual>
        <visual name='sphere'>
          <geometry>
            <sphere>
              <radius>0.025</radius>
            </sphere>
          </geometry>
          <material>
            <script>
              <uri>model://fire_hose_long_curled/materials/scripts</uri>
              <uri>model://fire_hose_long_curled/materials/textures</uri>
              <name>fire_hose_long_curled/fire_hose_canvas</name>
            </script>
          </material>
        </visual>
        <velocity_decay>
          <linear>0</linear>
          <angular>0</angular>
        </velocity_decay>
        <self_collide>0</self_collide>
        <kinematic>0</kinematic>
      </link>
      <link name='nozzle'>
        <pose>1.1 -0.508 0 0 -0 3.1415</pose>
        <inertial>
          <mass>0.1</mass>
          <inertia>
            <ixx>0.01</ixx>
            <ixy>0</ixy>
            <ixz>0</ixz>
            <iyy>0.01</iyy>
            <iyz>0</iyz>
            <izz>0.01</izz>
          </inertia>
        </inertial>
        <visual name='nozzle_vis'>
          <geometry>
            <mesh>
              <scale>1 0.5 0.5</scale>
              <uri>model://fire_hose_long_curled/meshes/nozzle.stl</uri>
            </mesh>
          </geometry>
        </visual>
        <velocity_decay>
          <linear>0</linear>
          <angular>0</angular>
        </velocity_decay>
        <self_collide>0</self_collide>
        <kinematic>0</kinematic>
        <gravity>0</gravity>
      </link>
      <joint name='joint_00' type='revolute'>
        <parent>coupling</parent>
        <child>link_00</child>
        <axis>
          <xyz>1 0 0</xyz>
          <dynamics>
            <damping>1</damping>
          </dynamics>
          <limit>
            <lower>-1e+16</lower>
            <upper>1e+16</upper>
          </limit>
        </axis>
        <physics>
          <ode>
            <cfm_damping>1</cfm_damping>
            <limit>
              <cfm>0</cfm>
              <erp>0.2</erp>
            </limit>
          </ode>
        </physics>
      </joint>
      <joint name='joint_01' type='universal'>
        <child>link_01</child>
        <parent>link_00</parent>
        <axis>
          <xyz>0 1 0</xyz>
          <limit>
            <lower>-1.57</lower>
            <upper>1.57</upper>
          </limit>
          <dynamics>
            <damping>1</damping>
          </dynamics>
        </axis>
        <axis2>
          <xyz>0 0 1</xyz>
          <limit>
            <lower>-1.57</lower>
            <upper>1.57</upper>
          </limit>
          <dynamics>
            <damping>1</damping>
          </dynamics>
        </axis2>
        <physics>
          <ode>
            <cfm_damping>1</cfm_damping>
            <limit>
              <cfm>0</cfm>
              <erp>0.2</erp>
            </limit>
          </ode>
        </physics>
      </joint>
      <joint name='joint_02' type='universal'>
        <child>link_02</child>
        <parent>link_01</parent>
        <axis>
          <xyz>0 1 0</xyz>
          <limit>
            <lower>-1.57</lower>
            <upper>1.57</upper>
          </limit>
          <dynamics>
            <damping>1</damping>
          </dynamics>
        </axis>
        <axis2>
          <xyz>0 0 1</xyz>
          <limit>
            <lower>-1.57</lower>
            <upper>1.57</upper>
          </limit>
          <dynamics>
            <damping>1</damping>
          </dynamics>
        </axis2>
        <physics>
          <ode>
            <cfm_damping>1</cfm_damping>
            <limit>
              <cfm>0</cfm>
              <erp>0.2</erp>
            </limit>
          </ode>
        </physics>
      </joint>
      <joint name='joint_03' type='universal'>
        <child>link_03</child>
        <parent>link_02</parent>
        <axis>
          <xyz>0 1 0</xyz>
          <limit>
            <lower>-1.57</lower>
            <upper>1.57</upper>
          </limit>
          <dynamics>
            <damping>1</damping>
          </dynamics>
        </axis>
        <axis2>
          <xyz>0 0 1</xyz>
          <limit>
            <lower>-1.57</lower>
            <upper>1.57</upper>
          </limit>
          <dynamics>
            <damping>1</damping>
          </dynamics>
        </axis2>
        <physics>
          <ode>
            <cfm_damping>1</cfm_damping>
            <limit>
              <cfm>0</cfm>
              <erp>0.2</erp>
            </limit>
          </ode>
        </physics>
      </joint>
      <joint name='joint_04' type='universal'>
        <child>link_04</child>
        <parent>link_03</parent>
        <axis>
          <xyz>0 1 0</xyz>
          <limit>
            <lower>-1.57</lower>
            <upper>1.57</upper>
          </limit>
          <dynamics>
            <damping>1</damping>
          </dynamics>
        </axis>
        <axis2>
          <xyz>0 0 1</xyz>
          <limit>
            <lower>-1.57</lower>
            <upper>1.57</upper>
          </limit>
          <dynamics>
            <damping>1</damping>
          </dynamics>
        </axis2>
        <physics>
          <ode>
            <cfm_damping>1</cfm_damping>
            <limit>
              <cfm>0</cfm>
              <erp>0.2</erp>
            </limit>
          </ode>
        </physics>
      </joint>
      <joint name='joint_05' type='universal'>
        <child>link_05</child>
        <parent>link_04</parent>
        <axis>
          <xyz>0 1 0</xyz>
          <limit>
            <lower>-1.57</lower>
            <upper>1.57</upper>
          </limit>
          <dynamics>
            <damping>1</damping>
          </dynamics>
        </axis>
        <axis2>
          <xyz>0 0 1</xyz>
          <limit>
            <lower>-1.57</lower>
            <upper>1.57</upper>
          </limit>
          <dynamics>
            <damping>1</damping>
          </dynamics>
        </axis2>
        <physics>
          <ode>
            <cfm_damping>1</cfm_damping>
            <limit>
              <cfm>0</cfm>
              <erp>0.2</erp>
            </limit>
          </ode>
        </physics>
      </joint>
      <joint name='joint_06' type='universal'>
        <child>link_06</child>
        <parent>link_05</parent>
        <axis>
          <xyz>0 0 1</xyz>
          <limit>
            <lower>-0.72</lower>
            <upper>2.35</upper>
          </limit>
          <dynamics>
            <damping>1</damping>
          </dynamics>
        </axis>
        <axis2>
          <xyz>1 1 0</xyz>
          <limit>
            <lower>-1.57</lower>
            <upper>1.57</upper>
          </limit>
          <dynamics>
            <damping>1</damping>
          </dynamics>
        </axis2>
        <physics>
          <ode>
            <cfm_damping>1</cfm_damping>
            <limit>
              <cfm>0</cfm>
              <erp>0.2</erp>
            </limit>
          </ode>
        </physics>
      </joint>
      <joint name='joint_07' type='universal'>
        <child>link_07</child>
        <parent>link_06</parent>
        <axis>
          <xyz>0 0 1</xyz>
          <limit>
            <lower>-0</lower>
            <upper>3</upper>
          </limit>
          <dynamics>
            <damping>1</damping>
          </dynamics>
        </axis>
        <axis2>
          <xyz>-1 1 0</xyz>
          <limit>
            <lower>-1.57</lower>
            <upper>1.57</upper>
          </limit>
          <dynamics>
            <damping>1</damping>
          </dynamics>
        </axis2>
        <physics>
          <ode>
            <cfm_damping>1</cfm_damping>
            <limit>
              <cfm>0</cfm>
              <erp>0.2</erp>
            </limit>
          </ode>
        </physics>
      </joint>
      <joint name='joint_08' type='universal'>
        <child>link_08</child>
        <parent>link_07</parent>
        <axis>
          <xyz>0 1 0</xyz>
          <limit>
            <lower>-1.57</lower>
            <upper>1.57</upper>
          </limit>
          <dynamics>
            <damping>1</damping>
          </dynamics>
        </axis>
        <axis2>
          <xyz>0 0 1</xyz>
          <limit>
            <lower>-0.72</lower>
            <upper>2.35</upper>
          </limit>
          <dynamics>
            <damping>1</damping>
          </dynamics>
        </axis2>
        <physics>
          <ode>
            <cfm_damping>1</cfm_damping>
            <limit>
              <cfm>0</cfm>
              <erp>0.2</erp>
            </limit>
          </ode>
        </physics>
      </joint>
      <joint name='joint_09' type='universal'>
        <child>link_09</child>
        <parent>link_08</parent>
        <axis>
          <xyz>0 1 0</xyz>
          <limit>
            <lower>-1.57</lower>
            <upper>1.57</upper>
          </limit>
          <dynamics>
            <damping>1</damping>
          </dynamics>
        </axis>
        <axis2>
          <xyz>0 0 1</xyz>
          <limit>
            <lower>-1.57</lower>
            <upper>1.57</upper>
          </limit>
          <dynamics>
            <damping>1</damping>
          </dynamics>
        </axis2>
        <physics>
          <ode>
            <cfm_damping>1</cfm_damping>
            <limit>
              <cfm>0</cfm>
              <erp>0.2</erp>
            </limit>
          </ode>
        </physics>
      </joint>
      <joint name='joint_10' type='universal'>
        <child>link_10</child>
        <parent>link_09</parent>
        <axis>
          <xyz>0 1 0</xyz>
          <limit>
            <lower>-1.57</lower>
            <upper>1.57</upper>
          </limit>
          <dynamics>
            <damping>1</damping>
          </dynamics>
        </axis>
        <axis2>
          <xyz>0 0 1</xyz>
          <limit>
            <lower>-1.57</lower>
            <upper>1.57</upper>
          </limit>
          <dynamics>
            <damping>1</damping>
          </dynamics>
        </axis2>
        <physics>
          <ode>
            <cfm_damping>1</cfm_damping>
            <limit>
              <cfm>0</cfm>
              <erp>0.2</erp>
            </limit>
          </ode>
        </physics>
      </joint>
      <joint name='joint_11' type='universal'>
        <child>link_11</child>
        <parent>link_10</parent>
        <axis>
          <xyz>0 1 0</xyz>
          <limit>
            <lower>-1.57</lower>
            <upper>1.57</upper>
          </limit>
          <dynamics>
            <damping>1</damping>
          </dynamics>
        </axis>
        <axis2>
          <xyz>0 0 1</xyz>
          <limit>
            <lower>-1.57</lower>
            <upper>1.57</upper>
          </limit>
          <dynamics>
            <damping>1</damping>
          </dynamics>
        </axis2>
        <physics>
          <ode>
            <cfm_damping>1</cfm_damping>
            <limit>
              <cfm>0</cfm>
              <erp>0.2</erp>
            </limit>
          </ode>
        </physics>
      </joint>
      <joint name='joint_12' type='universal'>
        <child>link_12</child>
        <parent>link_11</parent>
        <axis>
          <xyz>0 1 0</xyz>
          <limit>
            <lower>-1.57</lower>
            <upper>1.57</upper>
          </limit>
          <dynamics>
            <damping>1</damping>
          </dynamics>
        </axis>
        <axis2>
          <xyz>0 0 1</xyz>
          <limit>
            <lower>-1.57</lower>
            <upper>1.57</upper>
          </limit>
          <dynamics>
            <damping>1</damping>
          </dynamics>
        </axis2>
        <physics>
          <ode>
            <cfm_damping>1</cfm_damping>
            <limit>
              <cfm>0</cfm>
              <erp>0.2</erp>
            </limit>
          </ode>
        </physics>
      </joint>
      <joint name='joint_13' type='universal'>
        <child>link_13</child>
        <parent>link_12</parent>
        <axis>
          <xyz>0 0 1</xyz>
          <limit>
            <lower>-2.35</lower>
            <upper>0.72</upper>
          </limit>
          <dynamics>
            <damping>1</damping>
          </dynamics>
        </axis>
        <axis2>
          <xyz>-1 1 0</xyz>
          <limit>
            <lower>-1.57</lower>
            <upper>1.57</upper>
          </limit>
          <dynamics>
            <damping>1</damping>
          </dynamics>
        </axis2>
        <physics>
          <ode>
            <cfm_damping>1</cfm_damping>
            <limit>
              <cfm>0</cfm>
              <erp>0.2</erp>
            </limit>
          </ode>
        </physics>
      </joint>
      <joint name='joint_14' type='universal'>
        <child>link_14</child>
        <parent>link_13</parent>
        <axis>
          <xyz>0 0 1</xyz>
          <limit>
            <lower>-3</lower>
            <upper>0</upper>
          </limit>
          <dynamics>
            <damping>1</damping>
          </dynamics>
        </axis>
        <axis2>
          <xyz>1 1 0</xyz>
          <limit>
            <lower>-1.57</lower>
            <upper>1.57</upper>
          </limit>
          <dynamics>
            <damping>1</damping>
          </dynamics>
        </axis2>
        <physics>
          <ode>
            <cfm_damping>1</cfm_damping>
            <limit>
              <cfm>0</cfm>
              <erp>0.2</erp>
            </limit>
          </ode>
        </physics>
      </joint>
      <joint name='joint_15' type='universal'>
        <child>link_15</child>
        <parent>link_14</parent>
        <axis>
          <xyz>0 0 1</xyz>
          <limit>
            <lower>-2.35</lower>
            <upper>0.72</upper>
          </limit>
          <dynamics>
            <damping>1</damping>
          </dynamics>
        </axis>
        <axis2>
          <xyz>0 1 0</xyz>
          <limit>
            <lower>-1.57</lower>
            <upper>1.57</upper>
          </limit>
          <dynamics>
            <damping>1</damping>
          </dynamics>
        </axis2>
        <physics>
          <ode>
            <cfm_damping>1</cfm_damping>
            <limit>
              <cfm>0</cfm>
              <erp>0.2</erp>
            </limit>
          </ode>
        </physics>
      </joint>
      <joint name='joint_16' type='universal'>
        <child>link_16</child>
        <parent>link_15</parent>
        <axis>
          <xyz>0 1 0</xyz>
          <limit>
            <lower>-1.57</lower>
            <upper>1.57</upper>
          </limit>
          <dynamics>
            <damping>1</damping>
          </dynamics>
        </axis>
        <axis2>
          <xyz>0 0 1</xyz>
          <limit>
            <lower>-1.57</lower>
            <upper>1.57</upper>
          </limit>
          <dynamics>
            <damping>1</damping>
          </dynamics>
        </axis2>
        <physics>
          <ode>
            <cfm_damping>1</cfm_damping>
            <limit>
              <cfm>0</cfm>
              <erp>0.2</erp>
            </limit>
          </ode>
        </physics>
      </joint>
      <joint name='joint_17' type='universal'>
        <child>link_17</child>
        <parent>link_16</parent>
        <axis>
          <xyz>0 1 0</xyz>
          <limit>
            <lower>-1.57</lower>
            <upper>1.57</upper>
          </limit>
          <dynamics>
            <damping>1</damping>
          </dynamics>
        </axis>
        <axis2>
          <xyz>0 0 1</xyz>
          <limit>
            <lower>-1.57</lower>
            <upper>1.57</upper>
          </limit>
          <dynamics>
            <damping>1</damping>
          </dynamics>
        </axis2>
        <physics>
          <ode>
            <cfm_damping>1</cfm_damping>
            <limit>
              <cfm>0</cfm>
              <erp>0.2</erp>
            </limit>
          </ode>
        </physics>
      </joint>
      <joint name='joint_18' type='universal'>
        <child>link_18</child>
        <parent>link_17</parent>
        <axis>
          <xyz>0 1 0</xyz>
          <limit>
            <lower>-1.57</lower>
            <upper>1.57</upper>
          </limit>
          <dynamics>
            <damping>1</damping>
          </dynamics>
        </axis>
        <axis2>
          <xyz>0 0 1</xyz>
          <limit>
            <lower>-1.57</lower>
            <upper>1.57</upper>
          </limit>
          <dynamics>
            <damping>1</damping>
          </dynamics>
        </axis2>
        <physics>
          <ode>
            <cfm_damping>1</cfm_damping>
            <limit>
              <cfm>0</cfm>
              <erp>0.2</erp>
            </limit>
          </ode>
        </physics>
      </joint>
      <joint name='joint_19' type='universal'>
        <child>link_19</child>
        <parent>link_18</parent>
        <axis>
          <xyz>0 1 0</xyz>
          <limit>
            <lower>-1.57</lower>
            <upper>1.57</upper>
          </limit>
          <dynamics>
            <damping>1</damping>
          </dynamics>
        </axis>
        <axis2>
          <xyz>0 0 1</xyz>
          <limit>
            <lower>-1.57</lower>
            <upper>1.57</upper>
          </limit>
          <dynamics>
            <damping>1</damping>
          </dynamics>
        </axis2>
        <physics>
          <ode>
            <cfm_damping>1</cfm_damping>
            <limit>
              <cfm>0</cfm>
              <erp>0.2</erp>
            </limit>
          </ode>
        </physics>
      </joint>
      <joint name='joint_20' type='universal'>
        <child>nozzle</child>
        <parent>link_19</parent>
        <axis>
          <xyz>0 1 0</xyz>
          <limit>
            <lower>-1.57</lower>
            <upper>1.57</upper>
          </limit>
          <dynamics>
            <damping>1</damping>
          </dynamics>
        </axis>
        <axis2>
          <xyz>0 0 1</xyz>
          <limit>
            <lower>-1.57</lower>
            <upper>1.57</upper>
          </limit>
          <dynamics>
            <damping>1</damping>
          </dynamics>
        </axis2>
        <physics>
          <ode>
            <cfm_damping>1</cfm_damping>
            <limit>
              <cfm>0</cfm>
              <erp>0.2</erp>
            </limit>
          </ode>
        </physics>
      </joint>
      <joint name='world' type='universal'>
        <child>nozzle</child>
        <parent>world</parent>
        <axis>
          <xyz>0 1 0</xyz>
          <limit>
            <lower>-1.57</lower>
            <upper>1.57</upper>
          </limit>
          <dynamics>
            <damping>1</damping>
          </dynamics>
        </axis>
        <axis2>
          <xyz>0 0 1</xyz>
          <limit>
            <lower>-1.57</lower>
            <upper>1.57</upper>
          </limit>
          <dynamics>
            <damping>1</damping>
          </dynamics>
        </axis2>
        <physics>
          <ode>
            <cfm_damping>1</cfm_damping>
            <limit>
              <cfm>0</cfm>
              <erp>0.2</erp>
            </limit>
          </ode>
        </physics>
      </joint>
      <static>1</static>
    </model>
    <state world_name='default'>
      <sim_time>7866 507000000</sim_time>
      <real_time>125 827230893</real_time>
      <wall_time>1417194838 406094061</wall_time>
      <model name='eur_pallet'>
        <pose>-4.54988 0.116743 0.59 1.5707 -0 0</pose>
        <link name='link'>
          <pose>-4.54988 0.116743 0.59 1.5707 -0 0</pose>
          <velocity>0 0 0 0 -0 0</velocity>
          <acceleration>0 0 0 0 -0 0</acceleration>
          <wrench>0 0 0 0 -0 0</wrench>
        </link>
      </model>
      <model name='eur_pallet_0'>
        <pose>-4.26447 0.407308 0.59 1.5707 5.55112e-17 1.5707</pose>
        <link name='link'>
          <pose>-4.26447 0.407308 0.59 1.5707 5.55112e-17 1.5707</pose>
          <velocity>0 0 0 0 -0 0</velocity>
          <acceleration>0 0 0 0 -0 0</acceleration>
          <wrench>0 0 0 0 -0 0</wrench>
        </link>
      </model>
      <model name='eur_pallet_1'>
        <pose>-4.46802 -1.63273 0.69 3.14159 1.5707 3.14159</pose>
        <link name='link'>
          <pose>-4.46802 -1.63273 0.69 3.14159 1.5707 3.14159</pose>
          <velocity>0 0 0 0 -0 0</velocity>
          <acceleration>0 0 0 0 -0 0</acceleration>
          <wrench>0 0 0 0 -0 0</wrench>
        </link>
      </model>
      <model name='eur_pallet_2'>
        <pose>-4.94952 -1.15 0.69 -0.000572 1.5707 1.57013</pose>
        <link name='link'>
          <pose>-4.94952 -1.15 0.69 -0.000572 1.5707 1.57013</pose>
          <velocity>0 0 0 0 -0 0</velocity>
          <acceleration>0 0 0 0 -0 0</acceleration>
          <wrench>0 0 0 0 -0 0</wrench>
        </link>
      </model>
      <model name='fire_hose_long_curled_1'>
        <pose>-2.64385 0.004293 1.25339 -1.5707 1.5707 5.76279e-13</pose>
        <link name='coupling'>
          <pose>-2.64385 0.004293 1.25339 -1.5707 1.5707 5.76279e-13</pose>
          <velocity>0 0 0 0 -0 0</velocity>
          <acceleration>0 0 0 0 -0 0</acceleration>
          <wrench>0 0 0 0 -0 0</wrench>
        </link>
        <link name='link_00'>
          <pose>-2.64384 0.004293 1.15339 -1.5707 1.5707 5.76279e-13</pose>
          <velocity>0 0 0 0 -0 0</velocity>
          <acceleration>0 0 0 0 -0 0</acceleration>
          <wrench>0 0 0 0 -0 0</wrench>
        </link>
        <link name='link_01'>
          <pose>-2.64384 0.004293 1.15339 -1.5707 1.5707 5.76279e-13</pose>
          <velocity>0 0 0 0 -0 0</velocity>
          <acceleration>0 0 0 0 -0 0</acceleration>
          <wrench>0 0 0 0 -0 0</wrench>
        </link>
        <link name='link_02'>
          <pose>-2.64382 0.004293 0.95339 -1.5707 1.5707 5.76279e-13</pose>
          <velocity>0 0 0 0 -0 0</velocity>
          <acceleration>0 0 0 0 -0 0</acceleration>
          <wrench>0 0 0 0 -0 0</wrench>
        </link>
        <link name='link_03'>
          <pose>-2.6438 0.004293 0.75339 -1.5707 1.5707 5.76279e-13</pose>
          <velocity>0 0 0 0 -0 0</velocity>
          <acceleration>0 0 0 0 -0 0</acceleration>
          <wrench>0 0 0 0 -0 0</wrench>
        </link>
        <link name='link_04'>
          <pose>-2.64378 0.004293 0.55339 -1.5707 1.5707 5.76279e-13</pose>
          <velocity>0 0 0 0 -0 0</velocity>
          <acceleration>0 0 0 0 -0 0</acceleration>
          <wrench>0 0 0 0 -0 0</wrench>
        </link>
        <link name='link_05'>
          <pose>-2.64376 0.004293 0.35339 -1.5707 1.5707 5.76279e-13</pose>
          <velocity>0 0 0 0 -0 0</velocity>
          <acceleration>0 0 0 0 -0 0</acceleration>
          <wrench>0 0 0 0 -0 0</wrench>
        </link>
        <link name='link_06'>
          <pose>-2.64374 0.004293 0.15339 -1.5708 0.7857 -9.6e-05</pose>
          <velocity>0 0 0 0 -0 0</velocity>
          <acceleration>0 0 0 0 -0 0</acceleration>
          <wrench>0 0 0 0 -0 0</wrench>
        </link>
        <link name='link_07'>
          <pose>-2.51673 0.004281 0.026402 -1.5708 -0.7708 -9.6e-05</pose>
          <velocity>0 0 0 0 -0 0</velocity>
          <acceleration>0 0 0 0 -0 0</acceleration>
          <wrench>0 0 0 0 -0 0</wrench>
        </link>
        <link name='link_08'>
          <pose>-2.38974 0.004269 0.153414 1.56827 -1.57079 -3.13916</pose>
          <velocity>0 0 0 0 -0 0</velocity>
          <acceleration>0 0 0 0 -0 0</acceleration>
          <wrench>0 0 0 0 -0 0</wrench>
        </link>
        <link name='link_09'>
          <pose>-2.38976 0.004269 0.353414 1.56827 -1.57079 -3.13916</pose>
          <velocity>0 0 0 0 -0 0</velocity>
          <acceleration>0 0 0 0 -0 0</acceleration>
          <wrench>0 0 0 0 -0 0</wrench>
        </link>
        <link name='link_10'>
          <pose>-2.38978 0.004269 0.553414 1.56827 -1.57079 -3.13916</pose>
          <velocity>0 0 0 0 -0 0</velocity>
          <acceleration>0 0 0 0 -0 0</acceleration>
          <wrench>0 0 0 0 -0 0</wrench>
        </link>
        <link name='link_11'>
          <pose>-2.3898 0.004269 0.753414 1.56827 -1.57079 -3.13916</pose>
          <velocity>0 0 0 0 -0 0</velocity>
          <acceleration>0 0 0 0 -0 0</acceleration>
          <wrench>0 0 0 0 -0 0</wrench>
        </link>
        <link name='link_12'>
          <pose>-2.38982 0.004269 0.953414 1.56827 -1.57079 -3.13916</pose>
          <velocity>0 0 0 0 -0 0</velocity>
          <acceleration>0 0 0 0 -0 0</acceleration>
          <wrench>0 0 0 0 -0 0</wrench>
        </link>
        <link name='link_13'>
          <pose>-2.38984 0.004269 1.15341 -1.5708 -0.7853 -9.6e-05</pose>
          <velocity>0 0 0 0 -0 0</velocity>
          <acceleration>0 0 0 0 -0 0</acceleration>
          <wrench>0 0 0 0 -0 0</wrench>
        </link>
        <link name='link_14'>
          <pose>-2.26285 0.004256 1.28043 -1.5708 0.7857 -9.6e-05</pose>
          <velocity>0 0 0 0 -0 0</velocity>
          <acceleration>0 0 0 0 -0 0</acceleration>
          <wrench>0 0 0 0 -0 0</wrench>
        </link>
        <link name='link_15'>
          <pose>-2.13584 0.004244 1.15344 -1.5707 1.5707 5.76279e-13</pose>
          <velocity>0 0 0 0 -0 0</velocity>
          <acceleration>0 0 0 0 -0 0</acceleration>
          <wrench>0 0 0 0 -0 0</wrench>
        </link>
        <link name='link_16'>
          <pose>-2.13582 0.004244 0.953439 -1.5707 1.5707 5.76279e-13</pose>
          <velocity>0 0 0 0 -0 0</velocity>
          <acceleration>0 0 0 0 -0 0</acceleration>
          <wrench>0 0 0 0 -0 0</wrench>
        </link>
        <link name='link_17'>
          <pose>-2.1358 0.004244 0.753439 -1.5707 1.5707 5.76279e-13</pose>
          <velocity>0 0 0 0 -0 0</velocity>
          <acceleration>0 0 0 0 -0 0</acceleration>
          <wrench>0 0 0 0 -0 0</wrench>
        </link>
        <link name='link_18'>
          <pose>-2.13578 0.004244 0.553439 -1.5707 1.5707 5.76279e-13</pose>
          <velocity>0 0 0 0 -0 0</velocity>
          <acceleration>0 0 0 0 -0 0</acceleration>
          <wrench>0 0 0 0 -0 0</wrench>
        </link>
        <link name='link_19'>
          <pose>-2.13576 0.004244 0.353439 -1.5707 1.5707 5.76279e-13</pose>
          <velocity>0 0 0 0 -0 0</velocity>
          <acceleration>0 0 0 0 -0 0</acceleration>
          <wrench>0 0 0 0 -0 0</wrench>
        </link>
        <link name='nozzle'>
          <pose>-2.13574 0.004244 0.153439 1.57075 -1.57061 3.14154</pose>
          <velocity>0 0 0 0 -0 0</velocity>
          <acceleration>0 0 0 0 -0 0</acceleration>
          <wrench>0 0 0 0 -0 0</wrench>
        </link>
      </model>
      <model name='grey_wall'>
        <pose>-3.73994 0.894219 0 0 -0 0</pose>
        <link name='link'>
          <pose>-3.73994 0.894219 1.4 0 -0 0</pose>
          <velocity>0 0 0 0 -0 0</velocity>
          <acceleration>0 0 0 0 -0 0</acceleration>
          <wrench>0 0 0 0 -0 0</wrench>
        </link>
      </model>
      <model name='ground_plane'>
        <pose>0 0 0 0 -0 0</pose>
        <link name='link'>
          <pose>0 0 0 0 -0 0</pose>
          <velocity>0 0 0 0 -0 0</velocity>
          <acceleration>0 0 0 0 -0 0</acceleration>
          <wrench>0 0 0 0 -0 0</wrench>
        </link>
      </model>
      <model name='lab_with_windows_2'>
        <pose>0 0 0 0 -0 0</pose>
        <link name='link'>
          <pose>0 0 0 0 -0 0</pose>
          <velocity>0 0 0 0 -0 0</velocity>
          <acceleration>0 0 0 0 -0 0</acceleration>
          <wrench>0 0 0 0 -0 0</wrench>
        </link>
      </model>
      <model name='lumber_2x4x48'>
        <pose>-3.54201 -2.90202 0.043241 0 -0 0</pose>
        <link name='link'>
          <pose>-3.54201 -2.90202 0.043241 0 -0 0</pose>
          <velocity>0 0 0 0 -0 0</velocity>
          <acceleration>0 0 0 0 -0 0</acceleration>
          <wrench>0 0 0 0 -0 0</wrench>
        </link>
      </model>
      <model name='lumber_2x4x48_1'>
        <pose>-4.16505 -2.69657 0.042115 0 -0 1.5707</pose>
        <link name='link'>
          <pose>-4.16505 -2.69657 0.042115 0 -0 1.5707</pose>
          <velocity>0 0 0 0 -0 0</velocity>
          <acceleration>0 0 0 0 -0 0</acceleration>
          <wrench>0 0 0 0 -0 0</wrench>
        </link>
      </model>
      <model name='ragdoll'>
        <pose>-4.18583 -2.49475 1.39995 1.5e-05 0.001486 -0.036963</pose>
        <link name='head'>
          <pose>-4.18401 -2.49484 2.62495 1.5e-05 0.001486 -0.036963</pose>
          <velocity>0 0 0 0 -0 0</velocity>
          <acceleration>0 0 0 0 -0 0</acceleration>
          <wrench>0 0 0 0 -0 0</wrench>
        </link>
        <link name='hip'>
          <pose>-4.18583 -2.49475 1.39995 1.5e-05 0.001486 -0.036963</pose>
          <velocity>0 0 0 0 -0 0</velocity>
          <acceleration>0 0 0 0 -0 0</acceleration>
          <wrench>0 0 0 0 -0 0</wrench>
        </link>
        <link name='l_ankle'>
          <pose>-4.17967 -2.27481 0.074955 1.5e-05 0.001486 -0.036963</pose>
          <velocity>0 0 0 0 -0 0</velocity>
          <acceleration>0 0 0 0 -0 0</acceleration>
          <wrench>0 0 0 0 -0 0</wrench>
        </link>
        <link name='l_calf'>
          <pose>-4.17874 -2.27485 0.699954 1.5e-05 0.001486 -0.036963</pose>
          <velocity>0 0 0 0 -0 0</velocity>
          <acceleration>0 0 0 0 -0 0</acceleration>
          <wrench>0 0 0 0 -0 0</wrench>
        </link>
        <link name='l_foot'>
          <pose>-4.1797 -2.27481 0.049955 1.5e-05 0.001486 -0.036963</pose>
          <velocity>0 0 0 0 -0 0</velocity>
          <acceleration>0 0 0 0 -0 0</acceleration>
          <wrench>0 0 0 0 -0 0</wrench>
        </link>
        <link name='l_forearm'>
          <pose>-4.17325 -2.1675 1.72246 1.5e-05 0.001486 -0.036963</pose>
          <velocity>0 0 0 0 -0 0</velocity>
          <acceleration>0 0 0 0 -0 0</acceleration>
          <wrench>0 0 0 0 -0 0</wrench>
        </link>
        <link name='l_hand'>
          <pose>-4.17396 -2.16746 1.24246 1.5e-05 0.001486 -0.036963</pose>
          <velocity>0 0 0 0 -0 0</velocity>
          <acceleration>0 0 0 0 -0 0</acceleration>
          <wrench>0 0 0 0 -0 0</wrench>
        </link>
        <link name='l_shoulder'>
          <pose>-4.17236 -2.16754 2.32245 1.5e-05 0.001486 -0.036963</pose>
          <velocity>0 0 0 0 -0 0</velocity>
          <acceleration>0 0 0 0 -0 0</acceleration>
          <wrench>0 0 0 0 -0 0</wrench>
        </link>
        <link name='l_thigh_lift'>
          <pose>-4.1777 -2.2749 1.39995 1.5e-05 0.001486 -0.036963</pose>
          <velocity>0 0 0 0 -0 0</velocity>
          <acceleration>0 0 0 0 -0 0</acceleration>
          <wrench>0 0 0 0 -0 0</wrench>
        </link>
        <link name='l_thigh_pan'>
          <pose>-4.1777 -2.2749 1.39995 1.5e-05 0.001486 -0.036963</pose>
          <velocity>0 0 0 0 -0 0</velocity>
          <acceleration>0 0 0 0 -0 0</acceleration>
          <wrench>0 0 0 0 -0 0</wrench>
        </link>
        <link name='l_upper_arm'>
          <pose>-4.17236 -2.16754 2.32245 1.5e-05 0.001486 -0.036963</pose>
          <velocity>0 0 0 0 -0 0</velocity>
          <acceleration>0 0 0 0 -0 0</acceleration>
          <wrench>0 0 0 0 -0 0</wrench>
        </link>
        <link name='l_wrist'>
          <pose>-4.17394 -2.16746 1.25745 1.5e-05 0.001486 -0.036963</pose>
          <velocity>0 0 0 0 -0 0</velocity>
          <acceleration>0 0 0 0 -0 0</acceleration>
          <wrench>0 0 0 0 -0 0</wrench>
        </link>
        <link name='neck'>
          <pose>-4.18442 -2.49482 2.34995 1.5e-05 0.001486 -0.036963</pose>
          <velocity>0 0 0 0 -0 0</velocity>
          <acceleration>0 0 0 0 -0 0</acceleration>
          <wrench>0 0 0 0 -0 0</wrench>
        </link>
        <link name='r_ankle'>
          <pose>-4.19593 -2.71451 0.074948 1.5e-05 0.001486 -0.036963</pose>
          <velocity>0 0 0 0 -0 0</velocity>
          <acceleration>0 0 0 0 -0 0</acceleration>
          <wrench>0 0 0 0 -0 0</wrench>
        </link>
        <link name='r_calf'>
          <pose>-4.195 -2.71455 0.699947 1.5e-05 0.001486 -0.036963</pose>
          <velocity>0 0 0 0 -0 0</velocity>
          <acceleration>0 0 0 0 -0 0</acceleration>
          <wrench>0 0 0 0 -0 0</wrench>
        </link>
        <link name='r_foot'>
          <pose>-4.19596 -2.7145 0.049948 1.5e-05 0.001486 -0.036963</pose>
          <velocity>0 0 0 0 -0 0</velocity>
          <acceleration>0 0 0 0 -0 0</acceleration>
          <wrench>0 0 0 0 -0 0</wrench>
        </link>
        <link name='r_forearm'>
          <pose>-4.19745 -2.82205 1.72245 1.5e-05 0.001486 -0.036963</pose>
          <velocity>0 0 0 0 -0 0</velocity>
          <acceleration>0 0 0 0 -0 0</acceleration>
          <wrench>0 0 0 0 -0 0</wrench>
        </link>
        <link name='r_hand'>
          <pose>-4.19817 -2.82201 1.24245 1.5e-05 0.001486 -0.036963</pose>
          <velocity>0 0 0 0 -0 0</velocity>
          <acceleration>0 0 0 0 -0 0</acceleration>
          <wrench>0 0 0 0 -0 0</wrench>
        </link>
        <link name='r_shoulder'>
          <pose>-4.19656 -2.82209 2.32244 1.5e-05 0.001486 -0.036963</pose>
          <velocity>0 0 0 0 -0 0</velocity>
          <acceleration>0 0 0 0 -0 0</acceleration>
          <wrench>0 0 0 0 -0 0</wrench>
        </link>
        <link name='r_thigh_lift'>
          <pose>-4.19396 -2.7146 1.39995 1.5e-05 0.001486 -0.036963</pose>
          <velocity>0 0 0 0 -0 0</velocity>
          <acceleration>0 0 0 0 -0 0</acceleration>
          <wrench>0 0 0 0 -0 0</wrench>
        </link>
        <link name='r_thigh_pan'>
          <pose>-4.19396 -2.7146 1.39995 1.5e-05 0.001486 -0.036963</pose>
          <velocity>0 0 0 0 -0 0</velocity>
          <acceleration>0 0 0 0 -0 0</acceleration>
          <wrench>0 0 0 0 -0 0</wrench>
        </link>
        <link name='r_upper_arm'>
          <pose>-4.19656 -2.82209 2.32244 1.5e-05 0.001486 -0.036963</pose>
          <velocity>0 0 0 0 -0 0</velocity>
          <acceleration>0 0 0 0 -0 0</acceleration>
          <wrench>0 0 0 0 -0 0</wrench>
        </link>
        <link name='r_wrist'>
          <pose>-4.19814 -2.82202 1.25744 1.5e-05 0.001486 -0.036963</pose>
          <velocity>0 0 0 0 -0 0</velocity>
          <acceleration>0 0 0 0 -0 0</acceleration>
          <wrench>0 0 0 0 -0 0</wrench>
        </link>
        <link name='torso'>
          <pose>-4.18546 -2.49477 1.64995 1.5e-05 0.001486 -0.036963</pose>
          <velocity>0 0 0 0 -0 0</velocity>
          <acceleration>0 0 0 0 -0 0</acceleration>
          <wrench>0 0 0 0 -0 0</wrench>
        </link>
      </model>
      <model name='standpipe'>
        <pose>-4.63972 -2.47575 0 0 -0 0</pose>
        <link name='standpipe'>
          <pose>-4.63972 -2.47575 0.1 0 1.57078 0</pose>
          <velocity>0 0 0 0 -0 0</velocity>
          <acceleration>0 0 0 0 -0 0</acceleration>
          <wrench>0 0 0 0 -0 0</wrench>
        </link>
      </model>
      <model name='truss'>
        <pose>-5.11536 -1.15489 0.143305 0 0 -1.5707</pose>
        <link name='link'>
          <pose>-5.11536 -1.15489 0.143305 0 0 -1.5707</pose>
          <velocity>0 0 0 0 -0 0</velocity>
          <acceleration>0 0 0 0 -0 0</acceleration>
          <wrench>0 0 0 0 -0 0</wrench>
        </link>
      </model>
      <model name='truss_0'>
        <pose>-4.91779 -2.21386 0.143304 0 0 -1.5707</pose>
        <link name='link'>
          <pose>-4.91779 -2.21386 0.143304 0 0 -1.5707</pose>
          <velocity>0 0 0 0 -0 0</velocity>
          <acceleration>0 0 0 0 -0 0</acceleration>
          <wrench>0 0 0 0 -0 0</wrench>
        </link>
      </model>
      <model name='truss_1'>
        <pose>-4.47785 -1.79975 0.143304 0 -0 0</pose>
        <link name='link'>
          <pose>-4.47785 -1.79975 0.143304 0 -0 0</pose>
          <velocity>0 0 0 0 -0 0</velocity>
          <acceleration>0 0 0 0 -0 0</acceleration>
          <wrench>0 0 0 0 -0 0</wrench>
        </link>
      </model>
      <model name='wall_plumbing'>
        <pose>1.24979 0.00139 0.59 -4.8e-05 -1.5707 1.57075</pose>
        <link name='link'>
          <pose>1.24979 0.00139 0.59 -4.8e-05 -1.5707 1.57075</pose>
          <velocity>0 0 0 0 -0 0</velocity>
          <acceleration>0 0 0 0 -0 0</acceleration>
          <wrench>0 0 0 0 -0 0</wrench>
        </link>
      </model>
      <model name='wood_slats'>
        <pose>-4.15337 -2.92371 2.31 -1.56 0 0</pose>
        <link name='link'>
          <pose>-4.15337 -2.92371 2.31 -1.56 0 0</pose>
          <velocity>0 0 0 0 -0 0</velocity>
          <acceleration>0 0 0 0 -0 0</acceleration>
          <wrench>0 0 0 0 -0 0</wrench>
        </link>
      </model>
    </state>
    <model name='lab_with_windows_2'>
      <static>1</static>
      <link name='link'>
        <inertial>
          <mass>1000</mass>
        </inertial>
        <visual name='visual'>
          <geometry>
            <mesh>
              <uri>model://lab_with_windows/meshes/lab_with_windows.stl</uri>
            </mesh>
          </geometry>
          <material>
            <script>
              <name>Gazebo/Grey</name>
              <uri>__default__</uri>
            </script>
          </material>
          <transparency>0</transparency>
        </visual>
        <velocity_decay>
          <linear>0</linear>
          <angular>0</angular>
        </velocity_decay>
        <self_collide>0</self_collide>
        <kinematic>0</kinematic>
        <gravity>0</gravity>
      </link>
      <pose>0 0 0 0 -0 0</pose>
    </model>
    <gui fullscreen='0'>
      <camera name='user_camera'>
        <pose>1.29592 -2.31365 0.698998 0 -0.009949 1.5856</pose>
        <view_controller>orbit</view_controller>
      </camera>
    </gui>
    <model name='eur_pallet'>
      <static>1</static>
      <link name='link'>
        <inertial>
          <mass>22</mass>
        </inertial>
        <visual name='visual'>
          <geometry>
            <mesh>
              <uri>model://eur_pallet/meshes/eur_pallet.stl</uri>
            </mesh>
          </geometry>
          <material>
            <script>
              <name>Gazebo/Wood</name>
              <uri>__default__</uri>
            </script>
          </material>
        </visual>
        <velocity_decay>
          <linear>0</linear>
          <angular>0</angular>
        </velocity_decay>
        <self_collide>0</self_collide>
        <kinematic>0</kinematic>
        <gravity>1</gravity>
      </link>
      <pose>-3.59316 0 0 0 -0 0</pose>
    </model>
    <model name='eur_pallet_0'>
      <static>1</static>
      <link name='link'>
        <inertial>
          <mass>22</mass>
        </inertial>
        <visual name='visual'>
          <geometry>
            <mesh>
              <uri>model://eur_pallet/meshes/eur_pallet.stl</uri>
            </mesh>
          </geometry>
          <material>
            <script>
              <name>Gazebo/Wood</name>
              <uri>__default__</uri>
            </script>
          </material>
        </visual>
        <velocity_decay>
          <linear>0</linear>
          <angular>0</angular>
        </velocity_decay>
        <self_collide>0</self_collide>
        <kinematic>0</kinematic>
        <gravity>1</gravity>
      </link>
      <pose>-3.59929 0.424868 0 0 -0 0</pose>
    </model>
    <model name='eur_pallet_1'>
      <static>1</static>
      <link name='link'>
        <inertial>
          <mass>22</mass>
        </inertial>
        <visual name='visual'>
          <geometry>
            <mesh>
              <uri>model://eur_pallet/meshes/eur_pallet.stl</uri>
            </mesh>
          </geometry>
          <material>
            <script>
              <name>Gazebo/Wood</name>
              <uri>__default__</uri>
            </script>
          </material>
        </visual>
        <velocity_decay>
          <linear>0</linear>
          <angular>0</angular>
        </velocity_decay>
        <self_collide>0</self_collide>
        <kinematic>0</kinematic>
        <gravity>1</gravity>
      </link>
      <pose>-4 -1.40087 0 0 -0 0</pose>
    </model>
    <model name='eur_pallet_2'>
      <static>1</static>
      <link name='link'>
        <inertial>
          <mass>22</mass>
        </inertial>
        <visual name='visual'>
          <geometry>
            <mesh>
              <uri>model://eur_pallet/meshes/eur_pallet.stl</uri>
            </mesh>
          </geometry>
          <material>
            <script>
              <name>Gazebo/Wood</name>
              <uri>__default__</uri>
            </script>
          </material>
        </visual>
        <velocity_decay>
          <linear>0</linear>
          <angular>0</angular>
        </velocity_decay>
        <self_collide>0</self_collide>
        <kinematic>0</kinematic>
        <gravity>1</gravity>
      </link>
      <pose>-3.5746 -1 0 0 -0 0</pose>
    </model>
    <model name='lumber_2x4x48'>
      <link name='link'>
        <inertial>
          <mass>1.4111</mass>
          <inertia>
            <ixx>0.0011</ixx>
            <ixy>0</ixy>
            <ixz>0</ixz>
            <iyy>0.1771</iyy>
            <iyz>0</iyz>
            <izz>0.1763</izz>
          </inertia>
        </inertial>
        <visual name='visual'>
          <geometry>
            <mesh>
              <uri>model://drc_practice_2x4/meshes/2x4x48.dae</uri>
            </mesh>
          </geometry>
        </visual>
        <velocity_decay>
          <linear>0</linear>
          <angular>0</angular>
        </velocity_decay>
        <self_collide>0</self_collide>
        <kinematic>0</kinematic>
        <gravity>1</gravity>
      </link>
      <pose>-3.54399 -2.59925 0 0 -0 0</pose>
      <static>1</static>
    </model>
    <model name='lumber_2x4x48_1'>
      <link name='link'>
        <inertial>
          <mass>1.4111</mass>
          <inertia>
            <ixx>0.0011</ixx>
            <ixy>0</ixy>
            <ixz>0</ixz>
            <iyy>0.1771</iyy>
            <iyz>0</iyz>
            <izz>0.1763</izz>
          </inertia>
        </inertial>
        <visual name='visual'>
          <geometry>
            <mesh>
              <uri>model://drc_practice_2x4/meshes/2x4x48.dae</uri>
            </mesh>
          </geometry>
        </visual>
        <velocity_decay>
          <linear>0</linear>
          <angular>0</angular>
        </velocity_decay>
        <self_collide>0</self_collide>
        <kinematic>0</kinematic>
        <gravity>1</gravity>
      </link>
      <pose>-3.53769 -2.52113 0 0 -0 0</pose>
      <static>1</static>
    </model>
    <model name='truss_1'>
      <link name='link'>
        <inertial>
          <mass>20.7307</mass>
          <inertia>
            <ixx>4.7978</ixx>
            <ixy>0</ixy>
            <ixz>0</ixz>
            <iyy>0.4699</iyy>
            <iyz>-0.002</iyz>
            <izz>4.7978</izz>
          </inertia>
        </inertial>
        <visual name='visual'>
          <geometry>
            <mesh>
              <uri>model://drc_practice_truss/meshes/truss.dae</uri>
            </mesh>
          </geometry>
        </visual>
        <velocity_decay>
          <linear>0</linear>
          <angular>0</angular>
        </velocity_decay>
        <self_collide>0</self_collide>
        <kinematic>0</kinematic>
        <gravity>1</gravity>
      </link>
      <pose>-4.47643 -1.5919 0 0 -0 0</pose>
      <static>1</static>
    </model>
    <model name='truss'>
      <link name='link'>
        <inertial>
          <mass>20.7307</mass>
          <inertia>
            <ixx>4.7978</ixx>
            <ixy>0</ixy>
            <ixz>0</ixz>
            <iyy>0.4699</iyy>
            <iyz>-0.002</iyz>
            <izz>4.7978</izz>
          </inertia>
        </inertial>
        <visual name='visual'>
          <geometry>
            <mesh>
              <uri>model://drc_practice_truss/meshes/truss.dae</uri>
            </mesh>
          </geometry>
        </visual>
        <velocity_decay>
          <linear>0</linear>
          <angular>0</angular>
        </velocity_decay>
        <self_collide>0</self_collide>
        <kinematic>0</kinematic>
        <gravity>1</gravity>
      </link>
      <pose>-4 -1.42264 0 0 -0 0</pose>
      <static>1</static>
    </model>
    <model name='truss_0'>
      <link name='link'>
        <inertial>
          <mass>20.7307</mass>
          <inertia>
            <ixx>4.7978</ixx>
            <ixy>0</ixy>
            <ixz>0</ixz>
            <iyy>0.4699</iyy>
            <iyz>-0.002</iyz>
            <izz>4.7978</izz>
          </inertia>
        </inertial>
        <visual name='visual'>
          <geometry>
            <mesh>
              <uri>model://drc_practice_truss/meshes/truss.dae</uri>
            </mesh>
          </geometry>
        </visual>
        <velocity_decay>
          <linear>0</linear>
          <angular>0</angular>
        </velocity_decay>
        <self_collide>0</self_collide>
        <kinematic>0</kinematic>
        <gravity>1</gravity>
      </link>
      <pose>-4 -2.50719 0 0 -0 0</pose>
      <static>1</static>
    </model>
    <model name='wood_slats'>
      <static>1</static>
      <link name='link'>
        <visual name='visual'>
          <geometry>
            <mesh>
              <uri>model://drc_practice_wood_slats/meshes/wood_slats.dae</uri>
            </mesh>
          </geometry>
        </visual>
        <velocity_decay>
          <linear>0</linear>
          <angular>0</angular>
        </velocity_decay>
        <self_collide>0</self_collide>
        <kinematic>0</kinematic>
        <gravity>1</gravity>
      </link>
      <pose>-4 -2 0 0 -0 0</pose>
    </model>
    <model name='grey_wall'>
      <static>1</static>
      <link name='link'>
        <pose>0 0 1.4 0 -0 0</pose>
        <visual name='visual'>
          <cast_shadows>0</cast_shadows>
          <geometry>
            <box>
              <size>7.5 0.2 2.8</size>
            </box>
          </geometry>
          <material>
            <script>
              <uri>model://grey_wall/materials/scripts</uri>
              <uri>model://grey_wall/materials/textures</uri>
              <name>vrc/grey_wall</name>
            </script>
          </material>
        </visual>
        <velocity_decay>
          <linear>0</linear>
          <angular>0</angular>
        </velocity_decay>
        <self_collide>0</self_collide>
        <kinematic>0</kinematic>
        <gravity>1</gravity>
      </link>
      <pose>-2.54896 -2 0 0 -0 0</pose>
    </model>
    <model name='ragdoll'>
      <pose>-4 -2.5048 1.4 0 -0 0</pose>
      <link name='hip'>
        <inertial>
          <inertia>
            <ixx>0.1</ixx>
            <ixy>0</ixy>
            <ixz>0</ixz>
            <iyy>0.1</iyy>
            <iyz>0</iyz>
            <izz>0.1</izz>
          </inertia>
          <mass>10</mass>
        </inertial>
        <visual name='hip_geom_visual'>
          <pose>0 0 0.125 0 -0 0</pose>
          <geometry>
            <box>
              <size>0.1 0.5 0.25</size>
            </box>
          </geometry>
          <cast_shadows>1</cast_shadows>
          <laser_retro>0</laser_retro>
          <transparency>0</transparency>
        </visual>
        <gravity>0</gravity>
        <self_collide>0</self_collide>
        <kinematic>0</kinematic>
        <velocity_decay>
          <linear>0</linear>
          <angular>0</angular>
        </velocity_decay>
      </link>
      <link name='l_thigh_pan'>
        <pose>0 0.22 0 0 -0 0</pose>
        <inertial>
          <inertia>
            <ixx>0.01</ixx>
            <ixy>0</ixy>
            <ixz>0</ixz>
            <iyy>0.01</iyy>
            <iyz>0</iyz>
            <izz>0.01</izz>
          </inertia>
          <mass>1</mass>
        </inertial>
        <visual name='l_thigh_pan_geom_visual'>
          <pose>0 0 -0.03 0 -0 0</pose>
          <geometry>
            <sphere>
              <radius>0.06</radius>
            </sphere>
          </geometry>
          <cast_shadows>1</cast_shadows>
          <laser_retro>0</laser_retro>
          <transparency>0</transparency>
        </visual>
        <gravity>0</gravity>
        <self_collide>0</self_collide>
        <kinematic>0</kinematic>
        <velocity_decay>
          <linear>0</linear>
          <angular>0</angular>
        </velocity_decay>
      </link>
      <link name='l_thigh_lift'>
        <pose>0 0.22 0 0 -0 0</pose>
        <inertial>
          <inertia>
            <ixx>0.05</ixx>
            <ixy>0</ixy>
            <ixz>0</ixz>
            <iyy>0.05</iyy>
            <iyz>0</iyz>
            <izz>0.05</izz>
          </inertia>
          <mass>5</mass>
        </inertial>
        <visual name='l_thigh_lift_geom_visual'>
          <pose>0 0 -0.35 0 -0 0</pose>
          <geometry>
            <cylinder>
              <radius>0.06</radius>
              <length>0.7</length>
            </cylinder>
          </geometry>
          <cast_shadows>1</cast_shadows>
          <laser_retro>0</laser_retro>
          <transparency>0</transparency>
        </visual>
        <gravity>0</gravity>
        <self_collide>0</self_collide>
        <kinematic>0</kinematic>
        <velocity_decay>
          <linear>0</linear>
          <angular>0</angular>
        </velocity_decay>
      </link>
      <link name='l_calf'>
        <pose>0 0.22 -0.7 0 -0 0</pose>
        <inertial>
          <inertia>
            <ixx>0.02</ixx>
            <ixy>0</ixy>
            <ixz>0</ixz>
            <iyy>0.02</iyy>
            <iyz>0</iyz>
            <izz>0.02</izz>
          </inertia>
          <mass>2</mass>
        </inertial>
        <visual name='l_calf_geom_visual'>
          <pose>0 0 -0.3 0 -0 0</pose>
          <geometry>
            <cylinder>
              <radius>0.05</radius>
              <length>0.6</length>
            </cylinder>
          </geometry>
          <cast_shadows>1</cast_shadows>
          <laser_retro>0</laser_retro>
          <transparency>0</transparency>
        </visual>
        <gravity>0</gravity>
        <self_collide>0</self_collide>
        <kinematic>0</kinematic>
        <velocity_decay>
          <linear>0</linear>
          <angular>0</angular>
        </velocity_decay>
      </link>
      <link name='l_ankle'>
        <pose>0 0.22 -1.325 0 -0 0</pose>
        <inertial>
          <inertia>
            <ixx>0.01</ixx>
            <ixy>0</ixy>
            <ixz>0</ixz>
            <iyy>0.01</iyy>
            <iyz>0</iyz>
            <izz>0.01</izz>
          </inertia>
          <mass>1</mass>
        </inertial>
        <visual name='l_ankle_geom_visual'>
          <geometry>
            <sphere>
              <radius>0.05</radius>
            </sphere>
          </geometry>
          <cast_shadows>1</cast_shadows>
          <laser_retro>0</laser_retro>
          <transparency>0</transparency>
        </visual>
        <gravity>0</gravity>
        <self_collide>0</self_collide>
        <kinematic>0</kinematic>
        <velocity_decay>
          <linear>0</linear>
          <angular>0</angular>
        </velocity_decay>
      </link>
      <link name='l_foot'>
        <pose>0 0.22 -1.35 0 -0 0</pose>
        <inertial>
          <pose>0.1 0 0 0 -0 0</pose>
          <inertia>
            <ixx>0.01</ixx>
            <ixy>0</ixy>
            <ixz>0</ixz>
            <iyy>0.01</iyy>
            <iyz>0</iyz>
            <izz>0.01</izz>
          </inertia>
          <mass>1</mass>
        </inertial>
        <visual name='l_foot_geom_visual'>
          <pose>0.1 0 -0.025 0 -0 0</pose>
          <geometry>
            <box>
              <size>0.2 0.03 0.05</size>
            </box>
          </geometry>
          <cast_shadows>1</cast_shadows>
          <laser_retro>0</laser_retro>
          <transparency>0</transparency>
        </visual>
        <gravity>1</gravity>
        <self_collide>0</self_collide>
        <kinematic>0</kinematic>
        <velocity_decay>
          <linear>0</linear>
          <angular>0</angular>
        </velocity_decay>
      </link>
      <link name='r_thigh_pan'>
        <pose>0 -0.22 0 0 -0 0</pose>
        <inertial>
          <inertia>
            <ixx>0.01</ixx>
            <ixy>0</ixy>
            <ixz>0</ixz>
            <iyy>0.01</iyy>
            <iyz>0</iyz>
            <izz>0.01</izz>
          </inertia>
          <mass>1</mass>
        </inertial>
        <visual name='r_thigh_pan_geom_visual'>
          <pose>0 0 -0.03 0 -0 0</pose>
          <geometry>
            <sphere>
              <radius>0.06</radius>
            </sphere>
          </geometry>
          <cast_shadows>1</cast_shadows>
          <laser_retro>0</laser_retro>
          <transparency>0</transparency>
        </visual>
        <gravity>0</gravity>
        <self_collide>0</self_collide>
        <kinematic>0</kinematic>
        <velocity_decay>
          <linear>0</linear>
          <angular>0</angular>
        </velocity_decay>
      </link>
      <link name='r_thigh_lift'>
        <pose>0 -0.22 0 0 -0 0</pose>
        <inertial>
          <inertia>
            <ixx>0.05</ixx>
            <ixy>0</ixy>
            <ixz>0</ixz>
            <iyy>0.05</iyy>
            <iyz>0</iyz>
            <izz>0.05</izz>
          </inertia>
          <mass>5</mass>
        </inertial>
        <visual name='r_thigh_lift_geom_visual'>
          <pose>0 0 -0.35 0 -0 0</pose>
          <geometry>
            <cylinder>
              <radius>0.06</radius>
              <length>0.7</length>
            </cylinder>
          </geometry>
          <cast_shadows>1</cast_shadows>
          <laser_retro>0</laser_retro>
          <transparency>0</transparency>
        </visual>
        <gravity>0</gravity>
        <self_collide>0</self_collide>
        <kinematic>0</kinematic>
        <velocity_decay>
          <linear>0</linear>
          <angular>0</angular>
        </velocity_decay>
      </link>
      <link name='r_calf'>
        <pose>0 -0.22 -0.7 0 -0 0</pose>
        <inertial>
          <inertia>
            <ixx>0.02</ixx>
            <ixy>0</ixy>
            <ixz>0</ixz>
            <iyy>0.02</iyy>
            <iyz>0</iyz>
            <izz>0.02</izz>
          </inertia>
          <mass>2</mass>
        </inertial>
        <visual name='r_calf_geom_visual'>
          <pose>0 0 -0.3 0 -0 0</pose>
          <geometry>
            <cylinder>
              <radius>0.05</radius>
              <length>0.6</length>
            </cylinder>
          </geometry>
          <cast_shadows>1</cast_shadows>
          <laser_retro>0</laser_retro>
          <transparency>0</transparency>
        </visual>
        <gravity>0</gravity>
        <self_collide>0</self_collide>
        <kinematic>0</kinematic>
        <velocity_decay>
          <linear>0</linear>
          <angular>0</angular>
        </velocity_decay>
      </link>
      <link name='r_ankle'>
        <pose>0 -0.22 -1.325 0 -0 0</pose>
        <inertial>
          <inertia>
            <ixx>0.01</ixx>
            <ixy>0</ixy>
            <ixz>0</ixz>
            <iyy>0.01</iyy>
            <iyz>0</iyz>
            <izz>0.01</izz>
          </inertia>
          <mass>1</mass>
        </inertial>
        <visual name='r_ankle_geom_visual'>
          <geometry>
            <sphere>
              <radius>0.05</radius>
            </sphere>
          </geometry>
          <cast_shadows>1</cast_shadows>
          <laser_retro>0</laser_retro>
          <transparency>0</transparency>
        </visual>
        <gravity>0</gravity>
        <self_collide>0</self_collide>
        <kinematic>0</kinematic>
        <velocity_decay>
          <linear>0</linear>
          <angular>0</angular>
        </velocity_decay>
      </link>
      <link name='r_foot'>
        <pose>0 -0.22 -1.35 0 -0 0</pose>
        <inertial>
          <pose>0.1 0 0 0 -0 0</pose>
          <inertia>
            <ixx>0.01</ixx>
            <ixy>0</ixy>
            <ixz>0</ixz>
            <iyy>0.01</iyy>
            <iyz>0</iyz>
            <izz>0.01</izz>
          </inertia>
          <mass>1</mass>
        </inertial>
        <visual name='r_foot_geom_visual'>
          <pose>0.1 0 -0.025 0 -0 0</pose>
          <geometry>
            <box>
              <size>0.2 0.03 0.05</size>
            </box>
          </geometry>
          <cast_shadows>1</cast_shadows>
          <laser_retro>0</laser_retro>
          <transparency>0</transparency>
        </visual>
        <gravity>1</gravity>
        <self_collide>0</self_collide>
        <kinematic>0</kinematic>
        <velocity_decay>
          <linear>0</linear>
          <angular>0</angular>
        </velocity_decay>
      </link>
      <link name='torso'>
        <pose>0 0 0.25 0 -0 0</pose>
        <inertial>
          <inertia>
            <ixx>0.3</ixx>
            <ixy>0</ixy>
            <ixz>0</ixz>
            <iyy>0.3</iyy>
            <iyz>0</iyz>
            <izz>0.3</izz>
          </inertia>
          <mass>30</mass>
        </inertial>
        <visual name='torso_geom_visual'>
          <pose>0 0 0.35 0 -0 0</pose>
          <geometry>
            <box>
              <size>0.1 0.6 0.7</size>
            </box>
          </geometry>
          <cast_shadows>1</cast_shadows>
          <laser_retro>0</laser_retro>
          <transparency>0</transparency>
        </visual>
        <gravity>0</gravity>
        <self_collide>0</self_collide>
        <kinematic>0</kinematic>
        <velocity_decay>
          <linear>0</linear>
          <angular>0</angular>
        </velocity_decay>
      </link>
      <link name='l_shoulder'>
        <pose>0 0.3275 0.9225 0 -0 0</pose>
        <inertial>
          <inertia>
            <ixx>0.01</ixx>
            <ixy>0</ixy>
            <ixz>0</ixz>
            <iyy>0.01</iyy>
            <iyz>0</iyz>
            <izz>0.01</izz>
          </inertia>
          <mass>1</mass>
        </inertial>
        <visual name='l_shoulder_geom_visual'>
          <geometry>
            <sphere>
              <radius>0.055</radius>
            </sphere>
          </geometry>
          <cast_shadows>1</cast_shadows>
          <laser_retro>0</laser_retro>
          <transparency>0</transparency>
        </visual>
        <gravity>0</gravity>
        <self_collide>0</self_collide>
        <kinematic>0</kinematic>
        <velocity_decay>
          <linear>0</linear>
          <angular>0</angular>
        </velocity_decay>
      </link>
      <link name='l_upper_arm'>
        <pose>0 0.3275 0.9225 0 -0 0</pose>
        <inertial>
          <inertia>
            <ixx>0.02</ixx>
            <ixy>0</ixy>
            <ixz>0</ixz>
            <iyy>0.02</iyy>
            <iyz>0</iyz>
            <izz>0.02</izz>
          </inertia>
          <mass>2</mass>
        </inertial>
        <visual name='l_upper_arm_geom_visual'>
          <pose>0 0 -0.3 0 -0 0</pose>
          <geometry>
            <cylinder>
              <radius>0.055</radius>
              <length>0.6</length>
            </cylinder>
          </geometry>
          <cast_shadows>1</cast_shadows>
          <laser_retro>0</laser_retro>
          <transparency>0</transparency>
        </visual>
        <gravity>0</gravity>
        <self_collide>0</self_collide>
        <kinematic>0</kinematic>
        <velocity_decay>
          <linear>0</linear>
          <angular>0</angular>
        </velocity_decay>
      </link>
      <link name='l_forearm'>
        <pose>0 0.3275 0.3225 0 -0 0</pose>
        <inertial>
          <inertia>
            <ixx>0.01</ixx>
            <ixy>0</ixy>
            <ixz>0</ixz>
            <iyy>0.01</iyy>
            <iyz>0</iyz>
            <izz>0.01</izz>
          </inertia>
          <mass>1</mass>
        </inertial>
        <visual name='l_forearm_geom_visual'>
          <pose>0 0 -0.225 0 -0 0</pose>
          <geometry>
            <cylinder>
              <radius>0.05</radius>
              <length>0.45</length>
            </cylinder>
          </geometry>
          <cast_shadows>1</cast_shadows>
          <laser_retro>0</laser_retro>
          <transparency>0</transparency>
        </visual>
        <gravity>0</gravity>
        <self_collide>0</self_collide>
        <kinematic>0</kinematic>
        <velocity_decay>
          <linear>0</linear>
          <angular>0</angular>
        </velocity_decay>
      </link>
      <link name='l_wrist'>
        <pose>0 0.3275 -0.1425 0 -0 0</pose>
        <inertial>
          <inertia>
            <ixx>0.01</ixx>
            <ixy>0</ixy>
            <ixz>0</ixz>
            <iyy>0.01</iyy>
            <iyz>0</iyz>
            <izz>0.01</izz>
          </inertia>
          <mass>1</mass>
        </inertial>
        <visual name='l_wrist_geom_visual'>
          <geometry>
            <sphere>
              <radius>0.03</radius>
            </sphere>
          </geometry>
          <cast_shadows>1</cast_shadows>
          <laser_retro>0</laser_retro>
          <transparency>0</transparency>
        </visual>
        <gravity>0</gravity>
        <self_collide>0</self_collide>
        <kinematic>0</kinematic>
        <velocity_decay>
          <linear>0</linear>
          <angular>0</angular>
        </velocity_decay>
      </link>
      <link name='l_hand'>
        <pose>0 0.3275 -0.1575 0 -0 0</pose>
        <inertial>
          <inertia>
            <ixx>0.01</ixx>
            <ixy>0</ixy>
            <ixz>0</ixz>
            <iyy>0.01</iyy>
            <iyz>0</iyz>
            <izz>0.01</izz>
          </inertia>
          <mass>1</mass>
        </inertial>
        <visual name='l_hand_geom_visual'>
          <pose>0 0 -0.1 0 -0 0</pose>
          <geometry>
            <box>
              <size>0.03 0.1 0.2</size>
            </box>
          </geometry>
          <cast_shadows>1</cast_shadows>
          <laser_retro>0</laser_retro>
          <transparency>0</transparency>
        </visual>
        <gravity>0</gravity>
        <self_collide>0</self_collide>
        <kinematic>0</kinematic>
        <velocity_decay>
          <linear>0</linear>
          <angular>0</angular>
        </velocity_decay>
      </link>
      <link name='neck'>
        <pose>0 0 0.95 0 -0 0</pose>
        <inertial>
          <inertia>
            <ixx>0.01</ixx>
            <ixy>0</ixy>
            <ixz>0</ixz>
            <iyy>0.01</iyy>
            <iyz>0</iyz>
            <izz>0.01</izz>
          </inertia>
          <mass>1</mass>
        </inertial>
        <visual name='neck_geom_visual'>
          <pose>0 0 0.1 0 -0 0</pose>
          <geometry>
            <cylinder>
              <radius>0.075</radius>
              <length>0.2</length>
            </cylinder>
          </geometry>
          <cast_shadows>1</cast_shadows>
          <laser_retro>0</laser_retro>
          <transparency>0</transparency>
        </visual>
        <gravity>0</gravity>
        <self_collide>0</self_collide>
        <kinematic>0</kinematic>
        <velocity_decay>
          <linear>0</linear>
          <angular>0</angular>
        </velocity_decay>
      </link>
      <link name='head'>
        <pose>0 0 1.225 0 -0 0</pose>
        <inertial>
          <inertia>
            <ixx>0.1</ixx>
            <ixy>0</ixy>
            <ixz>0</ixz>
            <iyy>0.1</iyy>
            <iyz>0</iyz>
            <izz>0.1</izz>
          </inertia>
          <mass>10</mass>
        </inertial>
        <visual name='head_geom_visual'>
          <geometry>
            <sphere>
              <radius>0.15</radius>
            </sphere>
          </geometry>
          <cast_shadows>1</cast_shadows>
          <laser_retro>0</laser_retro>
          <transparency>0</transparency>
        </visual>
        <gravity>0</gravity>
        <self_collide>0</self_collide>
        <kinematic>0</kinematic>
        <velocity_decay>
          <linear>0</linear>
          <angular>0</angular>
        </velocity_decay>
      </link>
      <link name='r_shoulder'>
        <pose>0 -0.3275 0.9225 0 -0 0</pose>
        <inertial>
          <inertia>
            <ixx>0.01</ixx>
            <ixy>0</ixy>
            <ixz>0</ixz>
            <iyy>0.01</iyy>
            <iyz>0</iyz>
            <izz>0.01</izz>
          </inertia>
          <mass>1</mass>
        </inertial>
        <visual name='r_shoulder_geom_visual'>
          <geometry>
            <sphere>
              <radius>0.055</radius>
            </sphere>
          </geometry>
          <cast_shadows>1</cast_shadows>
          <laser_retro>0</laser_retro>
          <transparency>0</transparency>
        </visual>
        <gravity>0</gravity>
        <self_collide>0</self_collide>
        <kinematic>0</kinematic>
        <velocity_decay>
          <linear>0</linear>
          <angular>0</angular>
        </velocity_decay>
      </link>
      <link name='r_upper_arm'>
        <pose>0 -0.3275 0.9225 0 -0 0</pose>
        <inertial>
          <inertia>
            <ixx>0.02</ixx>
            <ixy>0</ixy>
            <ixz>0</ixz>
            <iyy>0.02</iyy>
            <iyz>0</iyz>
            <izz>0.02</izz>
          </inertia>
          <mass>2</mass>
        </inertial>
        <visual name='r_upper_arm_geom_visual'>
          <pose>0 0 -0.3 0 -0 0</pose>
          <geometry>
            <cylinder>
              <radius>0.055</radius>
              <length>0.6</length>
            </cylinder>
          </geometry>
          <cast_shadows>1</cast_shadows>
          <laser_retro>0</laser_retro>
          <transparency>0</transparency>
        </visual>
        <gravity>0</gravity>
        <self_collide>0</self_collide>
        <kinematic>0</kinematic>
        <velocity_decay>
          <linear>0</linear>
          <angular>0</angular>
        </velocity_decay>
      </link>
      <link name='r_forearm'>
        <pose>0 -0.3275 0.3225 0 -0 0</pose>
        <inertial>
          <inertia>
            <ixx>0.01</ixx>
            <ixy>0</ixy>
            <ixz>0</ixz>
            <iyy>0.01</iyy>
            <iyz>0</iyz>
            <izz>0.01</izz>
          </inertia>
          <mass>1</mass>
        </inertial>
        <visual name='r_forearm_geom_visual'>
          <pose>0 0 -0.225 0 -0 0</pose>
          <geometry>
            <cylinder>
              <radius>0.05</radius>
              <length>0.45</length>
            </cylinder>
          </geometry>
          <cast_shadows>1</cast_shadows>
          <laser_retro>0</laser_retro>
          <transparency>0</transparency>
        </visual>
        <gravity>0</gravity>
        <self_collide>0</self_collide>
        <kinematic>0</kinematic>
        <velocity_decay>
          <linear>0</linear>
          <angular>0</angular>
        </velocity_decay>
      </link>
      <link name='r_wrist'>
        <pose>0 -0.3275 -0.1425 0 -0 0</pose>
        <inertial>
          <inertia>
            <ixx>0.01</ixx>
            <ixy>0</ixy>
            <ixz>0</ixz>
            <iyy>0.01</iyy>
            <iyz>0</iyz>
            <izz>0.01</izz>
          </inertia>
          <mass>1</mass>
        </inertial>
        <visual name='r_wrist_geom_visual'>
          <geometry>
            <sphere>
              <radius>0.03</radius>
            </sphere>
          </geometry>
          <cast_shadows>1</cast_shadows>
          <laser_retro>0</laser_retro>
          <transparency>0</transparency>
        </visual>
        <gravity>0</gravity>
        <self_collide>0</self_collide>
        <kinematic>0</kinematic>
        <velocity_decay>
          <linear>0</linear>
          <angular>0</angular>
        </velocity_decay>
      </link>
      <link name='r_hand'>
        <pose>0 -0.3275 -0.1575 0 -0 0</pose>
        <inertial>
          <inertia>
            <ixx>0.01</ixx>
            <ixy>0</ixy>
            <ixz>0</ixz>
            <iyy>0.01</iyy>
            <iyz>0</iyz>
            <izz>0.01</izz>
          </inertia>
          <mass>1</mass>
        </inertial>
        <visual name='r_hand_geom_visual'>
          <pose>0 0 -0.1 0 -0 0</pose>
          <geometry>
            <box>
              <size>0.03 0.1 0.2</size>
            </box>
          </geometry>
          <cast_shadows>1</cast_shadows>
          <laser_retro>0</laser_retro>
          <transparency>0</transparency>
        </visual>
        <gravity>0</gravity>
        <self_collide>0</self_collide>
        <kinematic>0</kinematic>
        <velocity_decay>
          <linear>0</linear>
          <angular>0</angular>
        </velocity_decay>
      </link>
      <joint name='l_thigh_pan_joint' type='revolute'>
        <parent>hip</parent>
        <child>l_thigh_pan</child>
        <axis>
          <dynamics>
            <damping>0</damping>
            <friction>0</friction>
          </dynamics>
          <limit>
            <lower>-1.5708</lower>
            <upper>1.5708</upper>
            <effort>0</effort>
            <velocity>0</velocity>
          </limit>
          <xyz>0 0 1</xyz>
        </axis>
      </joint>
      <joint name='l_thigh_lift_joint' type='revolute'>
        <parent>l_thigh_pan</parent>
        <child>l_thigh_lift</child>
        <axis>
          <dynamics>
            <damping>0</damping>
            <friction>0</friction>
          </dynamics>
          <limit>
            <lower>-1.5708</lower>
            <upper>1.5708</upper>
            <effort>0</effort>
            <velocity>0</velocity>
          </limit>
          <xyz>0 1 0</xyz>
        </axis>
      </joint>
      <joint name='l_calf_joint' type='revolute'>
        <parent>l_thigh_lift</parent>
        <child>l_calf</child>
        <axis>
          <dynamics>
            <damping>0</damping>
            <friction>0</friction>
          </dynamics>
          <limit>
            <lower>-1.5708</lower>
            <upper>1.5708</upper>
            <effort>0</effort>
            <velocity>0</velocity>
          </limit>
          <xyz>0 1 0</xyz>
        </axis>
      </joint>
      <joint name='l_ankle_joint' type='revolute'>
        <parent>l_calf</parent>
        <child>l_ankle</child>
        <axis>
          <dynamics>
            <damping>0</damping>
            <friction>0</friction>
          </dynamics>
          <limit>
            <lower>-1.5708</lower>
            <upper>1.5708</upper>
            <effort>0</effort>
            <velocity>0</velocity>
          </limit>
          <xyz>0 1 0</xyz>
        </axis>
      </joint>
      <joint name='l_foot_joint' type='revolute'>
        <parent>l_ankle</parent>
        <child>l_foot</child>
        <axis>
          <dynamics>
            <damping>0</damping>
            <friction>0</friction>
          </dynamics>
          <limit>
            <lower>-1.5708</lower>
            <upper>1.5708</upper>
            <effort>0</effort>
            <velocity>0</velocity>
          </limit>
          <xyz>1 0 0</xyz>
        </axis>
      </joint>
      <joint name='r_thigh_pan_joint' type='revolute'>
        <parent>hip</parent>
        <child>r_thigh_pan</child>
        <axis>
          <dynamics>
            <damping>0</damping>
            <friction>0</friction>
          </dynamics>
          <limit>
            <lower>-1.5708</lower>
            <upper>1.5708</upper>
            <effort>0</effort>
            <velocity>0</velocity>
          </limit>
          <xyz>0 0 1</xyz>
        </axis>
      </joint>
      <joint name='r_thigh_lift_joint' type='revolute'>
        <parent>r_thigh_pan</parent>
        <child>r_thigh_lift</child>
        <axis>
          <dynamics>
            <damping>0</damping>
            <friction>0</friction>
          </dynamics>
          <limit>
            <lower>-1.5708</lower>
            <upper>1.5708</upper>
            <effort>0</effort>
            <velocity>0</velocity>
          </limit>
          <xyz>0 1 0</xyz>
        </axis>
      </joint>
      <joint name='r_calf_joint' type='revolute'>
        <parent>r_thigh_lift</parent>
        <child>r_calf</child>
        <axis>
          <dynamics>
            <damping>0</damping>
            <friction>0</friction>
          </dynamics>
          <limit>
            <lower>-1.5708</lower>
            <upper>1.5708</upper>
            <effort>0</effort>
            <velocity>0</velocity>
          </limit>
          <xyz>0 1 0</xyz>
        </axis>
      </joint>
      <joint name='r_ankle_joint' type='revolute'>
        <parent>r_calf</parent>
        <child>r_ankle</child>
        <axis>
          <dynamics>
            <damping>0</damping>
            <friction>0</friction>
          </dynamics>
          <limit>
            <lower>-1.5708</lower>
            <upper>1.5708</upper>
            <effort>0</effort>
            <velocity>0</velocity>
          </limit>
          <xyz>0 1 0</xyz>
        </axis>
      </joint>
      <joint name='r_foot_joint' type='revolute'>
        <parent>r_ankle</parent>
        <child>r_foot</child>
        <axis>
          <dynamics>
            <damping>0</damping>
            <friction>0</friction>
          </dynamics>
          <limit>
            <lower>-1.5708</lower>
            <upper>1.5708</upper>
            <effort>0</effort>
            <velocity>0</velocity>
          </limit>
          <xyz>1 0 0</xyz>
        </axis>
      </joint>
      <joint name='torso_joint' type='revolute'>
        <parent>hip</parent>
        <child>torso</child>
        <axis>
          <dynamics>
            <damping>0</damping>
            <friction>0</friction>
          </dynamics>
          <limit>
            <lower>-1.5708</lower>
            <upper>1.5708</upper>
            <effort>0</effort>
            <velocity>0</velocity>
          </limit>
          <xyz>0 1 0</xyz>
        </axis>
      </joint>
      <joint name='l_shoulder_joint' type='revolute'>
        <parent>torso</parent>
        <child>l_shoulder</child>
        <axis>
          <dynamics>
            <damping>0</damping>
            <friction>0</friction>
          </dynamics>
          <limit>
            <lower>-1.5708</lower>
            <upper>1.5708</upper>
            <effort>0</effort>
            <velocity>0</velocity>
          </limit>
          <xyz>1 0 0</xyz>
        </axis>
      </joint>
      <joint name='l_upper_arm_joint' type='revolute'>
        <parent>l_shoulder</parent>
        <child>l_upper_arm</child>
        <axis>
          <dynamics>
            <damping>0</damping>
            <friction>0</friction>
          </dynamics>
          <limit>
            <lower>-1.5708</lower>
            <upper>1.5708</upper>
            <effort>0</effort>
            <velocity>0</velocity>
          </limit>
          <xyz>0 1 0</xyz>
        </axis>
      </joint>
      <joint name='l_forearm_joint' type='revolute'>
        <parent>l_upper_arm</parent>
        <child>l_forearm</child>
        <axis>
          <dynamics>
            <damping>0</damping>
            <friction>0</friction>
          </dynamics>
          <limit>
            <lower>-1.5708</lower>
            <upper>1.5708</upper>
            <effort>0</effort>
            <velocity>0</velocity>
          </limit>
          <xyz>0 1 0</xyz>
        </axis>
      </joint>
      <joint name='l_wrist_joint' type='revolute'>
        <parent>l_forearm</parent>
        <child>l_wrist</child>
        <axis>
          <dynamics>
            <damping>0</damping>
            <friction>0</friction>
          </dynamics>
          <limit>
            <lower>-1.5708</lower>
            <upper>1.5708</upper>
            <effort>0</effort>
            <velocity>0</velocity>
          </limit>
          <xyz>0 1 0</xyz>
        </axis>
      </joint>
      <joint name='l_hand_joint' type='revolute'>
        <parent>l_wrist</parent>
        <child>l_hand</child>
        <axis>
          <dynamics>
            <damping>0</damping>
            <friction>0</friction>
          </dynamics>
          <limit>
            <lower>-1.5708</lower>
            <upper>1.5708</upper>
            <effort>0</effort>
            <velocity>0</velocity>
          </limit>
          <xyz>0 1 0</xyz>
        </axis>
      </joint>
      <joint name='neck_joint' type='revolute'>
        <parent>torso</parent>
        <child>neck</child>
        <axis>
          <dynamics>
            <damping>0</damping>
            <friction>0</friction>
          </dynamics>
          <limit>
            <lower>-1.5708</lower>
            <upper>1.5708</upper>
            <effort>0</effort>
            <velocity>0</velocity>
          </limit>
          <xyz>0 0 1</xyz>
        </axis>
      </joint>
      <joint name='head_joint' type='revolute'>
        <parent>neck</parent>
        <child>head</child>
        <axis>
          <dynamics>
            <damping>0</damping>
            <friction>0</friction>
          </dynamics>
          <limit>
            <lower>-1.5708</lower>
            <upper>1.5708</upper>
            <effort>0</effort>
            <velocity>0</velocity>
          </limit>
          <xyz>0 1 0</xyz>
        </axis>
      </joint>
      <joint name='r_shoulder_joint' type='revolute'>
        <parent>torso</parent>
        <child>r_shoulder</child>
        <axis>
          <dynamics>
            <damping>0</damping>
            <friction>0</friction>
          </dynamics>
          <limit>
            <lower>-1.5708</lower>
            <upper>1.5708</upper>
            <effort>0</effort>
            <velocity>0</velocity>
          </limit>
          <xyz>1 0 0</xyz>
        </axis>
      </joint>
      <joint name='r_upper_arm_joint' type='revolute'>
        <parent>r_shoulder</parent>
        <child>r_upper_arm</child>
        <axis>
          <dynamics>
            <damping>0</damping>
            <friction>0</friction>
          </dynamics>
          <limit>
            <lower>-1.5708</lower>
            <upper>1.5708</upper>
            <effort>0</effort>
            <velocity>0</velocity>
          </limit>
          <xyz>0 1 0</xyz>
        </axis>
      </joint>
      <joint name='r_forearm_joint' type='revolute'>
        <parent>r_upper_arm</parent>
        <child>r_forearm</child>
        <axis>
          <dynamics>
            <damping>0</damping>
            <friction>0</friction>
          </dynamics>
          <limit>
            <lower>-1.5708</lower>
            <upper>1.5708</upper>
            <effort>0</effort>
            <velocity>0</velocity>
          </limit>
          <xyz>0 1 0</xyz>
        </axis>
      </joint>
      <joint name='r_wrist_joint' type='revolute'>
        <parent>r_forearm</parent>
        <child>r_wrist</child>
        <axis>
          <dynamics>
            <damping>0</damping>
            <friction>0</friction>
          </dynamics>
          <limit>
            <lower>-1.5708</lower>
            <upper>1.5708</upper>
            <effort>0</effort>
            <velocity>0</velocity>
          </limit>
          <xyz>0 1 0</xyz>
        </axis>
      </joint>
      <joint name='r_hand_joint' type='revolute'>
        <parent>r_wrist</parent>
        <child>r_hand</child>
        <axis>
          <dynamics>
            <damping>0</damping>
            <friction>0</friction>
          </dynamics>
          <limit>
            <lower>-1.5708</lower>
            <upper>1.5708</upper>
            <effort>0</effort>
            <velocity>0</velocity>
          </limit>
          <xyz>0 1 0</xyz>
        </axis>
      </joint>
      <static>1</static>
    </model>
    <model name='standpipe'>
      <static>1</static>
      <link name='standpipe'>
        <pose>0 0 0.1 0 1.57078 0</pose>
        <visual name='visual'>
          <pose>0 0 0.15 0 -0 0</pose>
          <geometry>
            <mesh>
              <uri>model://standpipe/meshes/standpipe.dae</uri>
            </mesh>
          </geometry>
        </visual>
        <velocity_decay>
          <linear>0</linear>
          <angular>0</angular>
        </velocity_decay>
        <self_collide>0</self_collide>
        <kinematic>0</kinematic>
        <gravity>1</gravity>
      </link>
      <pose>-2.44761 -2 0 0 -0 0</pose>
    </model>
    <model name='wall_plumbing'>
      <static>1</static>
      <link name='link'>
        <pose>0 0 0 0 -0 0</pose>
        <collision name='collision'>
          <geometry>
            <box>
              <size>1.2105 2.5142 0.01</size>
            </box>
          </geometry>
          <max_contacts>10</max_contacts>
          <surface>
            <bounce/>
            <friction>
              <ode/>
            </friction>
            <contact>
              <ode/>
            </contact>
          </surface>
        </collision>
        <visual name='visual'>
          <cast_shadows>0</cast_shadows>
          <geometry>
            <box>
              <size>1.2105 2.5142 0.01</size>
            </box>
          </geometry>
          <material>
            <script>
              <uri>model://wall_plumbing/materials/scripts</uri>
              <uri>model://wall_plumbing/materials/textures</uri>
              <name>wall_plumbing</name>
            </script>
          </material>
        </visual>
        <velocity_decay>
          <linear>0</linear>
          <angular>0</angular>
        </velocity_decay>
        <self_collide>0</self_collide>
        <kinematic>0</kinematic>
        <gravity>1</gravity>
      </link>
      <pose>-3.42731 -1.43638 0 0 -0 0</pose>
    </model>
  </world>
</sdf>
