<sdf version='1.4'>
  <world name='default'>
    <light name='sun' type='directional'>
      <cast_shadows>1</cast_shadows>
      <pose>2 0 10 0 -0 0</pose>
      <diffuse>0.8 0.8 0.8 1</diffuse>
      <specular>0.2 0.2 0.2 1</specular>
      <attenuation>
        <range>1000</range>
        <constant>0.9</constant>
        <linear>0.01</linear>
        <quadratic>0.001</quadratic>
      </attenuation>
      <direction>-0.5 0.1 -0.9</direction>
    </light>
    <model name='ground_plane'>
      <static>1</static>
      <link name='link'>
        <collision name='collision'>
          <geometry>
            <plane>
              <normal>0 0 1</normal>
              <size>100 100</size>
            </plane>
          </geometry>
          <surface>
            <friction>
              <ode>
                <mu>100</mu>
                <mu2>50</mu2>
              </ode>
            </friction>
            <bounce/>
            <contact>
              <ode/>
            </contact>
          </surface>
          <max_contacts>10</max_contacts>
        </collision>
        <visual name='visual'>
          <cast_shadows>0</cast_shadows>
          <geometry>
            <plane>
              <normal>0 0 1</normal>
              <size>100 100</size>
            </plane>
          </geometry>
          <material>
            <script>
              <uri>file://media/materials/scripts/gazebo.material</uri>
              <name>Gazebo/Grey</name>
            </script>
          </material>
        </visual>
        <velocity_decay>
          <linear>0</linear>
          <angular>0</angular>
        </velocity_decay>
        <self_collide>0</self_collide>
        <kinematic>0</kinematic>
        <gravity>0</gravity>
      </link>
    </model>
    <physics type='ode'>
      <max_step_size>0.001</max_step_size>
      <real_time_factor>1</real_time_factor>
      <real_time_update_rate>1000</real_time_update_rate>
      <gravity>0 0 -9.8</gravity>
    </physics>
    <scene>
      <ambient>0.4 0.4 0.4 1</ambient>
      <background>0.7 0.7 0.7 1</background>
      <shadows>1</shadows>
    </scene>
    <model name='Speed limit'>
      <static>1</static>
      <link name='link'>
        <collision name='collision'>
          <geometry>
            <mesh>
              <scale>10 10 10</scale>
              <uri>model://speed_limit_sign/meshes/speed_limit_sign.dae</uri>
            </mesh>
          </geometry>
          <max_contacts>10</max_contacts>
          <surface>
            <bounce/>
            <friction>
              <ode/>
            </friction>
            <contact>
              <ode/>
            </contact>
          </surface>
        </collision>
        <visual name='visual'>
          <geometry>
            <mesh>
              <scale>10 10 10</scale>
              <uri>model://speed_limit_sign/meshes/speed_limit_sign.dae</uri>
            </mesh>
          </geometry>
        </visual>
        <velocity_decay>
          <linear>0</linear>
          <angular>0</angular>
        </velocity_decay>
        <self_collide>0</self_collide>
        <kinematic>0</kinematic>
        <gravity>0</gravity>
      </link>
      <pose>0.683787 -0.745205 0 0 -0 0</pose>
    </model>
    <model name='Stop Sign'>
      <link name='link'>
        <collision name='collision'>
          <geometry>
            <mesh>
              <uri>model://stop_sign/meshes/stop_sign.dae</uri>
            </mesh>
          </geometry>
          <max_contacts>10</max_contacts>
          <surface>
            <bounce/>
            <friction>
              <ode/>
            </friction>
            <contact>
              <ode/>
            </contact>
          </surface>
        </collision>
        <visual name='visual'>
          <geometry>
            <mesh>
              <uri>model://stop_sign/meshes/stop_sign.dae</uri>
            </mesh>
          </geometry>
          <material>
            <script>
              <uri>model://stop_sign/materials/scripts</uri>
              <uri>model://stop_sign/materials/textures</uri>
              <name>StopSign/Diffuse</name>
            </script>
          </material>
        </visual>
        <velocity_decay>
          <linear>0</linear>
          <angular>0</angular>
        </velocity_decay>
        <self_collide>0</self_collide>
        <inertial>
          <inertia>
            <ixx>1</ixx>
            <ixy>0</ixy>
            <ixz>0</ixz>
            <iyy>1</iyy>
            <iyz>0</iyz>
            <izz>1</izz>
          </inertia>
          <mass>1</mass>
        </inertial>
        <kinematic>0</kinematic>
        <gravity>0</gravity>
      </link>
      <pose>1.30293 -0.659447 0 0 -0 0</pose>
      <static>1</static>
    </model>
    <model name='fire_hose_long_curled_1'>
      <pose>4 -3 0.055 0 -0 0</pose>
      <link name='coupling'>
        <inertial>
          <pose>-0.07 0 0 0 -0 0</pose>
          <mass>0.1</mass>
          <inertia>
            <ixx>0.01</ixx>
            <ixy>0</ixy>
            <ixz>0</ixz>
            <iyy>0.01</iyy>
            <iyz>0</iyz>
            <izz>0.01</izz>
          </inertia>
        </inertial>
        <collision name='coupling_collision'>
          <pose>-0.01 0 0 0 -1.57079 0</pose>
          <geometry>
            <mesh>
              <scale>0.4 0.4 0.8</scale>
              <uri>model://fire_hose_long_curled/meshes/coupling_hexagon.dae</uri>
            </mesh>
          </geometry>
          <surface>
            <friction>
              <ode>
                <mu>1</mu>
                <mu2>1</mu2>
              </ode>
            </friction>
            <bounce/>
            <contact>
              <ode/>
            </contact>
          </surface>
          <max_contacts>10</max_contacts>
        </collision>
        <visual name='coupling_vis'>
          <pose>-0.01 0 0 0 -1.57079 0</pose>
          <geometry>
            <mesh>
              <scale>0.4 0.4 0.8</scale>
              <uri>model://fire_hose_long_curled/meshes/coupling_hexagon.dae</uri>
            </mesh>
          </geometry>
          <material>
            <script>
              <uri>model://fire_hose_long_curled/materials/scripts</uri>
              <uri>model://fire_hose_long_curled/materials/textures</uri>
              <name>fire_hose_long_curled/fire_hose_coupling</name>
            </script>
          </material>
        </visual>
        <visual name='attachment_vis'>
          <pose>-0.1225 0 0 0 -1.57079 0</pose>
          <geometry>
            <mesh>
              <uri>model://fire_hose_long_curled/meshes/connector.dae</uri>
            </mesh>
          </geometry>
          <material>
            <script>
              <uri>model://fire_hose_long_curled/materials/scripts</uri>
              <uri>model://fire_hose_long_curled/materials/textures</uri>
              <name>fire_hose_long_curled/fire_hose_red_coupling</name>
            </script>
          </material>
        </visual>
        <collision name='attachment_col'>
          <pose>-0.1225 0 0 0 -1.57079 0</pose>
          <geometry>
            <cylinder>
              <length>0.025</length>
              <radius>0.055</radius>
            </cylinder>
          </geometry>
          <surface>
            <contact>
              <ode>
                <min_depth>0.005</min_depth>
              </ode>
            </contact>
            <friction>
              <ode>
                <mu>1</mu>
                <mu2>1</mu2>
              </ode>
            </friction>
            <bounce/>
          </surface>
          <max_contacts>10</max_contacts>
        </collision>
        <velocity_decay>
          <linear>0</linear>
          <angular>0</angular>
        </velocity_decay>
        <self_collide>0</self_collide>
        <kinematic>0</kinematic>
        <gravity>0</gravity>
      </link>
      <link name='link_00'>
        <gravity>0</gravity>
        <pose>0.1 0 0 0 -0 0</pose>
        <inertial>
          <mass>0.1</mass>
          <pose>0.1 0 0 0 -0 0</pose>
          <inertia>
            <ixx>0.01</ixx>
            <ixy>0</ixy>
            <ixz>0</ixz>
            <iyy>0.01</iyy>
            <iyz>0</iyz>
            <izz>0.01</izz>
          </inertia>
        </inertial>
        <visual name='sphere'>
          <geometry>
            <sphere>
              <radius>0.025</radius>
            </sphere>
          </geometry>
          <material>
            <script>
              <uri>model://fire_hose_long_curled/materials/scripts</uri>
              <uri>model://fire_hose_long_curled/materials/textures</uri>
              <name>fire_hose_long_curled/fire_hose_canvas</name>
            </script>
          </material>
        </visual>
        <velocity_decay>
          <linear>0</linear>
          <angular>0</angular>
        </velocity_decay>
        <self_collide>0</self_collide>
        <kinematic>0</kinematic>
      </link>
      <link name='link_01'>
        <gravity>0</gravity>
        <pose>0.1 0 0 0 -0 0</pose>
        <inertial>
          <mass>0.1</mass>
          <pose>0.1 0 0 0 -0 0</pose>
          <inertia>
            <ixx>0.01</ixx>
            <ixy>0</ixy>
            <ixz>0</ixz>
            <iyy>0.01</iyy>
            <iyz>0</iyz>
            <izz>0.01</izz>
          </inertia>
        </inertial>
        <collision name='collision'>
          <pose>0.1 0 0 0 1.57079 0</pose>
          <geometry>
            <cylinder>
              <length>0.2</length>
              <radius>0.025</radius>
            </cylinder>
          </geometry>
          <surface>
            <contact>
              <ode>
                <min_depth>0.005</min_depth>
              </ode>
            </contact>
            <friction>
              <ode>
                <mu>1</mu>
                <mu2>1</mu2>
              </ode>
            </friction>
            <bounce/>
          </surface>
          <max_contacts>10</max_contacts>
        </collision>
        <visual name='visual'>
          <pose>0.1 0 0 0 1.57079 0</pose>
          <geometry>
            <cylinder>
              <length>0.2</length>
              <radius>0.025</radius>
            </cylinder>
          </geometry>
          <material>
            <script>
              <uri>model://fire_hose_long_curled/materials/scripts</uri>
              <uri>model://fire_hose_long_curled/materials/textures</uri>
              <name>fire_hose_long_curled/fire_hose_canvas</name>
            </script>
          </material>
        </visual>
        <velocity_decay>
          <linear>0</linear>
          <angular>0</angular>
        </velocity_decay>
        <self_collide>0</self_collide>
        <kinematic>0</kinematic>
      </link>
      <link name='link_02'>
        <gravity>0</gravity>
        <pose>0.3 0 0 0 -0 0</pose>
        <inertial>
          <mass>0.1</mass>
          <pose>0.1 0 0 0 -0 0</pose>
          <inertia>
            <ixx>0.01</ixx>
            <ixy>0</ixy>
            <ixz>0</ixz>
            <iyy>0.01</iyy>
            <iyz>0</iyz>
            <izz>0.01</izz>
          </inertia>
        </inertial>
        <collision name='collision'>
          <pose>0.1 0 0 0 1.57079 0</pose>
          <geometry>
            <cylinder>
              <length>0.2</length>
              <radius>0.025</radius>
            </cylinder>
          </geometry>
          <surface>
            <contact>
              <ode>
                <min_depth>0.005</min_depth>
              </ode>
            </contact>
            <friction>
              <ode>
                <mu>1</mu>
                <mu2>1</mu2>
              </ode>
            </friction>
            <bounce/>
          </surface>
          <max_contacts>10</max_contacts>
        </collision>
        <visual name='visual'>
          <pose>0.1 0 0 0 1.57079 0</pose>
          <geometry>
            <cylinder>
              <length>0.2</length>
              <radius>0.025</radius>
            </cylinder>
          </geometry>
          <material>
            <script>
              <uri>model://fire_hose_long_curled/materials/scripts</uri>
              <uri>model://fire_hose_long_curled/materials/textures</uri>
              <name>fire_hose_long_curled/fire_hose_canvas</name>
            </script>
          </material>
        </visual>
        <visual name='sphere'>
          <geometry>
            <sphere>
              <radius>0.025</radius>
            </sphere>
          </geometry>
          <material>
            <script>
              <uri>model://fire_hose_long_curled/materials/scripts</uri>
              <uri>model://fire_hose_long_curled/materials/textures</uri>
              <name>fire_hose_long_curled/fire_hose_canvas</name>
            </script>
          </material>
        </visual>
        <velocity_decay>
          <linear>0</linear>
          <angular>0</angular>
        </velocity_decay>
        <self_collide>0</self_collide>
        <kinematic>0</kinematic>
      </link>
      <link name='link_03'>
        <gravity>0</gravity>
        <pose>0.5 0 0 0 -0 0</pose>
        <inertial>
          <mass>0.1</mass>
          <pose>0.1 0 0 0 -0 0</pose>
          <inertia>
            <ixx>0.01</ixx>
            <ixy>0</ixy>
            <ixz>0</ixz>
            <iyy>0.01</iyy>
            <iyz>0</iyz>
            <izz>0.01</izz>
          </inertia>
        </inertial>
        <collision name='collision'>
          <pose>0.1 0 0 0 1.57079 0</pose>
          <geometry>
            <cylinder>
              <length>0.2</length>
              <radius>0.025</radius>
            </cylinder>
          </geometry>
          <surface>
            <contact>
              <ode>
                <min_depth>0.005</min_depth>
              </ode>
            </contact>
            <friction>
              <ode>
                <mu>1</mu>
                <mu2>1</mu2>
              </ode>
            </friction>
            <bounce/>
          </surface>
          <max_contacts>10</max_contacts>
        </collision>
        <visual name='visual'>
          <pose>0.1 0 0 0 1.57079 0</pose>
          <geometry>
            <cylinder>
              <length>0.2</length>
              <radius>0.025</radius>
            </cylinder>
          </geometry>
          <material>
            <script>
              <uri>model://fire_hose_long_curled/materials/scripts</uri>
              <uri>model://fire_hose_long_curled/materials/textures</uri>
              <name>fire_hose_long_curled/fire_hose_canvas</name>
            </script>
          </material>
        </visual>
        <visual name='sphere'>
          <geometry>
            <sphere>
              <radius>0.025</radius>
            </sphere>
          </geometry>
          <material>
            <script>
              <uri>model://fire_hose_long_curled/materials/scripts</uri>
              <uri>model://fire_hose_long_curled/materials/textures</uri>
              <name>fire_hose_long_curled/fire_hose_canvas</name>
            </script>
          </material>
        </visual>
        <velocity_decay>
          <linear>0</linear>
          <angular>0</angular>
        </velocity_decay>
        <self_collide>0</self_collide>
        <kinematic>0</kinematic>
      </link>
      <link name='link_04'>
        <gravity>0</gravity>
        <pose>0.7 0 0 0 -0 0</pose>
        <inertial>
          <mass>0.1</mass>
          <pose>0.1 0 0 0 -0 0</pose>
          <inertia>
            <ixx>0.01</ixx>
            <ixy>0</ixy>
            <ixz>0</ixz>
            <iyy>0.01</iyy>
            <iyz>0</iyz>
            <izz>0.01</izz>
          </inertia>
        </inertial>
        <collision name='collision'>
          <pose>0.1 0 0 0 1.57079 0</pose>
          <geometry>
            <cylinder>
              <length>0.2</length>
              <radius>0.025</radius>
            </cylinder>
          </geometry>
          <surface>
            <contact>
              <ode>
                <min_depth>0.005</min_depth>
              </ode>
            </contact>
            <friction>
              <ode>
                <mu>1</mu>
                <mu2>1</mu2>
              </ode>
            </friction>
            <bounce/>
          </surface>
          <max_contacts>10</max_contacts>
        </collision>
        <visual name='visual'>
          <pose>0.1 0 0 0 1.57079 0</pose>
          <geometry>
            <cylinder>
              <length>0.2</length>
              <radius>0.025</radius>
            </cylinder>
          </geometry>
          <material>
            <script>
              <uri>model://fire_hose_long_curled/materials/scripts</uri>
              <uri>model://fire_hose_long_curled/materials/textures</uri>
              <name>fire_hose_long_curled/fire_hose_canvas</name>
            </script>
          </material>
        </visual>
        <visual name='sphere'>
          <geometry>
            <sphere>
              <radius>0.025</radius>
            </sphere>
          </geometry>
          <material>
            <script>
              <uri>model://fire_hose_long_curled/materials/scripts</uri>
              <uri>model://fire_hose_long_curled/materials/textures</uri>
              <name>fire_hose_long_curled/fire_hose_canvas</name>
            </script>
          </material>
        </visual>
        <velocity_decay>
          <linear>0</linear>
          <angular>0</angular>
        </velocity_decay>
        <self_collide>0</self_collide>
        <kinematic>0</kinematic>
      </link>
      <link name='link_05'>
        <gravity>0</gravity>
        <pose>0.9 0 0 0 -0 0</pose>
        <inertial>
          <mass>0.1</mass>
          <pose>0.1 0 0 0 -0 0</pose>
          <inertia>
            <ixx>0.01</ixx>
            <ixy>0</ixy>
            <ixz>0</ixz>
            <iyy>0.01</iyy>
            <iyz>0</iyz>
            <izz>0.01</izz>
          </inertia>
        </inertial>
        <collision name='collision'>
          <pose>0.1 0 0 0 1.57079 0</pose>
          <geometry>
            <cylinder>
              <length>0.2</length>
              <radius>0.025</radius>
            </cylinder>
          </geometry>
          <surface>
            <contact>
              <ode>
                <min_depth>0.005</min_depth>
              </ode>
            </contact>
            <friction>
              <ode>
                <mu>1</mu>
                <mu2>1</mu2>
              </ode>
            </friction>
            <bounce/>
          </surface>
          <max_contacts>10</max_contacts>
        </collision>
        <visual name='visual'>
          <pose>0.1 0 0 0 1.57079 0</pose>
          <geometry>
            <cylinder>
              <length>0.2</length>
              <radius>0.025</radius>
            </cylinder>
          </geometry>
          <material>
            <script>
              <uri>model://fire_hose_long_curled/materials/scripts</uri>
              <uri>model://fire_hose_long_curled/materials/textures</uri>
              <name>fire_hose_long_curled/fire_hose_canvas</name>
            </script>
          </material>
        </visual>
        <visual name='sphere'>
          <geometry>
            <sphere>
              <radius>0.025</radius>
            </sphere>
          </geometry>
          <material>
            <script>
              <uri>model://fire_hose_long_curled/materials/scripts</uri>
              <uri>model://fire_hose_long_curled/materials/textures</uri>
              <name>fire_hose_long_curled/fire_hose_canvas</name>
            </script>
          </material>
        </visual>
        <velocity_decay>
          <linear>0</linear>
          <angular>0</angular>
        </velocity_decay>
        <self_collide>0</self_collide>
        <kinematic>0</kinematic>
      </link>
      <link name='link_06'>
        <gravity>0</gravity>
        <pose>1.1 0 0 0 0 -0.785</pose>
        <inertial>
          <mass>0.1</mass>
          <pose>0.0875 0 0 0 -0 0</pose>
          <inertia>
            <ixx>0.01</ixx>
            <ixy>0</ixy>
            <ixz>0</ixz>
            <iyy>0.01</iyy>
            <iyz>0</iyz>
            <izz>0.01</izz>
          </inertia>
        </inertial>
        <collision name='collision'>
          <pose>0.0875 0 0 0 1.57079 0</pose>
          <geometry>
            <cylinder>
              <length>0.175</length>
              <radius>0.025</radius>
            </cylinder>
          </geometry>
          <surface>
            <contact>
              <ode>
                <min_depth>0.005</min_depth>
              </ode>
            </contact>
            <friction>
              <ode>
                <mu>1</mu>
                <mu2>1</mu2>
              </ode>
            </friction>
            <bounce/>
          </surface>
          <max_contacts>10</max_contacts>
        </collision>
        <visual name='visual'>
          <pose>0.0875 0 0 0 1.57079 0</pose>
          <geometry>
            <cylinder>
              <length>0.175</length>
              <radius>0.025</radius>
            </cylinder>
          </geometry>
          <material>
            <script>
              <uri>model://fire_hose_long_curled/materials/scripts</uri>
              <uri>model://fire_hose_long_curled/materials/textures</uri>
              <name>fire_hose_long_curled/fire_hose_canvas</name>
            </script>
          </material>
        </visual>
        <visual name='sphere'>
          <geometry>
            <sphere>
              <radius>0.025</radius>
            </sphere>
          </geometry>
          <material>
            <script>
              <uri>model://fire_hose_long_curled/materials/scripts</uri>
              <uri>model://fire_hose_long_curled/materials/textures</uri>
              <name>fire_hose_long_curled/fire_hose_canvas</name>
            </script>
          </material>
        </visual>
        <velocity_decay>
          <linear>0</linear>
          <angular>0</angular>
        </velocity_decay>
        <self_collide>0</self_collide>
        <kinematic>0</kinematic>
      </link>
      <link name='link_07'>
        <gravity>0</gravity>
        <pose>1.227 -0.127 0 0 0 -2.3415</pose>
        <inertial>
          <mass>0.1</mass>
          <pose>0.0875 0 0 0 -0 0</pose>
          <inertia>
            <ixx>0.01</ixx>
            <ixy>0</ixy>
            <ixz>0</ixz>
            <iyy>0.01</iyy>
            <iyz>0</iyz>
            <izz>0.01</izz>
          </inertia>
        </inertial>
        <collision name='collision'>
          <pose>0.0875 0 0 0 1.57079 0</pose>
          <geometry>
            <cylinder>
              <length>0.175</length>
              <radius>0.025</radius>
            </cylinder>
          </geometry>
          <surface>
            <contact>
              <ode>
                <min_depth>0.005</min_depth>
              </ode>
            </contact>
            <friction>
              <ode>
                <mu>1</mu>
                <mu2>1</mu2>
              </ode>
            </friction>
            <bounce/>
          </surface>
          <max_contacts>10</max_contacts>
        </collision>
        <visual name='visual'>
          <pose>0.0875 0 0 0 1.57079 0</pose>
          <geometry>
            <cylinder>
              <length>0.175</length>
              <radius>0.025</radius>
            </cylinder>
          </geometry>
          <material>
            <script>
              <uri>model://fire_hose_long_curled/materials/scripts</uri>
              <uri>model://fire_hose_long_curled/materials/textures</uri>
              <name>fire_hose_long_curled/fire_hose_canvas</name>
            </script>
          </material>
        </visual>
        <visual name='sphere'>
          <geometry>
            <sphere>
              <radius>0.025</radius>
            </sphere>
          </geometry>
          <material>
            <script>
              <uri>model://fire_hose_long_curled/materials/scripts</uri>
              <uri>model://fire_hose_long_curled/materials/textures</uri>
              <name>fire_hose_long_curled/fire_hose_canvas</name>
            </script>
          </material>
        </visual>
        <velocity_decay>
          <linear>0</linear>
          <angular>0</angular>
        </velocity_decay>
        <self_collide>0</self_collide>
        <kinematic>0</kinematic>
      </link>
      <link name='link_08'>
        <gravity>0</gravity>
        <pose>1.1 -0.254 0 0 0 -3.1415</pose>
        <inertial>
          <mass>0.1</mass>
          <pose>0.1 0 0 0 -0 0</pose>
          <inertia>
            <ixx>0.01</ixx>
            <ixy>0</ixy>
            <ixz>0</ixz>
            <iyy>0.01</iyy>
            <iyz>0</iyz>
            <izz>0.01</izz>
          </inertia>
        </inertial>
        <collision name='collision'>
          <pose>0.1 0 0 0 1.57079 0</pose>
          <geometry>
            <cylinder>
              <length>0.2</length>
              <radius>0.025</radius>
            </cylinder>
          </geometry>
          <surface>
            <contact>
              <ode>
                <min_depth>0.005</min_depth>
              </ode>
            </contact>
            <friction>
              <ode>
                <mu>1</mu>
                <mu2>1</mu2>
              </ode>
            </friction>
            <bounce/>
          </surface>
          <max_contacts>10</max_contacts>
        </collision>
        <visual name='visual'>
          <pose>0.1 0 0 0 1.57079 0</pose>
          <geometry>
            <cylinder>
              <length>0.2</length>
              <radius>0.025</radius>
            </cylinder>
          </geometry>
          <material>
            <script>
              <uri>model://fire_hose_long_curled/materials/scripts</uri>
              <uri>model://fire_hose_long_curled/materials/textures</uri>
              <name>fire_hose_long_curled/fire_hose_canvas</name>
            </script>
          </material>
        </visual>
        <visual name='sphere'>
          <geometry>
            <sphere>
              <radius>0.025</radius>
            </sphere>
          </geometry>
          <material>
            <script>
              <uri>model://fire_hose_long_curled/materials/scripts</uri>
              <uri>model://fire_hose_long_curled/materials/textures</uri>
              <name>fire_hose_long_curled/fire_hose_canvas</name>
            </script>
          </material>
        </visual>
        <velocity_decay>
          <linear>0</linear>
          <angular>0</angular>
        </velocity_decay>
        <self_collide>0</self_collide>
        <kinematic>0</kinematic>
      </link>
      <link name='link_09'>
        <gravity>0</gravity>
        <pose>0.9 -0.254 0 0 0 -3.1415</pose>
        <inertial>
          <mass>0.1</mass>
          <pose>0.1 0 0 0 -0 0</pose>
          <inertia>
            <ixx>0.01</ixx>
            <ixy>0</ixy>
            <ixz>0</ixz>
            <iyy>0.01</iyy>
            <iyz>0</iyz>
            <izz>0.01</izz>
          </inertia>
        </inertial>
        <collision name='collision'>
          <pose>0.1 0 0 0 1.57079 0</pose>
          <geometry>
            <cylinder>
              <length>0.2</length>
              <radius>0.025</radius>
            </cylinder>
          </geometry>
          <surface>
            <contact>
              <ode>
                <min_depth>0.005</min_depth>
              </ode>
            </contact>
            <friction>
              <ode>
                <mu>1</mu>
                <mu2>1</mu2>
              </ode>
            </friction>
            <bounce/>
          </surface>
          <max_contacts>10</max_contacts>
        </collision>
        <visual name='visual'>
          <pose>0.1 0 0 0 1.57079 0</pose>
          <geometry>
            <cylinder>
              <length>0.2</length>
              <radius>0.025</radius>
            </cylinder>
          </geometry>
          <material>
            <script>
              <uri>model://fire_hose_long_curled/materials/scripts</uri>
              <uri>model://fire_hose_long_curled/materials/textures</uri>
              <name>fire_hose_long_curled/fire_hose_canvas</name>
            </script>
          </material>
        </visual>
        <visual name='sphere'>
          <geometry>
            <sphere>
              <radius>0.025</radius>
            </sphere>
          </geometry>
          <material>
            <script>
              <uri>model://fire_hose_long_curled/materials/scripts</uri>
              <uri>model://fire_hose_long_curled/materials/textures</uri>
              <name>fire_hose_long_curled/fire_hose_canvas</name>
            </script>
          </material>
        </visual>
        <velocity_decay>
          <linear>0</linear>
          <angular>0</angular>
        </velocity_decay>
        <self_collide>0</self_collide>
        <kinematic>0</kinematic>
      </link>
      <link name='link_10'>
        <gravity>0</gravity>
        <pose>0.7 -0.254 0 0 0 -3.1415</pose>
        <inertial>
          <mass>0.1</mass>
          <pose>0.1 0 0 0 -0 0</pose>
          <inertia>
            <ixx>0.01</ixx>
            <ixy>0</ixy>
            <ixz>0</ixz>
            <iyy>0.01</iyy>
            <iyz>0</iyz>
            <izz>0.01</izz>
          </inertia>
        </inertial>
        <collision name='collision'>
          <pose>0.1 0 0 0 1.57079 0</pose>
          <geometry>
            <cylinder>
              <length>0.2</length>
              <radius>0.025</radius>
            </cylinder>
          </geometry>
          <surface>
            <contact>
              <ode>
                <min_depth>0.005</min_depth>
              </ode>
            </contact>
            <friction>
              <ode>
                <mu>1</mu>
                <mu2>1</mu2>
              </ode>
            </friction>
            <bounce/>
          </surface>
          <max_contacts>10</max_contacts>
        </collision>
        <visual name='visual'>
          <pose>0.1 0 0 0 1.57079 0</pose>
          <geometry>
            <cylinder>
              <length>0.2</length>
              <radius>0.025</radius>
            </cylinder>
          </geometry>
          <material>
            <script>
              <uri>model://fire_hose_long_curled/materials/scripts</uri>
              <uri>model://fire_hose_long_curled/materials/textures</uri>
              <name>fire_hose_long_curled/fire_hose_canvas</name>
            </script>
          </material>
        </visual>
        <visual name='sphere'>
          <geometry>
            <sphere>
              <radius>0.025</radius>
            </sphere>
          </geometry>
          <material>
            <script>
              <uri>model://fire_hose_long_curled/materials/scripts</uri>
              <uri>model://fire_hose_long_curled/materials/textures</uri>
              <name>fire_hose_long_curled/fire_hose_canvas</name>
            </script>
          </material>
        </visual>
        <velocity_decay>
          <linear>0</linear>
          <angular>0</angular>
        </velocity_decay>
        <self_collide>0</self_collide>
        <kinematic>0</kinematic>
      </link>
      <link name='link_11'>
        <gravity>0</gravity>
        <pose>0.5 -0.254 0 0 0 -3.1415</pose>
        <inertial>
          <mass>0.1</mass>
          <pose>0.1 0 0 0 -0 0</pose>
          <inertia>
            <ixx>0.01</ixx>
            <ixy>0</ixy>
            <ixz>0</ixz>
            <iyy>0.01</iyy>
            <iyz>0</iyz>
            <izz>0.01</izz>
          </inertia>
        </inertial>
        <collision name='collision'>
          <pose>0.1 0 0 0 1.57079 0</pose>
          <geometry>
            <cylinder>
              <length>0.2</length>
              <radius>0.025</radius>
            </cylinder>
          </geometry>
          <surface>
            <contact>
              <ode>
                <min_depth>0.005</min_depth>
              </ode>
            </contact>
            <friction>
              <ode>
                <mu>1</mu>
                <mu2>1</mu2>
              </ode>
            </friction>
            <bounce/>
          </surface>
          <max_contacts>10</max_contacts>
        </collision>
        <visual name='visual'>
          <pose>0.1 0 0 0 1.57079 0</pose>
          <geometry>
            <cylinder>
              <length>0.2</length>
              <radius>0.025</radius>
            </cylinder>
          </geometry>
          <material>
            <script>
              <uri>model://fire_hose_long_curled/materials/scripts</uri>
              <uri>model://fire_hose_long_curled/materials/textures</uri>
              <name>fire_hose_long_curled/fire_hose_canvas</name>
            </script>
          </material>
        </visual>
        <visual name='sphere'>
          <geometry>
            <sphere>
              <radius>0.025</radius>
            </sphere>
          </geometry>
          <material>
            <script>
              <uri>model://fire_hose_long_curled/materials/scripts</uri>
              <uri>model://fire_hose_long_curled/materials/textures</uri>
              <name>fire_hose_long_curled/fire_hose_canvas</name>
            </script>
          </material>
        </visual>
        <velocity_decay>
          <linear>0</linear>
          <angular>0</angular>
        </velocity_decay>
        <self_collide>0</self_collide>
        <kinematic>0</kinematic>
      </link>
      <link name='link_12'>
        <gravity>0</gravity>
        <pose>0.3 -0.254 0 0 0 -3.1415</pose>
        <inertial>
          <mass>0.1</mass>
          <pose>0.1 0 0 0 -0 0</pose>
          <inertia>
            <ixx>0.01</ixx>
            <ixy>0</ixy>
            <ixz>0</ixz>
            <iyy>0.01</iyy>
            <iyz>0</iyz>
            <izz>0.01</izz>
          </inertia>
        </inertial>
        <collision name='collision'>
          <pose>0.1 0 0 0 1.57079 0</pose>
          <geometry>
            <cylinder>
              <length>0.2</length>
              <radius>0.025</radius>
            </cylinder>
          </geometry>
          <surface>
            <contact>
              <ode>
                <min_depth>0.005</min_depth>
              </ode>
            </contact>
            <friction>
              <ode>
                <mu>1</mu>
                <mu2>1</mu2>
              </ode>
            </friction>
            <bounce/>
          </surface>
          <max_contacts>10</max_contacts>
        </collision>
        <visual name='visual'>
          <pose>0.1 0 0 0 1.57079 0</pose>
          <geometry>
            <cylinder>
              <length>0.2</length>
              <radius>0.025</radius>
            </cylinder>
          </geometry>
          <material>
            <script>
              <uri>model://fire_hose_long_curled/materials/scripts</uri>
              <uri>model://fire_hose_long_curled/materials/textures</uri>
              <name>fire_hose_long_curled/fire_hose_canvas</name>
            </script>
          </material>
        </visual>
        <visual name='sphere'>
          <geometry>
            <sphere>
              <radius>0.025</radius>
            </sphere>
          </geometry>
          <material>
            <script>
              <uri>model://fire_hose_long_curled/materials/scripts</uri>
              <uri>model://fire_hose_long_curled/materials/textures</uri>
              <name>fire_hose_long_curled/fire_hose_canvas</name>
            </script>
          </material>
        </visual>
        <velocity_decay>
          <linear>0</linear>
          <angular>0</angular>
        </velocity_decay>
        <self_collide>0</self_collide>
        <kinematic>0</kinematic>
      </link>
      <link name='link_13'>
        <gravity>0</gravity>
        <pose>0.1 -0.254 0 0 0 -2.356</pose>
        <inertial>
          <mass>0.1</mass>
          <pose>0.0875 0 0 0 -0 0</pose>
          <inertia>
            <ixx>0.01</ixx>
            <ixy>0</ixy>
            <ixz>0</ixz>
            <iyy>0.01</iyy>
            <iyz>0</iyz>
            <izz>0.01</izz>
          </inertia>
        </inertial>
        <collision name='collision'>
          <pose>0.0875 0 0 0 1.57079 0</pose>
          <geometry>
            <cylinder>
              <length>0.175</length>
              <radius>0.025</radius>
            </cylinder>
          </geometry>
          <surface>
            <contact>
              <ode>
                <min_depth>0.005</min_depth>
              </ode>
            </contact>
            <friction>
              <ode>
                <mu>1</mu>
                <mu2>1</mu2>
              </ode>
            </friction>
            <bounce/>
          </surface>
          <max_contacts>10</max_contacts>
        </collision>
        <visual name='visual'>
          <pose>0.0875 0 0 0 1.57079 0</pose>
          <geometry>
            <cylinder>
              <length>0.175</length>
              <radius>0.025</radius>
            </cylinder>
          </geometry>
          <material>
            <script>
              <uri>model://fire_hose_long_curled/materials/scripts</uri>
              <uri>model://fire_hose_long_curled/materials/textures</uri>
              <name>fire_hose_long_curled/fire_hose_canvas</name>
            </script>
          </material>
        </visual>
        <visual name='sphere'>
          <geometry>
            <sphere>
              <radius>0.025</radius>
            </sphere>
          </geometry>
          <material>
            <script>
              <uri>model://fire_hose_long_curled/materials/scripts</uri>
              <uri>model://fire_hose_long_curled/materials/textures</uri>
              <name>fire_hose_long_curled/fire_hose_canvas</name>
            </script>
          </material>
        </visual>
        <velocity_decay>
          <linear>0</linear>
          <angular>0</angular>
        </velocity_decay>
        <self_collide>0</self_collide>
        <kinematic>0</kinematic>
      </link>
      <link name='link_14'>
        <gravity>0</gravity>
        <pose>-0.027 -0.381 0 0 0 -0.785</pose>
        <inertial>
          <mass>0.1</mass>
          <pose>0.0875 0 0 0 -0 0</pose>
          <inertia>
            <ixx>0.01</ixx>
            <ixy>0</ixy>
            <ixz>0</ixz>
            <iyy>0.01</iyy>
            <iyz>0</iyz>
            <izz>0.01</izz>
          </inertia>
        </inertial>
        <collision name='collision'>
          <pose>0.0875 0 0 0 1.57079 0</pose>
          <geometry>
            <cylinder>
              <length>0.175</length>
              <radius>0.025</radius>
            </cylinder>
          </geometry>
          <surface>
            <contact>
              <ode>
                <min_depth>0.005</min_depth>
              </ode>
            </contact>
            <friction>
              <ode>
                <mu>1</mu>
                <mu2>1</mu2>
              </ode>
            </friction>
            <bounce/>
          </surface>
          <max_contacts>10</max_contacts>
        </collision>
        <visual name='visual'>
          <pose>0.0875 0 0 0 1.57079 0</pose>
          <geometry>
            <cylinder>
              <length>0.175</length>
              <radius>0.025</radius>
            </cylinder>
          </geometry>
          <material>
            <script>
              <uri>model://fire_hose_long_curled/materials/scripts</uri>
              <uri>model://fire_hose_long_curled/materials/textures</uri>
              <name>fire_hose_long_curled/fire_hose_canvas</name>
            </script>
          </material>
        </visual>
        <visual name='sphere'>
          <geometry>
            <sphere>
              <radius>0.025</radius>
            </sphere>
          </geometry>
          <material>
            <script>
              <uri>model://fire_hose_long_curled/materials/scripts</uri>
              <uri>model://fire_hose_long_curled/materials/textures</uri>
              <name>fire_hose_long_curled/fire_hose_canvas</name>
            </script>
          </material>
        </visual>
        <velocity_decay>
          <linear>0</linear>
          <angular>0</angular>
        </velocity_decay>
        <self_collide>0</self_collide>
        <kinematic>0</kinematic>
      </link>
      <link name='link_15'>
        <gravity>0</gravity>
        <pose>0.1 -0.508 0 0 -0 0</pose>
        <inertial>
          <mass>0.1</mass>
          <pose>0.1 0 0 0 -0 0</pose>
          <inertia>
            <ixx>0.01</ixx>
            <ixy>0</ixy>
            <ixz>0</ixz>
            <iyy>0.01</iyy>
            <iyz>0</iyz>
            <izz>0.01</izz>
          </inertia>
        </inertial>
        <collision name='collision'>
          <pose>0.1 0 0 0 1.57079 0</pose>
          <geometry>
            <cylinder>
              <length>0.2</length>
              <radius>0.025</radius>
            </cylinder>
          </geometry>
          <surface>
            <contact>
              <ode>
                <min_depth>0.005</min_depth>
              </ode>
            </contact>
            <friction>
              <ode>
                <mu>1</mu>
                <mu2>1</mu2>
              </ode>
            </friction>
            <bounce/>
          </surface>
          <max_contacts>10</max_contacts>
        </collision>
        <visual name='visual'>
          <pose>0.1 0 0 0 1.57079 0</pose>
          <geometry>
            <cylinder>
              <length>0.2</length>
              <radius>0.025</radius>
            </cylinder>
          </geometry>
          <material>
            <script>
              <uri>model://fire_hose_long_curled/materials/scripts</uri>
              <uri>model://fire_hose_long_curled/materials/textures</uri>
              <name>fire_hose_long_curled/fire_hose_canvas</name>
            </script>
          </material>
        </visual>
        <visual name='sphere'>
          <geometry>
            <sphere>
              <radius>0.025</radius>
            </sphere>
          </geometry>
          <material>
            <script>
              <uri>model://fire_hose_long_curled/materials/scripts</uri>
              <uri>model://fire_hose_long_curled/materials/textures</uri>
              <name>fire_hose_long_curled/fire_hose_canvas</name>
            </script>
          </material>
        </visual>
        <velocity_decay>
          <linear>0</linear>
          <angular>0</angular>
        </velocity_decay>
        <self_collide>0</self_collide>
        <kinematic>0</kinematic>
      </link>
      <link name='link_16'>
        <gravity>0</gravity>
        <pose>0.3 -0.508 0 0 -0 0</pose>
        <inertial>
          <mass>0.1</mass>
          <pose>0.1 0 0 0 -0 0</pose>
          <inertia>
            <ixx>0.01</ixx>
            <ixy>0</ixy>
            <ixz>0</ixz>
            <iyy>0.01</iyy>
            <iyz>0</iyz>
            <izz>0.01</izz>
          </inertia>
        </inertial>
        <collision name='collision'>
          <pose>0.1 0 0 0 1.57079 0</pose>
          <geometry>
            <cylinder>
              <length>0.2</length>
              <radius>0.025</radius>
            </cylinder>
          </geometry>
          <surface>
            <contact>
              <ode>
                <min_depth>0.005</min_depth>
              </ode>
            </contact>
            <friction>
              <ode>
                <mu>1</mu>
                <mu2>1</mu2>
              </ode>
            </friction>
            <bounce/>
          </surface>
          <max_contacts>10</max_contacts>
        </collision>
        <visual name='visual'>
          <pose>0.1 0 0 0 1.57079 0</pose>
          <geometry>
            <cylinder>
              <length>0.2</length>
              <radius>0.025</radius>
            </cylinder>
          </geometry>
          <material>
            <script>
              <uri>model://fire_hose_long_curled/materials/scripts</uri>
              <uri>model://fire_hose_long_curled/materials/textures</uri>
              <name>fire_hose_long_curled/fire_hose_canvas</name>
            </script>
          </material>
        </visual>
        <visual name='sphere'>
          <geometry>
            <sphere>
              <radius>0.025</radius>
            </sphere>
          </geometry>
          <material>
            <script>
              <uri>model://fire_hose_long_curled/materials/scripts</uri>
              <uri>model://fire_hose_long_curled/materials/textures</uri>
              <name>fire_hose_long_curled/fire_hose_canvas</name>
            </script>
          </material>
        </visual>
        <velocity_decay>
          <linear>0</linear>
          <angular>0</angular>
        </velocity_decay>
        <self_collide>0</self_collide>
        <kinematic>0</kinematic>
      </link>
      <link name='link_17'>
        <gravity>0</gravity>
        <pose>0.5 -0.508 0 0 -0 0</pose>
        <inertial>
          <mass>0.1</mass>
          <pose>0.1 0 0 0 -0 0</pose>
          <inertia>
            <ixx>0.01</ixx>
            <ixy>0</ixy>
            <ixz>0</ixz>
            <iyy>0.01</iyy>
            <iyz>0</iyz>
            <izz>0.01</izz>
          </inertia>
        </inertial>
        <collision name='collision'>
          <pose>0.1 0 0 0 1.57079 0</pose>
          <geometry>
            <cylinder>
              <length>0.2</length>
              <radius>0.025</radius>
            </cylinder>
          </geometry>
          <surface>
            <contact>
              <ode>
                <min_depth>0.005</min_depth>
              </ode>
            </contact>
            <friction>
              <ode>
                <mu>1</mu>
                <mu2>1</mu2>
              </ode>
            </friction>
            <bounce/>
          </surface>
          <max_contacts>10</max_contacts>
        </collision>
        <visual name='visual'>
          <pose>0.1 0 0 0 1.57079 0</pose>
          <geometry>
            <cylinder>
              <length>0.2</length>
              <radius>0.025</radius>
            </cylinder>
          </geometry>
          <material>
            <script>
              <uri>model://fire_hose_long_curled/materials/scripts</uri>
              <uri>model://fire_hose_long_curled/materials/textures</uri>
              <name>fire_hose_long_curled/fire_hose_canvas</name>
            </script>
          </material>
        </visual>
        <visual name='sphere'>
          <geometry>
            <sphere>
              <radius>0.025</radius>
            </sphere>
          </geometry>
          <material>
            <script>
              <uri>model://fire_hose_long_curled/materials/scripts</uri>
              <uri>model://fire_hose_long_curled/materials/textures</uri>
              <name>fire_hose_long_curled/fire_hose_canvas</name>
            </script>
          </material>
        </visual>
        <velocity_decay>
          <linear>0</linear>
          <angular>0</angular>
        </velocity_decay>
        <self_collide>0</self_collide>
        <kinematic>0</kinematic>
      </link>
      <link name='link_18'>
        <gravity>0</gravity>
        <pose>0.7 -0.508 0 0 -0 0</pose>
        <inertial>
          <mass>0.1</mass>
          <pose>0.1 0 0 0 -0 0</pose>
          <inertia>
            <ixx>0.01</ixx>
            <ixy>0</ixy>
            <ixz>0</ixz>
            <iyy>0.01</iyy>
            <iyz>0</iyz>
            <izz>0.01</izz>
          </inertia>
        </inertial>
        <collision name='collision'>
          <pose>0.1 0 0 0 1.57079 0</pose>
          <geometry>
            <cylinder>
              <length>0.2</length>
              <radius>0.025</radius>
            </cylinder>
          </geometry>
          <surface>
            <contact>
              <ode>
                <min_depth>0.005</min_depth>
              </ode>
            </contact>
            <friction>
              <ode>
                <mu>1</mu>
                <mu2>1</mu2>
              </ode>
            </friction>
            <bounce/>
          </surface>
          <max_contacts>10</max_contacts>
        </collision>
        <visual name='visual'>
          <pose>0.1 0 0 0 1.57079 0</pose>
          <geometry>
            <cylinder>
              <length>0.2</length>
              <radius>0.025</radius>
            </cylinder>
          </geometry>
          <material>
            <script>
              <uri>model://fire_hose_long_curled/materials/scripts</uri>
              <uri>model://fire_hose_long_curled/materials/textures</uri>
              <name>fire_hose_long_curled/fire_hose_canvas</name>
            </script>
          </material>
        </visual>
        <visual name='sphere'>
          <geometry>
            <sphere>
              <radius>0.025</radius>
            </sphere>
          </geometry>
          <material>
            <script>
              <uri>model://fire_hose_long_curled/materials/scripts</uri>
              <uri>model://fire_hose_long_curled/materials/textures</uri>
              <name>fire_hose_long_curled/fire_hose_canvas</name>
            </script>
          </material>
        </visual>
        <velocity_decay>
          <linear>0</linear>
          <angular>0</angular>
        </velocity_decay>
        <self_collide>0</self_collide>
        <kinematic>0</kinematic>
      </link>
      <link name='link_19'>
        <gravity>0</gravity>
        <pose>0.9 -0.508 0 0 -0 0</pose>
        <inertial>
          <mass>0.1</mass>
          <pose>0.1 0 0 0 -0 0</pose>
          <inertia>
            <ixx>0.01</ixx>
            <ixy>0</ixy>
            <ixz>0</ixz>
            <iyy>0.01</iyy>
            <iyz>0</iyz>
            <izz>0.01</izz>
          </inertia>
        </inertial>
        <collision name='collision'>
          <pose>0.1 0 0 0 1.57079 0</pose>
          <geometry>
            <cylinder>
              <length>0.2</length>
              <radius>0.025</radius>
            </cylinder>
          </geometry>
          <surface>
            <contact>
              <ode>
                <min_depth>0.005</min_depth>
              </ode>
            </contact>
            <friction>
              <ode>
                <mu>1</mu>
                <mu2>1</mu2>
              </ode>
            </friction>
            <bounce/>
          </surface>
          <max_contacts>10</max_contacts>
        </collision>
        <visual name='visual'>
          <pose>0.1 0 0 0 1.57079 0</pose>
          <geometry>
            <cylinder>
              <length>0.2</length>
              <radius>0.025</radius>
            </cylinder>
          </geometry>
          <material>
            <script>
              <uri>model://fire_hose_long_curled/materials/scripts</uri>
              <uri>model://fire_hose_long_curled/materials/textures</uri>
              <name>fire_hose_long_curled/fire_hose_canvas</name>
            </script>
          </material>
        </visual>
        <visual name='sphere'>
          <geometry>
            <sphere>
              <radius>0.025</radius>
            </sphere>
          </geometry>
          <material>
            <script>
              <uri>model://fire_hose_long_curled/materials/scripts</uri>
              <uri>model://fire_hose_long_curled/materials/textures</uri>
              <name>fire_hose_long_curled/fire_hose_canvas</name>
            </script>
          </material>
        </visual>
        <velocity_decay>
          <linear>0</linear>
          <angular>0</angular>
        </velocity_decay>
        <self_collide>0</self_collide>
        <kinematic>0</kinematic>
      </link>
      <link name='nozzle'>
        <pose>1.1 -0.508 0 0 -0 3.1415</pose>
        <inertial>
          <mass>0.1</mass>
          <inertia>
            <ixx>0.01</ixx>
            <ixy>0</ixy>
            <ixz>0</ixz>
            <iyy>0.01</iyy>
            <iyz>0</iyz>
            <izz>0.01</izz>
          </inertia>
        </inertial>
        <collision name='nozzle_collision'>
          <geometry>
            <mesh>
              <scale>1 0.5 0.5</scale>
              <uri>model://fire_hose_long_curled/meshes/nozzle.stl</uri>
            </mesh>
          </geometry>
          <surface>
            <contact>
              <ode>
                <min_depth>0.005</min_depth>
              </ode>
            </contact>
            <friction>
              <ode>
                <mu>1</mu>
                <mu2>1</mu2>
              </ode>
            </friction>
            <bounce/>
          </surface>
          <max_contacts>10</max_contacts>
        </collision>
        <visual name='nozzle_vis'>
          <geometry>
            <mesh>
              <scale>1 0.5 0.5</scale>
              <uri>model://fire_hose_long_curled/meshes/nozzle.stl</uri>
            </mesh>
          </geometry>
        </visual>
        <velocity_decay>
          <linear>0</linear>
          <angular>0</angular>
        </velocity_decay>
        <self_collide>0</self_collide>
        <kinematic>0</kinematic>
        <gravity>0</gravity>
      </link>
      <joint name='joint_00' type='revolute'>
        <parent>coupling</parent>
        <child>link_00</child>
        <axis>
          <xyz>1 0 0</xyz>
          <dynamics>
            <damping>1</damping>
          </dynamics>
          <limit>
            <lower>-1e+16</lower>
            <upper>1e+16</upper>
          </limit>
        </axis>
        <physics>
          <ode>
            <cfm_damping>1</cfm_damping>
            <limit>
              <cfm>0</cfm>
              <erp>0.2</erp>
            </limit>
          </ode>
        </physics>
      </joint>
      <joint name='joint_01' type='universal'>
        <child>link_01</child>
        <parent>link_00</parent>
        <axis>
          <xyz>0 1 0</xyz>
          <limit>
            <lower>-1.57</lower>
            <upper>1.57</upper>
          </limit>
          <dynamics>
            <damping>1</damping>
          </dynamics>
        </axis>
        <axis2>
          <xyz>0 0 1</xyz>
          <limit>
            <lower>-1.57</lower>
            <upper>1.57</upper>
          </limit>
          <dynamics>
            <damping>1</damping>
          </dynamics>
        </axis2>
        <physics>
          <ode>
            <cfm_damping>1</cfm_damping>
            <limit>
              <cfm>0</cfm>
              <erp>0.2</erp>
            </limit>
          </ode>
        </physics>
      </joint>
      <joint name='joint_02' type='universal'>
        <child>link_02</child>
        <parent>link_01</parent>
        <axis>
          <xyz>0 1 0</xyz>
          <limit>
            <lower>-1.57</lower>
            <upper>1.57</upper>
          </limit>
          <dynamics>
            <damping>1</damping>
          </dynamics>
        </axis>
        <axis2>
          <xyz>0 0 1</xyz>
          <limit>
            <lower>-1.57</lower>
            <upper>1.57</upper>
          </limit>
          <dynamics>
            <damping>1</damping>
          </dynamics>
        </axis2>
        <physics>
          <ode>
            <cfm_damping>1</cfm_damping>
            <limit>
              <cfm>0</cfm>
              <erp>0.2</erp>
            </limit>
          </ode>
        </physics>
      </joint>
      <joint name='joint_03' type='universal'>
        <child>link_03</child>
        <parent>link_02</parent>
        <axis>
          <xyz>0 1 0</xyz>
          <limit>
            <lower>-1.57</lower>
            <upper>1.57</upper>
          </limit>
          <dynamics>
            <damping>1</damping>
          </dynamics>
        </axis>
        <axis2>
          <xyz>0 0 1</xyz>
          <limit>
            <lower>-1.57</lower>
            <upper>1.57</upper>
          </limit>
          <dynamics>
            <damping>1</damping>
          </dynamics>
        </axis2>
        <physics>
          <ode>
            <cfm_damping>1</cfm_damping>
            <limit>
              <cfm>0</cfm>
              <erp>0.2</erp>
            </limit>
          </ode>
        </physics>
      </joint>
      <joint name='joint_04' type='universal'>
        <child>link_04</child>
        <parent>link_03</parent>
        <axis>
          <xyz>0 1 0</xyz>
          <limit>
            <lower>-1.57</lower>
            <upper>1.57</upper>
          </limit>
          <dynamics>
            <damping>1</damping>
          </dynamics>
        </axis>
        <axis2>
          <xyz>0 0 1</xyz>
          <limit>
            <lower>-1.57</lower>
            <upper>1.57</upper>
          </limit>
          <dynamics>
            <damping>1</damping>
          </dynamics>
        </axis2>
        <physics>
          <ode>
            <cfm_damping>1</cfm_damping>
            <limit>
              <cfm>0</cfm>
              <erp>0.2</erp>
            </limit>
          </ode>
        </physics>
      </joint>
      <joint name='joint_05' type='universal'>
        <child>link_05</child>
        <parent>link_04</parent>
        <axis>
          <xyz>0 1 0</xyz>
          <limit>
            <lower>-1.57</lower>
            <upper>1.57</upper>
          </limit>
          <dynamics>
            <damping>1</damping>
          </dynamics>
        </axis>
        <axis2>
          <xyz>0 0 1</xyz>
          <limit>
            <lower>-1.57</lower>
            <upper>1.57</upper>
          </limit>
          <dynamics>
            <damping>1</damping>
          </dynamics>
        </axis2>
        <physics>
          <ode>
            <cfm_damping>1</cfm_damping>
            <limit>
              <cfm>0</cfm>
              <erp>0.2</erp>
            </limit>
          </ode>
        </physics>
      </joint>
      <joint name='joint_06' type='universal'>
        <child>link_06</child>
        <parent>link_05</parent>
        <axis>
          <xyz>0 0 1</xyz>
          <limit>
            <lower>-0.72</lower>
            <upper>2.35</upper>
          </limit>
          <dynamics>
            <damping>1</damping>
          </dynamics>
        </axis>
        <axis2>
          <xyz>1 1 0</xyz>
          <limit>
            <lower>-1.57</lower>
            <upper>1.57</upper>
          </limit>
          <dynamics>
            <damping>1</damping>
          </dynamics>
        </axis2>
        <physics>
          <ode>
            <cfm_damping>1</cfm_damping>
            <limit>
              <cfm>0</cfm>
              <erp>0.2</erp>
            </limit>
          </ode>
        </physics>
      </joint>
      <joint name='joint_07' type='universal'>
        <child>link_07</child>
        <parent>link_06</parent>
        <axis>
          <xyz>0 0 1</xyz>
          <limit>
            <lower>-0</lower>
            <upper>3</upper>
          </limit>
          <dynamics>
            <damping>1</damping>
          </dynamics>
        </axis>
        <axis2>
          <xyz>-1 1 0</xyz>
          <limit>
            <lower>-1.57</lower>
            <upper>1.57</upper>
          </limit>
          <dynamics>
            <damping>1</damping>
          </dynamics>
        </axis2>
        <physics>
          <ode>
            <cfm_damping>1</cfm_damping>
            <limit>
              <cfm>0</cfm>
              <erp>0.2</erp>
            </limit>
          </ode>
        </physics>
      </joint>
      <joint name='joint_08' type='universal'>
        <child>link_08</child>
        <parent>link_07</parent>
        <axis>
          <xyz>0 1 0</xyz>
          <limit>
            <lower>-1.57</lower>
            <upper>1.57</upper>
          </limit>
          <dynamics>
            <damping>1</damping>
          </dynamics>
        </axis>
        <axis2>
          <xyz>0 0 1</xyz>
          <limit>
            <lower>-0.72</lower>
            <upper>2.35</upper>
          </limit>
          <dynamics>
            <damping>1</damping>
          </dynamics>
        </axis2>
        <physics>
          <ode>
            <cfm_damping>1</cfm_damping>
            <limit>
              <cfm>0</cfm>
              <erp>0.2</erp>
            </limit>
          </ode>
        </physics>
      </joint>
      <joint name='joint_09' type='universal'>
        <child>link_09</child>
        <parent>link_08</parent>
        <axis>
          <xyz>0 1 0</xyz>
          <limit>
            <lower>-1.57</lower>
            <upper>1.57</upper>
          </limit>
          <dynamics>
            <damping>1</damping>
          </dynamics>
        </axis>
        <axis2>
          <xyz>0 0 1</xyz>
          <limit>
            <lower>-1.57</lower>
            <upper>1.57</upper>
          </limit>
          <dynamics>
            <damping>1</damping>
          </dynamics>
        </axis2>
        <physics>
          <ode>
            <cfm_damping>1</cfm_damping>
            <limit>
              <cfm>0</cfm>
              <erp>0.2</erp>
            </limit>
          </ode>
        </physics>
      </joint>
      <joint name='joint_10' type='universal'>
        <child>link_10</child>
        <parent>link_09</parent>
        <axis>
          <xyz>0 1 0</xyz>
          <limit>
            <lower>-1.57</lower>
            <upper>1.57</upper>
          </limit>
          <dynamics>
            <damping>1</damping>
          </dynamics>
        </axis>
        <axis2>
          <xyz>0 0 1</xyz>
          <limit>
            <lower>-1.57</lower>
            <upper>1.57</upper>
          </limit>
          <dynamics>
            <damping>1</damping>
          </dynamics>
        </axis2>
        <physics>
          <ode>
            <cfm_damping>1</cfm_damping>
            <limit>
              <cfm>0</cfm>
              <erp>0.2</erp>
            </limit>
          </ode>
        </physics>
      </joint>
      <joint name='joint_11' type='universal'>
        <child>link_11</child>
        <parent>link_10</parent>
        <axis>
          <xyz>0 1 0</xyz>
          <limit>
            <lower>-1.57</lower>
            <upper>1.57</upper>
          </limit>
          <dynamics>
            <damping>1</damping>
          </dynamics>
        </axis>
        <axis2>
          <xyz>0 0 1</xyz>
          <limit>
            <lower>-1.57</lower>
            <upper>1.57</upper>
          </limit>
          <dynamics>
            <damping>1</damping>
          </dynamics>
        </axis2>
        <physics>
          <ode>
            <cfm_damping>1</cfm_damping>
            <limit>
              <cfm>0</cfm>
              <erp>0.2</erp>
            </limit>
          </ode>
        </physics>
      </joint>
      <joint name='joint_12' type='universal'>
        <child>link_12</child>
        <parent>link_11</parent>
        <axis>
          <xyz>0 1 0</xyz>
          <limit>
            <lower>-1.57</lower>
            <upper>1.57</upper>
          </limit>
          <dynamics>
            <damping>1</damping>
          </dynamics>
        </axis>
        <axis2>
          <xyz>0 0 1</xyz>
          <limit>
            <lower>-1.57</lower>
            <upper>1.57</upper>
          </limit>
          <dynamics>
            <damping>1</damping>
          </dynamics>
        </axis2>
        <physics>
          <ode>
            <cfm_damping>1</cfm_damping>
            <limit>
              <cfm>0</cfm>
              <erp>0.2</erp>
            </limit>
          </ode>
        </physics>
      </joint>
      <joint name='joint_13' type='universal'>
        <child>link_13</child>
        <parent>link_12</parent>
        <axis>
          <xyz>0 0 1</xyz>
          <limit>
            <lower>-2.35</lower>
            <upper>0.72</upper>
          </limit>
          <dynamics>
            <damping>1</damping>
          </dynamics>
        </axis>
        <axis2>
          <xyz>-1 1 0</xyz>
          <limit>
            <lower>-1.57</lower>
            <upper>1.57</upper>
          </limit>
          <dynamics>
            <damping>1</damping>
          </dynamics>
        </axis2>
        <physics>
          <ode>
            <cfm_damping>1</cfm_damping>
            <limit>
              <cfm>0</cfm>
              <erp>0.2</erp>
            </limit>
          </ode>
        </physics>
      </joint>
      <joint name='joint_14' type='universal'>
        <child>link_14</child>
        <parent>link_13</parent>
        <axis>
          <xyz>0 0 1</xyz>
          <limit>
            <lower>-3</lower>
            <upper>0</upper>
          </limit>
          <dynamics>
            <damping>1</damping>
          </dynamics>
        </axis>
        <axis2>
          <xyz>1 1 0</xyz>
          <limit>
            <lower>-1.57</lower>
            <upper>1.57</upper>
          </limit>
          <dynamics>
            <damping>1</damping>
          </dynamics>
        </axis2>
        <physics>
          <ode>
            <cfm_damping>1</cfm_damping>
            <limit>
              <cfm>0</cfm>
              <erp>0.2</erp>
            </limit>
          </ode>
        </physics>
      </joint>
      <joint name='joint_15' type='universal'>
        <child>link_15</child>
        <parent>link_14</parent>
        <axis>
          <xyz>0 0 1</xyz>
          <limit>
            <lower>-2.35</lower>
            <upper>0.72</upper>
          </limit>
          <dynamics>
            <damping>1</damping>
          </dynamics>
        </axis>
        <axis2>
          <xyz>0 1 0</xyz>
          <limit>
            <lower>-1.57</lower>
            <upper>1.57</upper>
          </limit>
          <dynamics>
            <damping>1</damping>
          </dynamics>
        </axis2>
        <physics>
          <ode>
            <cfm_damping>1</cfm_damping>
            <limit>
              <cfm>0</cfm>
              <erp>0.2</erp>
            </limit>
          </ode>
        </physics>
      </joint>
      <joint name='joint_16' type='universal'>
        <child>link_16</child>
        <parent>link_15</parent>
        <axis>
          <xyz>0 1 0</xyz>
          <limit>
            <lower>-1.57</lower>
            <upper>1.57</upper>
          </limit>
          <dynamics>
            <damping>1</damping>
          </dynamics>
        </axis>
        <axis2>
          <xyz>0 0 1</xyz>
          <limit>
            <lower>-1.57</lower>
            <upper>1.57</upper>
          </limit>
          <dynamics>
            <damping>1</damping>
          </dynamics>
        </axis2>
        <physics>
          <ode>
            <cfm_damping>1</cfm_damping>
            <limit>
              <cfm>0</cfm>
              <erp>0.2</erp>
            </limit>
          </ode>
        </physics>
      </joint>
      <joint name='joint_17' type='universal'>
        <child>link_17</child>
        <parent>link_16</parent>
        <axis>
          <xyz>0 1 0</xyz>
          <limit>
            <lower>-1.57</lower>
            <upper>1.57</upper>
          </limit>
          <dynamics>
            <damping>1</damping>
          </dynamics>
        </axis>
        <axis2>
          <xyz>0 0 1</xyz>
          <limit>
            <lower>-1.57</lower>
            <upper>1.57</upper>
          </limit>
          <dynamics>
            <damping>1</damping>
          </dynamics>
        </axis2>
        <physics>
          <ode>
            <cfm_damping>1</cfm_damping>
            <limit>
              <cfm>0</cfm>
              <erp>0.2</erp>
            </limit>
          </ode>
        </physics>
      </joint>
      <joint name='joint_18' type='universal'>
        <child>link_18</child>
        <parent>link_17</parent>
        <axis>
          <xyz>0 1 0</xyz>
          <limit>
            <lower>-1.57</lower>
            <upper>1.57</upper>
          </limit>
          <dynamics>
            <damping>1</damping>
          </dynamics>
        </axis>
        <axis2>
          <xyz>0 0 1</xyz>
          <limit>
            <lower>-1.57</lower>
            <upper>1.57</upper>
          </limit>
          <dynamics>
            <damping>1</damping>
          </dynamics>
        </axis2>
        <physics>
          <ode>
            <cfm_damping>1</cfm_damping>
            <limit>
              <cfm>0</cfm>
              <erp>0.2</erp>
            </limit>
          </ode>
        </physics>
      </joint>
      <joint name='joint_19' type='universal'>
        <child>link_19</child>
        <parent>link_18</parent>
        <axis>
          <xyz>0 1 0</xyz>
          <limit>
            <lower>-1.57</lower>
            <upper>1.57</upper>
          </limit>
          <dynamics>
            <damping>1</damping>
          </dynamics>
        </axis>
        <axis2>
          <xyz>0 0 1</xyz>
          <limit>
            <lower>-1.57</lower>
            <upper>1.57</upper>
          </limit>
          <dynamics>
            <damping>1</damping>
          </dynamics>
        </axis2>
        <physics>
          <ode>
            <cfm_damping>1</cfm_damping>
            <limit>
              <cfm>0</cfm>
              <erp>0.2</erp>
            </limit>
          </ode>
        </physics>
      </joint>
      <joint name='joint_20' type='universal'>
        <child>nozzle</child>
        <parent>link_19</parent>
        <axis>
          <xyz>0 1 0</xyz>
          <limit>
            <lower>-1.57</lower>
            <upper>1.57</upper>
          </limit>
          <dynamics>
            <damping>1</damping>
          </dynamics>
        </axis>
        <axis2>
          <xyz>0 0 1</xyz>
          <limit>
            <lower>-1.57</lower>
            <upper>1.57</upper>
          </limit>
          <dynamics>
            <damping>1</damping>
          </dynamics>
        </axis2>
        <physics>
          <ode>
            <cfm_damping>1</cfm_damping>
            <limit>
              <cfm>0</cfm>
              <erp>0.2</erp>
            </limit>
          </ode>
        </physics>
      </joint>
      <joint name='world' type='universal'>
        <child>nozzle</child>
        <parent>world</parent>
        <axis>
          <xyz>0 1 0</xyz>
          <limit>
            <lower>-1.57</lower>
            <upper>1.57</upper>
          </limit>
          <dynamics>
            <damping>1</damping>
          </dynamics>
        </axis>
        <axis2>
          <xyz>0 0 1</xyz>
          <limit>
            <lower>-1.57</lower>
            <upper>1.57</upper>
          </limit>
          <dynamics>
            <damping>1</damping>
          </dynamics>
        </axis2>
        <physics>
          <ode>
            <cfm_damping>1</cfm_damping>
            <limit>
              <cfm>0</cfm>
              <erp>0.2</erp>
            </limit>
          </ode>
        </physics>
      </joint>
      <static>1</static>
    </model>
    <state world_name='default'>
      <sim_time>6605 44000000</sim_time>
      <real_time>38 715716634</real_time>
      <wall_time>1417134442 470572207</wall_time>
      <model name='Speed limit'>
        <pose>-4.73663 -1.00485 -1.58 0 -0 0</pose>
        <link name='link'>
          <pose>-4.73663 -1.00485 -1.58 0 -0 0</pose>
          <velocity>0 0 0 0 -0 0</velocity>
          <acceleration>0 0 0 0 -0 0</acceleration>
          <wrench>0 0 0 0 -0 0</wrench>
        </link>
      </model>
      <model name='Stop Sign'>
        <pose>-4.35633 -1.33211 -1.22995 -0.00054 0.001725 1.58156</pose>
        <link name='link'>
          <pose>-4.35633 -1.33211 -1.22995 -0.00054 0.001725 1.58156</pose>
          <velocity>0 0 0 0 -0 0</velocity>
          <acceleration>0 0 0 0 -0 0</acceleration>
          <wrench>0 0 0 0 -0 0</wrench>
        </link>
      </model>
      <model name='eur_pallet'>
        <pose>-4.54988 0.116743 0.59 1.5707 -0 0</pose>
        <link name='link'>
          <pose>-4.54988 0.116743 0.59 1.5707 -0 0</pose>
          <velocity>0 0 0 0 -0 0</velocity>
          <acceleration>0 0 0 0 -0 0</acceleration>
          <wrench>0 0 0 0 -0 0</wrench>
        </link>
      </model>
      <model name='eur_pallet_0'>
        <pose>-4.26447 0.407308 0.59 1.5707 5.55112e-17 1.5707</pose>
        <link name='link'>
          <pose>-4.26447 0.407308 0.59 1.5707 5.55112e-17 1.5707</pose>
          <velocity>0 0 0 0 -0 0</velocity>
          <acceleration>0 0 0 0 -0 0</acceleration>
          <wrench>0 0 0 0 -0 0</wrench>
        </link>
      </model>
      <model name='eur_pallet_1'>
        <pose>-4.46802 -1.63273 0.98 3.14159 1.5707 3.14159</pose>
        <link name='link'>
          <pose>-4.46802 -1.63273 0.98 3.14159 1.5707 3.14159</pose>
          <velocity>0 0 0 0 -0 0</velocity>
          <acceleration>0 0 0 0 -0 0</acceleration>
          <wrench>0 0 0 0 -0 0</wrench>
        </link>
      </model>
      <model name='eur_pallet_2'>
        <pose>-4.94952 -1.15358 0.98 4.8e-05 1.5707 1.57075</pose>
        <link name='link'>
          <pose>-4.94952 -1.15358 0.98 4.8e-05 1.5707 1.57075</pose>
          <velocity>0 0 0 0 -0 0</velocity>
          <acceleration>0 0 0 0 -0 0</acceleration>
          <wrench>0 0 0 0 -0 0</wrench>
        </link>
      </model>
      <model name='fire_hose_long_curled_1'>
        <pose>-2.64385 0.004293 1.25339 -1.56319 1.53985 -0.001538</pose>
        <link name='coupling'>
          <pose>-2.64385 0.004293 1.25339 -1.56319 1.53985 -0.001538</pose>
          <velocity>0 0 0 0 -0 0</velocity>
          <acceleration>0 0 0 0 -0 0</acceleration>
          <wrench>0 0 0 0 -0 0</wrench>
        </link>
        <link name='link_00'>
          <pose>-2.64076 0.004288 1.15344 -1.56319 1.53985 -0.001538</pose>
          <velocity>0 0 0 0 -0 0</velocity>
          <acceleration>0 0 0 0 -0 0</acceleration>
          <wrench>0 0 0 0 -0 0</wrench>
        </link>
        <link name='link_01'>
          <pose>-2.64076 0.004288 1.15344 -1.56319 1.53985 -0.001538</pose>
          <velocity>0 0 0 0 -0 0</velocity>
          <acceleration>0 0 0 0 -0 0</acceleration>
          <wrench>0 0 0 0 -0 0</wrench>
        </link>
        <link name='link_02'>
          <pose>-2.63457 0.004279 0.953534 -1.56319 1.53985 -0.001538</pose>
          <velocity>0 0 0 0 -0 0</velocity>
          <acceleration>0 0 0 0 -0 0</acceleration>
          <wrench>0 0 0 0 -0 0</wrench>
        </link>
        <link name='link_03'>
          <pose>-2.62838 0.004269 0.753629 -1.56319 1.53985 -0.001538</pose>
          <velocity>0 0 0 0 -0 0</velocity>
          <acceleration>0 0 0 0 -0 0</acceleration>
          <wrench>0 0 0 0 -0 0</wrench>
        </link>
        <link name='link_04'>
          <pose>-2.62219 0.00426 0.553725 -1.56319 1.53985 -0.001538</pose>
          <velocity>0 0 0 0 -0 0</velocity>
          <acceleration>0 0 0 0 -0 0</acceleration>
          <wrench>0 0 0 0 -0 0</wrench>
        </link>
        <link name='link_05'>
          <pose>-2.616 0.00425 0.353821 -1.56319 1.53985 -0.001538</pose>
          <velocity>0 0 0 0 -0 0</velocity>
          <acceleration>0 0 0 0 -0 0</acceleration>
          <wrench>0 0 0 0 -0 0</wrench>
        </link>
        <link name='link_06'>
          <pose>-2.60982 0.004241 0.153917 -1.57047 0.754851 -0.008919</pose>
          <velocity>0 0 0 0 -0 0</velocity>
          <acceleration>0 0 0 0 -0 0</acceleration>
          <wrench>0 0 0 0 -0 0</wrench>
        </link>
        <link name='link_07'>
          <pose>-2.47895 0.003073 0.030907 -1.57046 -0.801649 -0.009384</pose>
          <velocity>0 0 0 0 -0 0</velocity>
          <acceleration>0 0 0 0 -0 0</acceleration>
          <wrench>0 0 0 0 -0 0</wrench>
        </link>
        <link name='link_08'>
          <pose>-2.35595 0.001918 0.161776 1.56317 -1.53994 3.14008</pose>
          <velocity>0 0 0 0 -0 0</velocity>
          <acceleration>0 0 0 0 -0 0</acceleration>
          <wrench>0 0 0 0 -0 0</wrench>
        </link>
        <link name='link_09'>
          <pose>-2.36213 0.001928 0.36168 1.56317 -1.53994 3.14008</pose>
          <velocity>0 0 0 0 -0 0</velocity>
          <acceleration>0 0 0 0 -0 0</acceleration>
          <wrench>0 0 0 0 -0 0</wrench>
        </link>
        <link name='link_10'>
          <pose>-2.36832 0.001937 0.561584 1.56317 -1.53994 3.14008</pose>
          <velocity>0 0 0 0 -0 0</velocity>
          <acceleration>0 0 0 0 -0 0</acceleration>
          <wrench>0 0 0 0 -0 0</wrench>
        </link>
        <link name='link_11'>
          <pose>-2.37451 0.001947 0.761488 1.56317 -1.53994 3.14008</pose>
          <velocity>0 0 0 0 -0 0</velocity>
          <acceleration>0 0 0 0 -0 0</acceleration>
          <wrench>0 0 0 0 -0 0</wrench>
        </link>
        <link name='link_12'>
          <pose>-2.3807 0.001956 0.961393 1.56317 -1.53994 3.14008</pose>
          <velocity>0 0 0 0 -0 0</velocity>
          <acceleration>0 0 0 0 -0 0</acceleration>
          <wrench>0 0 0 0 -0 0</wrench>
        </link>
        <link name='link_13'>
          <pose>-2.38689 0.001966 1.1613 -1.57045 -0.816149 -0.009391</pose>
          <velocity>0 0 0 0 -0 0</velocity>
          <acceleration>0 0 0 0 -0 0</acceleration>
          <wrench>0 0 0 0 -0 0</wrench>
        </link>
        <link name='link_14'>
          <pose>-2.26388 0.000811 1.29217 -1.57047 0.754851 -0.008919</pose>
          <velocity>0 0 0 0 -0 0</velocity>
          <acceleration>0 0 0 0 -0 0</acceleration>
          <wrench>0 0 0 0 -0 0</wrench>
        </link>
        <link name='link_15'>
          <pose>-2.13302 -0.000357 1.16916 -1.56319 1.53985 -0.001538</pose>
          <velocity>0 0 0 0 -0 0</velocity>
          <acceleration>0 0 0 0 -0 0</acceleration>
          <wrench>0 0 0 0 -0 0</wrench>
        </link>
        <link name='link_16'>
          <pose>-2.12683 -0.000366 0.969251 -1.56319 1.53985 -0.001538</pose>
          <velocity>0 0 0 0 -0 0</velocity>
          <acceleration>0 0 0 0 -0 0</acceleration>
          <wrench>0 0 0 0 -0 0</wrench>
        </link>
        <link name='link_17'>
          <pose>-2.12064 -0.000376 0.769347 -1.56319 1.53985 -0.001538</pose>
          <velocity>0 0 0 0 -0 0</velocity>
          <acceleration>0 0 0 0 -0 0</acceleration>
          <wrench>0 0 0 0 -0 0</wrench>
        </link>
        <link name='link_18'>
          <pose>-2.11446 -0.000385 0.569443 -1.56319 1.53985 -0.001538</pose>
          <velocity>0 0 0 0 -0 0</velocity>
          <acceleration>0 0 0 0 -0 0</acceleration>
          <wrench>0 0 0 0 -0 0</wrench>
        </link>
        <link name='link_19'>
          <pose>-2.10827 -0.000395 0.369539 -1.56319 1.53985 -0.001538</pose>
          <velocity>0 0 0 0 -0 0</velocity>
          <acceleration>0 0 0 0 -0 0</acceleration>
          <wrench>0 0 0 0 -0 0</wrench>
        </link>
        <link name='nozzle'>
          <pose>-2.10208 -0.000404 0.169634 1.56321 -1.53976 3.14003</pose>
          <velocity>0 0 0 0 -0 0</velocity>
          <acceleration>0 0 0 0 -0 0</acceleration>
          <wrench>0 0 0 0 -0 0</wrench>
        </link>
      </model>
      <model name='ground_plane'>
        <pose>0 0 0 0 -0 0</pose>
        <link name='link'>
          <pose>0 0 0 0 -0 0</pose>
          <velocity>0 0 0 0 -0 0</velocity>
          <acceleration>0 0 0 0 -0 0</acceleration>
          <wrench>0 0 0 0 -0 0</wrench>
        </link>
      </model>
      <model name='lab_with_windows_2'>
        <pose>0 0 0 0 -0 0</pose>
        <link name='link'>
          <pose>0 0 0 0 -0 0</pose>
          <velocity>0 0 0 0 -0 0</velocity>
          <acceleration>0 0 0 0 -0 0</acceleration>
          <wrench>0 0 0 0 -0 0</wrench>
        </link>
      </model>
      <model name='lumber_2x4x48'>
        <pose>-3.54201 -2.90202 0.043241 0 -0 0</pose>
        <link name='link'>
          <pose>-3.54201 -2.90202 0.043241 0 -0 0</pose>
          <velocity>0 0 0 0 -0 0</velocity>
          <acceleration>0 0 0 0 -0 0</acceleration>
          <wrench>0 0 0 0 -0 0</wrench>
        </link>
      </model>
      <model name='lumber_2x4x48_1'>
        <pose>-4.16505 -2.69657 0.042115 0 -0 1.5707</pose>
        <link name='link'>
          <pose>-4.16505 -2.69657 0.042115 0 -0 1.5707</pose>
          <velocity>0 0 0 0 -0 0</velocity>
          <acceleration>0 0 0 0 -0 0</acceleration>
          <wrench>0 0 0 0 -0 0</wrench>
        </link>
      </model>
    </state>
    <model name='lab_with_windows_2'>
      <static>1</static>
      <link name='link'>
        <inertial>
          <mass>1000</mass>
        </inertial>
        <collision name='collision'>
          <geometry>
            <mesh>
              <uri>model://lab_with_windows/meshes/lab_with_windows.stl</uri>
            </mesh>
          </geometry>
          <max_contacts>10</max_contacts>
          <surface>
            <bounce/>
            <friction>
              <ode/>
            </friction>
            <contact>
              <ode/>
            </contact>
          </surface>
        </collision>
        <visual name='visual'>
          <geometry>
            <mesh>
              <uri>model://lab_with_windows/meshes/lab_with_windows.stl</uri>
            </mesh>
          </geometry>
          <material>
            <script>
              <name>Gazebo/Black</name>
              <uri>__default__</uri>
            </script>
          </material>
          <transparency>0</transparency>
        </visual>
        <velocity_decay>
          <linear>0</linear>
          <angular>0</angular>
        </velocity_decay>
        <self_collide>0</self_collide>
        <kinematic>0</kinematic>
        <gravity>0</gravity>
      </link>
      <pose>0 0 0 0 -0 0</pose>
    </model>
    <gui fullscreen='0'>
      <camera name='user_camera'>
        <pose>0.076768 -0.575988 1.97906 0 0.405797 -3.10316</pose>
        <view_controller>orbit</view_controller>
      </camera>
    </gui>
    <model name='eur_pallet'>
      <static>1</static>
      <link name='link'>
        <inertial>
          <mass>22</mass>
        </inertial>
        <collision name='collision'>
          <geometry>
            <mesh>
              <uri>model://eur_pallet/meshes/eur_pallet.stl</uri>
            </mesh>
          </geometry>
          <max_contacts>10</max_contacts>
          <surface>
            <bounce/>
            <friction>
              <ode/>
            </friction>
            <contact>
              <ode/>
            </contact>
          </surface>
        </collision>
        <visual name='visual'>
          <geometry>
            <mesh>
              <uri>model://eur_pallet/meshes/eur_pallet.stl</uri>
            </mesh>
          </geometry>
          <material>
            <script>
              <name>Gazebo/Wood</name>
              <uri>__default__</uri>
            </script>
          </material>
        </visual>
        <velocity_decay>
          <linear>0</linear>
          <angular>0</angular>
        </velocity_decay>
        <self_collide>0</self_collide>
        <kinematic>0</kinematic>
        <gravity>1</gravity>
      </link>
      <pose>-3.59316 0 0 0 -0 0</pose>
    </model>
    <model name='eur_pallet_0'>
      <static>1</static>
      <link name='link'>
        <inertial>
          <mass>22</mass>
        </inertial>
        <collision name='collision'>
          <geometry>
            <mesh>
              <uri>model://eur_pallet/meshes/eur_pallet.stl</uri>
            </mesh>
          </geometry>
          <max_contacts>10</max_contacts>
          <surface>
            <bounce/>
            <friction>
              <ode/>
            </friction>
            <contact>
              <ode/>
            </contact>
          </surface>
        </collision>
        <visual name='visual'>
          <geometry>
            <mesh>
              <uri>model://eur_pallet/meshes/eur_pallet.stl</uri>
            </mesh>
          </geometry>
          <material>
            <script>
              <name>Gazebo/Wood</name>
              <uri>__default__</uri>
            </script>
          </material>
        </visual>
        <velocity_decay>
          <linear>0</linear>
          <angular>0</angular>
        </velocity_decay>
        <self_collide>0</self_collide>
        <kinematic>0</kinematic>
        <gravity>1</gravity>
      </link>
      <pose>-3.59929 0.424868 0 0 -0 0</pose>
    </model>
    <model name='eur_pallet_1'>
      <static>1</static>
      <link name='link'>
        <inertial>
          <mass>22</mass>
        </inertial>
        <collision name='collision'>
          <geometry>
            <mesh>
              <uri>model://eur_pallet/meshes/eur_pallet.stl</uri>
            </mesh>
          </geometry>
          <max_contacts>10</max_contacts>
          <surface>
            <bounce/>
            <friction>
              <ode/>
            </friction>
            <contact>
              <ode/>
            </contact>
          </surface>
        </collision>
        <visual name='visual'>
          <geometry>
            <mesh>
              <uri>model://eur_pallet/meshes/eur_pallet.stl</uri>
            </mesh>
          </geometry>
          <material>
            <script>
              <name>Gazebo/Wood</name>
              <uri>__default__</uri>
            </script>
          </material>
        </visual>
        <velocity_decay>
          <linear>0</linear>
          <angular>0</angular>
        </velocity_decay>
        <self_collide>0</self_collide>
        <kinematic>0</kinematic>
        <gravity>1</gravity>
      </link>
      <pose>-4 -1.40087 0 0 -0 0</pose>
    </model>
    <model name='eur_pallet_2'>
      <static>1</static>
      <link name='link'>
        <inertial>
          <mass>22</mass>
        </inertial>
        <collision name='collision'>
          <geometry>
            <mesh>
              <uri>model://eur_pallet/meshes/eur_pallet.stl</uri>
            </mesh>
          </geometry>
          <max_contacts>10</max_contacts>
          <surface>
            <bounce/>
            <friction>
              <ode/>
            </friction>
            <contact>
              <ode/>
            </contact>
          </surface>
        </collision>
        <visual name='visual'>
          <geometry>
            <mesh>
              <uri>model://eur_pallet/meshes/eur_pallet.stl</uri>
            </mesh>
          </geometry>
          <material>
            <script>
              <name>Gazebo/Wood</name>
              <uri>__default__</uri>
            </script>
          </material>
        </visual>
        <velocity_decay>
          <linear>0</linear>
          <angular>0</angular>
        </velocity_decay>
        <self_collide>0</self_collide>
        <kinematic>0</kinematic>
        <gravity>1</gravity>
      </link>
      <pose>-3.5746 -1 0 0 -0 0</pose>
    </model>
    <model name='lumber_2x4x48'>
      <link name='link'>
        <inertial>
          <mass>1.4111</mass>
          <inertia>
            <ixx>0.0011</ixx>
            <ixy>0</ixy>
            <ixz>0</ixz>
            <iyy>0.1771</iyy>
            <iyz>0</iyz>
            <izz>0.1763</izz>
          </inertia>
        </inertial>
        <collision name='collision'>
          <geometry>
            <box>
              <size>1.2192 0.038 0.0888</size>
            </box>
          </geometry>
          <surface>
            <bounce>
              <restitution_coefficient>0.01</restitution_coefficient>
              <threshold>5</threshold>
            </bounce>
            <friction>
              <ode>
                <mu>5</mu>
                <mu2>5</mu2>
              </ode>
            </friction>
            <contact>
              <ode>
                <soft_cfm>0.001</soft_cfm>
                <soft_erp>0.2</soft_erp>
                <kp>10000</kp>
                <kd>1000</kd>
                <max_vel>0.01</max_vel>
                <min_depth>0.001</min_depth>
              </ode>
            </contact>
          </surface>
          <max_contacts>10</max_contacts>
        </collision>
        <visual name='visual'>
          <geometry>
            <mesh>
              <uri>model://drc_practice_2x4/meshes/2x4x48.dae</uri>
            </mesh>
          </geometry>
        </visual>
        <velocity_decay>
          <linear>0</linear>
          <angular>0</angular>
        </velocity_decay>
        <self_collide>0</self_collide>
        <kinematic>0</kinematic>
        <gravity>1</gravity>
      </link>
      <pose>-3.54399 -2.59925 0 0 -0 0</pose>
      <static>1</static>
    </model>
    <model name='lumber_2x4x48_1'>
      <link name='link'>
        <inertial>
          <mass>1.4111</mass>
          <inertia>
            <ixx>0.0011</ixx>
            <ixy>0</ixy>
            <ixz>0</ixz>
            <iyy>0.1771</iyy>
            <iyz>0</iyz>
            <izz>0.1763</izz>
          </inertia>
        </inertial>
        <collision name='collision'>
          <geometry>
            <box>
              <size>1.2192 0.038 0.0888</size>
            </box>
          </geometry>
          <surface>
            <bounce>
              <restitution_coefficient>0.01</restitution_coefficient>
              <threshold>5</threshold>
            </bounce>
            <friction>
              <ode>
                <mu>5</mu>
                <mu2>5</mu2>
              </ode>
            </friction>
            <contact>
              <ode>
                <soft_cfm>0.001</soft_cfm>
                <soft_erp>0.2</soft_erp>
                <kp>10000</kp>
                <kd>1000</kd>
                <max_vel>0.01</max_vel>
                <min_depth>0.001</min_depth>
              </ode>
            </contact>
          </surface>
          <max_contacts>10</max_contacts>
        </collision>
        <visual name='visual'>
          <geometry>
            <mesh>
              <uri>model://drc_practice_2x4/meshes/2x4x48.dae</uri>
            </mesh>
          </geometry>
        </visual>
        <velocity_decay>
          <linear>0</linear>
          <angular>0</angular>
        </velocity_decay>
        <self_collide>0</self_collide>
        <kinematic>0</kinematic>
        <gravity>1</gravity>
      </link>
      <pose>-3.53769 -2.52113 0 0 -0 0</pose>
      <static>1</static>
    </model>
  </world>
</sdf>
