<sdf version='1.4'>
  <world name='default'>
    <light name='sun' type='directional'>
      <cast_shadows>1</cast_shadows>
      <pose>-1 -1 1.5 0 -0 0</pose>
      <diffuse>0.8 0.8 0.8 1</diffuse>
      <specular>0.2 0.2 0.2 1</specular>
      <attenuation>
        <range>1000</range>
        <constant>0.9</constant>
        <linear>0.01</linear>
        <quadratic>0.001</quadratic>
      </attenuation>
      <direction>-0.5 0 -1</direction>
    </light>
    <model name='ground_plane'>
      <static>1</static>
      <link name='link'>
        <collision name='collision'>
          <geometry>
            <plane>
              <normal>0 0 1</normal>
              <size>100 100</size>
            </plane>
          </geometry>
          <surface>
            <friction>
              <ode>
                <mu>100</mu>
                <mu2>50</mu2>
              </ode>
            </friction>
            <bounce/>
            <contact>
              <ode/>
            </contact>
          </surface>
          <max_contacts>10</max_contacts>
        </collision>
        <visual name='visual'>
          <cast_shadows>0</cast_shadows>
          <geometry>
            <plane>
              <normal>0 0 1</normal>
              <size>100 100</size>
            </plane>
          </geometry>
          <material>
            <script>
              <uri>file://media/materials/scripts/gazebo.material</uri>
              <name>Gazebo/Black</name>
            </script>
          </material>
        </visual>
        <velocity_decay>
          <linear>0</linear>
          <angular>0</angular>
        </velocity_decay>
        <self_collide>0</self_collide>
        <kinematic>0</kinematic>
        <gravity>0</gravity>
      </link>
    </model>
    <physics type='ode'>
      <max_step_size>0.1</max_step_size>
      <real_time_factor>1</real_time_factor>
      <real_time_update_rate>10</real_time_update_rate>
      <max_contacts>3</max_contacts>
      <gravity>0 0 -9.8</gravity>
      <ode>
        <solver>
          <min_step_size>0.1</min_step_size>
          <iters>1</iters>
        </solver>
      </ode>
    </physics>
    <scene>
      <ambient>0.4 0.4 0.4 1</ambient>
      <background>0.7 0.7 0.7 1</background>
      <shadows>1</shadows>
    </scene>
    <gui fullscreen='0'>
      <camera name='user_camera'>
        <pose>2.9235 -2.24042 1.50694 0 0.214049 2.44715</pose>
        <view_controller>orbit</view_controller>
      </camera>
    </gui>
    <state world_name='default'>
      <sim_time>2701 945000000</sim_time>
      <real_time>2846 716447021</real_time>
      <wall_time>1418431473 133681294</wall_time>
      <model name='dot_grid'>
        <pose>0.002252 0.309368 1.22 0 1.5707 0</pose>
        <link name='link'>
          <pose>0.002252 0.309368 1.22 0 1.5707 0</pose>
          <velocity>0 0 0 0 -0 0</velocity>
          <acceleration>0 0 0 0 -0 0</acceleration>
          <wrench>0 0 0 0 -0 0</wrench>
        </link>
      </model>
      <model name='dot_grid_0'>
        <pose>0.308878 0.002476 1.22 0.000572 -1.5707 1.57013</pose>
        <link name='link'>
          <pose>0.308878 0.002476 1.22 0.000572 -1.5707 1.57013</pose>
          <velocity>0 0 0 0 -0 0</velocity>
          <acceleration>0 0 0 0 -0 0</acceleration>
          <wrench>0 0 0 0 -0 0</wrench>
        </link>
      </model>
      <model name='dot_grid_1'>
        <pose>0.908878 -0.000314 1.22 0.000572 -1.5707 1.57013</pose>
        <link name='link'>
          <pose>0.908878 -0.000314 1.22 0.000572 -1.5707 1.57013</pose>
          <velocity>0 0 0 0 -0 0</velocity>
          <acceleration>0 0 0 0 -0 0</acceleration>
          <wrench>0 0 0 0 -0 0</wrench>
        </link>
      </model>
      <model name='dot_grid_2'>
        <pose>1.50888 -0.000314 1.22 0.000572 -1.5707 1.57013</pose>
        <link name='link'>
          <pose>1.50888 -0.000314 1.22 0.000572 -1.5707 1.57013</pose>
          <velocity>0 0 0 0 -0 0</velocity>
          <acceleration>0 0 0 0 -0 0</acceleration>
          <wrench>0 0 0 0 -0 0</wrench>
        </link>
      </model>
      <model name='dot_grid_3'>
        <pose>2.10888 -0.000314 1.22 0.000572 -1.5707 1.57013</pose>
        <link name='link'>
          <pose>2.10888 -0.000314 1.22 0.000572 -1.5707 1.57013</pose>
          <velocity>0 0 0 0 -0 0</velocity>
          <acceleration>0 0 0 0 -0 0</acceleration>
          <wrench>0 0 0 0 -0 0</wrench>
        </link>
      </model>
      <model name='fire_extinguisher_drawing'>
        <pose>-1.503 0.380286 1.37 -0.000425 -1.5707 -3.1415</pose>
        <link name='link'>
          <pose>-1.503 0.380286 1.37 -0.000425 -1.5707 -3.1415</pose>
          <velocity>0 0 0 0 -0 0</velocity>
          <acceleration>0 0 0 0 -0 0</acceleration>
          <wrench>0 0 0 0 -0 0</wrench>
        </link>
      </model>
      <model name='fire_hose_reel'>
        <pose>-2.07295 0.003277 1.62 0.000283 -1.57079 1.57108</pose>
        <link name='link'>
          <pose>-2.07295 0.003277 1.62 0.000283 -1.57079 1.57108</pose>
          <velocity>0 0 0 0 -0 0</velocity>
          <acceleration>0 0 0 0 -0 0</acceleration>
          <wrench>0 0 0 0 -0 0</wrench>
        </link>
      </model>
      <model name='gball'>
        <pose>1.01522 -1.42786 -0.1 0 -0 2.60318</pose>
        <link name='arm_1_link'>
          <pose>0.929364 -1.37658 0.5447 3.14159 -0 2.60318</pose>
          <velocity>0 0 0 0 -0 0</velocity>
          <acceleration>0 0 0 0 -0 0</acceleration>
          <wrench>0 0 0 0 -0 0</wrench>
        </link>
        <link name='arm_2_link'>
          <pose>0.929364 -1.37658 0.5447 -1.57079 -0 2.60318</pose>
          <velocity>0 0 0 0 -0 0</velocity>
          <acceleration>0 0 0 0 -0 0</acceleration>
          <wrench>0 0 0 0 -0 0</wrench>
        </link>
        <link name='arm_3_link'>
          <pose>0.931081 -1.37761 0.896 -3.14159 1.57079 -2.10921</pose>
          <velocity>0 0 0 0 -0 0</velocity>
          <acceleration>0 0 0 0 -0 0</acceleration>
          <wrench>0 0 0 0 -0 0</wrench>
        </link>
        <link name='arm_4_link'>
          <pose>0.931081 -1.37761 0.896 1.57079 -1.57079 1.03239</pose>
          <velocity>0 0 0 0 -0 0</velocity>
          <acceleration>0 0 0 0 -0 0</acceleration>
          <wrench>0 0 0 0 -0 0</wrench>
        </link>
        <link name='arm_5_link'>
          <pose>0.62592 -1.18393 0.896 -1.5708 -0 -0.5385</pose>
          <velocity>0 0 0 0 -0 0</velocity>
          <acceleration>0 0 0 0 -0 0</acceleration>
          <wrench>0 0 0 0 -0 0</wrench>
        </link>
        <link name='arm_6_link'>
          <pose>0.62592 -1.18393 0.896 3.1415 -0 2.60318</pose>
          <velocity>0 0 0 0 -0 0</velocity>
          <acceleration>0 0 0 0 -0 0</acceleration>
          <wrench>0 0 0 0 -0 0</wrench>
        </link>
        <link name='base_footprint'>
          <pose>1.01522 -1.42786 -0.1 0 -0 2.60318</pose>
          <velocity>0 0 0 0 -0 0</velocity>
          <acceleration>0 0 0 0 -0 0</acceleration>
          <wrench>0 0 0 0 -0 0</wrench>
        </link>
        <link name='camera_pan_link'>
          <pose>0.860682 -1.33556 0.35 0 -0 2.60318</pose>
          <velocity>0 0 0 0 -0 0</velocity>
          <acceleration>0 0 0 0 -0 0</acceleration>
          <wrench>0 0 0 0 -0 0</wrench>
        </link>
        <link name='camera_tilt_link'>
          <pose>0.860682 -1.33556 0.35 0 -0 2.60318</pose>
          <velocity>0 0 0 0 -0 0</velocity>
          <acceleration>0 0 0 0 -0 0</acceleration>
          <wrench>0 0 0 0 -0 0</wrench>
        </link>
        <link name='projector'>
          <pose>0.62592 -1.18393 1 0 -0 2.60318</pose>
          <velocity>0 0 0 0 -0 0</velocity>
          <acceleration>0 0 0 0 -0 0</acceleration>
          <wrench>0 0 0 0 -0 0</wrench>
        </link>
      </model>
      <model name='ground_plane'>
        <pose>0 0 0 0 -0 0</pose>
        <link name='link'>
          <pose>0 0 0 0 -0 0</pose>
          <velocity>0 0 0 0 -0 0</velocity>
          <acceleration>0 0 0 0 -0 0</acceleration>
          <wrench>0 0 0 0 -0 0</wrench>
        </link>
      </model>
      <model name='lab_with_windows_2'>
        <pose>0 0 0 0 -0 0</pose>
        <link name='link'>
          <pose>0 0 0 0 -0 0</pose>
          <velocity>0 0 0 0 -0 0</velocity>
          <acceleration>0 0 0 0 -0 0</acceleration>
          <wrench>0 0 0 0 -0 0</wrench>
        </link>
      </model>
      <model name='wall_pipe'>
        <pose>0.001361 0.806656 1.78 1.5707 -5.55112e-17 -1.5707</pose>
        <link name='link'>
          <pose>0.001361 0.806656 1.78 1.5707 -5.55112e-17 -1.5707</pose>
          <velocity>0 0 0 0 -0 0</velocity>
          <acceleration>0 0 0 0 -0 0</acceleration>
          <wrench>0 0 0 0 -0 0</wrench>
        </link>
      </model>
    </state>
    <model name='lab_with_windows_2'>
      <static>1</static>
      <link name='link'>
        <inertial>
          <mass>1000</mass>
        </inertial>
        <visual name='visual'>
          <geometry>
            <mesh>
              <uri>model://lab_with_windows/meshes/lab_with_windows.stl</uri>
            </mesh>
          </geometry>
          <material>
            <script>
              <uri>file://media/materials/scripts/gazebo.material</uri>
              <name>Gazebo/Black</name>
            </script>
          </material>
          <transparency>0</transparency>
        </visual>
        <velocity_decay>
          <linear>0</linear>
          <angular>0</angular>
        </velocity_decay>
        <self_collide>0</self_collide>
        <kinematic>0</kinematic>
        <gravity>0</gravity>
      </link>
      <pose>0 0 0 0 -0 0</pose>
    </model>
    <model name='fire_hose_reel'>
      <static>1</static>
      <link name='link'>
        <pose>0 0 0 0 -0 0</pose>
        <visual name='visual'>
          <geometry>
            <box>
              <size>1.763 0.732 0.007</size>
            </box>
          </geometry>
          <material>
            <script>
              <uri>model://fire_hose_reel/materials/scripts</uri>
              <uri>model://fire_hose_reel/materials/textures</uri>
              <name>fire_hose_reel</name>
            </script>
          </material>
        </visual>
        <velocity_decay>
          <linear>0</linear>
          <angular>0</angular>
        </velocity_decay>
        <self_collide>0</self_collide>
        <kinematic>0</kinematic>
        <gravity>0</gravity>
      </link>
      <pose>-2.85 -2.09 0.59 0 -0 0</pose>
    </model>
    <model name='fire_extinguisher_drawing'>
      <static>1</static>
      <link name='link'>
        <pose>0 0 0 0 -0 0</pose>
        <visual name='visual'>
          <cast_shadows>0</cast_shadows>
          <geometry>
            <box>
              <size>0.63 0.27 0.007</size>
            </box>
          </geometry>
          <material>
            <script>
              <uri>model://fire_extinguisher_drawing/materials/scripts</uri>
              <uri>model://fire_extinguisher_drawing/materials/textures</uri>
              <name>fire_extinguisher_drawing</name>
            </script>
          </material>
        </visual>
        <velocity_decay>
          <linear>0</linear>
          <angular>0</angular>
        </velocity_decay>
        <self_collide>0</self_collide>
        <kinematic>0</kinematic>
        <gravity>1</gravity>
      </link>
    </model>
    <model name='dot_grid'>
      <static>1</static>
      <link name='link'>
        <pose>0 0 0 0 -0 0</pose>
        <visual name='visual'>
          <cast_shadows>0</cast_shadows>
          <geometry>
            <box>
              <size>2.4 0.6 0.007</size>
            </box>
          </geometry>
          <material>
            <script>
              <uri>model://dot_grid/materials/scripts</uri>
              <uri>model://dot_grid/materials/textures</uri>
              <name>dot_grid</name>
            </script>
          </material>
        </visual>
        <velocity_decay>
          <linear>0</linear>
          <angular>0</angular>
        </velocity_decay>
        <self_collide>0</self_collide>
        <kinematic>0</kinematic>
        <gravity>1</gravity>
      </link>
    </model>
    <model name='dot_grid_0'>
      <static>1</static>
      <link name='link'>
        <pose>0 0 0 0 -0 0</pose>
        <visual name='visual'>
          <cast_shadows>0</cast_shadows>
          <geometry>
            <box>
              <size>2.4 0.6 0.007</size>
            </box>
          </geometry>
          <material>
            <script>
              <uri>model://dot_grid/materials/scripts</uri>
              <uri>model://dot_grid/materials/textures</uri>
              <name>dot_grid</name>
            </script>
          </material>
        </visual>
        <velocity_decay>
          <linear>0</linear>
          <angular>0</angular>
        </velocity_decay>
        <self_collide>0</self_collide>
        <kinematic>0</kinematic>
        <gravity>1</gravity>
      </link>
      <pose>2 -1 0 0 -0 0</pose>
    </model>
    <model name='dot_grid_1'>
      <static>1</static>
      <link name='link'>
        <pose>0 0 0 0 -0 0</pose>
        <visual name='visual'>
          <cast_shadows>0</cast_shadows>
          <geometry>
            <box>
              <size>2.4 0.6 0.007</size>
            </box>
          </geometry>
          <material>
            <script>
              <uri>model://dot_grid/materials/scripts</uri>
              <uri>model://dot_grid/materials/textures</uri>
              <name>dot_grid</name>
            </script>
          </material>
        </visual>
        <velocity_decay>
          <linear>0</linear>
          <angular>0</angular>
        </velocity_decay>
        <self_collide>0</self_collide>
        <kinematic>0</kinematic>
        <gravity>1</gravity>
      </link>
    </model>
    <model name='dot_grid_2'>
      <static>1</static>
      <link name='link'>
        <pose>0 0 0 0 -0 0</pose>
        <visual name='visual'>
          <cast_shadows>0</cast_shadows>
          <geometry>
            <box>
              <size>2.4 0.6 0.007</size>
            </box>
          </geometry>
          <material>
            <script>
              <uri>model://dot_grid/materials/scripts</uri>
              <uri>model://dot_grid/materials/textures</uri>
              <name>dot_grid</name>
            </script>
          </material>
        </visual>
        <velocity_decay>
          <linear>0</linear>
          <angular>0</angular>
        </velocity_decay>
        <self_collide>0</self_collide>
        <kinematic>0</kinematic>
        <gravity>1</gravity>
      </link>
    </model>
    <model name='dot_grid_3'>
      <static>1</static>
      <link name='link'>
        <pose>0 0 0 0 -0 0</pose>
        <visual name='visual'>
          <cast_shadows>0</cast_shadows>
          <geometry>
            <box>
              <size>2.4 0.6 0.007</size>
            </box>
          </geometry>
          <material>
            <script>
              <uri>model://dot_grid/materials/scripts</uri>
              <uri>model://dot_grid/materials/textures</uri>
              <name>dot_grid</name>
            </script>
          </material>
        </visual>
        <velocity_decay>
          <linear>0</linear>
          <angular>0</angular>
        </velocity_decay>
        <self_collide>0</self_collide>
        <kinematic>0</kinematic>
        <gravity>1</gravity>
      </link>
    </model>
    <model name='wall_pipe'>
      <static>1</static>
      <link name='link'>
        <inertial>
          <mass>10</mass>
        </inertial>
        <visual name='visual'>
          <transparency>0.2</transparency>
          <geometry>
            <mesh>
              <uri>model://wall_pipe/meshes/wall_pipe.stl</uri>
            </mesh>
          </geometry>
        </visual>
        <velocity_decay>
          <linear>0</linear>
          <angular>0</angular>
        </velocity_decay>
        <self_collide>0</self_collide>
        <kinematic>0</kinematic>
        <gravity>1</gravity>
      </link>
    </model>
    <model name='gball'>
      <static>1</static>
      <link name='base_footprint'>
        <pose>0 0 0 0 -0 0</pose>
        <inertial>
          <pose>0.000487957 0 0.181407 0 -0 0</pose>
          <mass>97.8957</mass>
          <inertia>
            <ixx>3.91766</ixx>
            <ixy>0.008</ixy>
            <ixz>-0.159941</ixz>
            <iyy>8.51815</iyy>
            <iyz>-0.004</iyz>
            <izz>9.03139</izz>
          </inertia>
        </inertial>
        <collision name='base_footprint_collision'>
          <pose>0 0 0 0 -0 0</pose>
          <geometry>
            <box>
              <size>0.001 0.001 0.001</size>
            </box>
          </geometry>
          <surface>
            <contact>
              <ode/>
            </contact>
            <friction>
              <ode/>
            </friction>
            <bounce/>
          </surface>
          <max_contacts>10</max_contacts>
        </collision>
        <collision name='base_footprint_collision_arm_0_link'>
          <pose>0.1 0 0.555 3.14159 -0 0</pose>
          <geometry>
            <mesh>
              <scale>1 1 1</scale>
              <uri>model://gball/meshes/powerball0.stl</uri>
            </mesh>
          </geometry>
          <surface>
            <contact>
              <ode/>
            </contact>
            <friction>
              <ode/>
            </friction>
            <bounce/>
          </surface>
          <surface>
            <contact>
              <ode/>
            </contact>
            <friction>
              <ode/>
            </friction>
          </surface>
          <max_contacts>10</max_contacts>
        </collision>
        <collision name='base_footprint_collision_base_link'>
          <pose>0 0 0.18 0 -0 0</pose>
          <geometry>
            <mesh>
              <scale>1 1 1</scale>
              <uri>model://gball/meshes/chassisV6.stl</uri>
            </mesh>
          </geometry>
          <surface>
            <contact>
              <ode/>
            </contact>
            <friction>
              <ode/>
            </friction>
            <bounce/>
          </surface>
          <surface>
            <contact>
              <ode/>
            </contact>
            <friction>
              <ode/>
            </friction>
          </surface>
          <max_contacts>10</max_contacts>
        </collision>
        <collision name='base_footprint_collision_imu_link'>
          <pose>0 0 0.4625 0 -0 0</pose>
          <geometry>
            <box>
              <size>0.001 0.001 0.001</size>
            </box>
          </geometry>
          <surface>
            <contact>
              <ode/>
            </contact>
            <friction>
              <ode/>
            </friction>
            <bounce/>
          </surface>
          <max_contacts>10</max_contacts>
        </collision>
        <collision name='base_footprint_collision_left_track'>
          <pose>0 0 0.18 0 -0 0</pose>
          <geometry>
            <mesh>
              <scale>1 1 1</scale>
              <uri>model://gball/meshes/trackV5_l.stl</uri>
            </mesh>
          </geometry>
          <surface>
            <contact>
              <ode/>
            </contact>
            <friction>
              <ode/>
            </friction>
            <bounce/>
          </surface>
          <surface>
            <contact>
              <ode/>
            </contact>
            <friction>
              <ode/>
            </friction>
          </surface>
          <surface>
            <contact>
              <ode/>
            </contact>
            <friction>
              <ode/>
            </friction>
          </surface>
          <max_contacts>10</max_contacts>
        </collision>
        <collision name='base_footprint_collision_right_track'>
          <pose>0 0 0.18 0 -0 3.14159</pose>
          <geometry>
            <mesh>
              <scale>1 1 1</scale>
              <uri>model://gball/meshes/trackV5_l.stl</uri>
            </mesh>
          </geometry>
          <surface>
            <contact>
              <ode/>
            </contact>
            <friction>
              <ode/>
            </friction>
            <bounce/>
          </surface>
          <surface>
            <contact>
              <ode/>
            </contact>
            <friction>
              <ode/>
            </friction>
          </surface>
          <surface>
            <contact>
              <ode/>
            </contact>
            <friction>
              <ode/>
            </friction>
          </surface>
          <max_contacts>10</max_contacts>
        </collision>
        <visual name='base_footprint_visual'>
          <pose>0 0 0 0 -0 0</pose>
          <geometry>
            <box>
              <size>0.001 0.001 0.001</size>
            </box>
          </geometry>
          <material>
            <script>
              <name>Gazebo/Green</name>
              <uri>__default__</uri>
            </script>
          </material>
        </visual>
        <visual name='base_footprint_visual_arm_0_link'>
          <pose>0.1 0 0.555 3.14159 -0 0</pose>
          <geometry>
            <mesh>
              <scale>1 1 1</scale>
              <uri>model://gball/meshes/powerball0.stl</uri>
            </mesh>
          </geometry>
          <material>
            <script>
              <name>Gazebo/Grey</name>
              <uri>__default__</uri>
            </script>
          </material>
        </visual>
        <visual name='base_footprint_visual_base_link'>
          <pose>0 0 0.18 0 -0 0</pose>
          <geometry>
            <mesh>
              <scale>1 1 1</scale>
              <uri>model://gball/meshes/chassisV6.stl</uri>
            </mesh>
          </geometry>
          <material>
            <script>
              <name>Gazebo/DarkGrey</name>
              <uri>__default__</uri>
            </script>
          </material>
        </visual>
        <visual name='base_footprint_visual_imu_link'>
          <pose>0 0 0.4625 0 -0 0</pose>
          <geometry>
            <box>
              <size>0.001 0.001 0.001</size>
            </box>
          </geometry>
        </visual>
        <visual name='base_footprint_visual_left_track'>
          <pose>0 0 0.18 0 -0 0</pose>
          <geometry>
            <mesh>
              <scale>1 1 1</scale>
              <uri>model://gball/meshes/trackV5_l.stl</uri>
            </mesh>
          </geometry>
          <material>
            <script>
              <name>Gazebo/FlatBlack</name>
              <uri>__default__</uri>
            </script>
          </material>
          <material>
            <script>
              <name>Gazebo/FlatBlack</name>
              <uri>__default__</uri>
            </script>
          </material>
        </visual>
        <visual name='base_footprint_visual_right_track'>
          <pose>0 0 0.18 0 -0 3.14159</pose>
          <geometry>
            <mesh>
              <scale>1 1 1</scale>
              <uri>model://gball/meshes/trackV5_l.stl</uri>
            </mesh>
          </geometry>
          <material>
            <script>
              <name>Gazebo/FlatBlack</name>
              <uri>__default__</uri>
            </script>
          </material>
          <material>
            <script>
              <name>Gazebo/FlatBlack</name>
              <uri>__default__</uri>
            </script>
          </material>
        </visual>
        <velocity_decay>
          <linear>0</linear>
          <angular>0</angular>
        </velocity_decay>
        <velocity_decay>
          <linear>0</linear>
          <angular>0</angular>
        </velocity_decay>
        <velocity_decay>
          <linear>0</linear>
          <angular>0</angular>
        </velocity_decay>
        <velocity_decay>
          <linear>0</linear>
          <angular>0</angular>
        </velocity_decay>
        <sensor name='base_hokuyo_sensor' type='ray'>
          <visualize>0</visualize>
          <update_rate>10</update_rate>
          <ray>
            <scan>
              <horizontal>
                <samples>684</samples>
                <resolution>1</resolution>
                <min_angle>-2.0944</min_angle>
                <max_angle>2.0944</max_angle>
              </horizontal>
            </scan>
            <range>
              <min>0.1</min>
              <max>5</max>
              <resolution>0.001</resolution>
            </range>
            <noise>
              <type>gaussian</type>
              <mean>0</mean>
              <stddev>0.01</stddev>
            </noise>
          </ray>
          <pose>0.49 0 0.41 0 -0 0</pose>
        </sensor>
        <velocity_decay>
          <linear>0</linear>
          <angular>0</angular>
        </velocity_decay>
        <velocity_decay>
          <linear>0</linear>
          <angular>0</angular>
        </velocity_decay>
        <gravity>1</gravity>
        <velocity_decay>
          <linear>0</linear>
          <angular>0</angular>
        </velocity_decay>
        <gravity>1</gravity>
        <velocity_decay>
          <linear>0</linear>
          <angular>0</angular>
        </velocity_decay>
        <self_collide>0</self_collide>
        <kinematic>0</kinematic>
      </link>
      <link name='arm_1_link'>
        <pose>0.1 4.807e-09 0.6447 3.14159 -0 0</pose>
        <inertial>
          <pose>0 0 0 0 -0 0</pose>
          <mass>0.29364</mass>
          <inertia>
            <ixx>0.01</ixx>
            <ixy>0</ixy>
            <ixz>0</ixz>
            <iyy>0.01</iyy>
            <iyz>0</iyz>
            <izz>0.01</izz>
          </inertia>
        </inertial>
        <collision name='arm_1_link_collision'>
          <pose>0 0 0 0 -0 0</pose>
          <geometry>
            <mesh>
              <scale>1 1 1</scale>
              <uri>model://gball/meshes/powerball1.stl</uri>
            </mesh>
          </geometry>
          <surface>
            <contact>
              <ode/>
            </contact>
            <friction>
              <ode/>
            </friction>
            <bounce/>
          </surface>
          <max_contacts>10</max_contacts>
        </collision>
        <visual name='arm_1_link_visual'>
          <pose>0 0 0 0 -0 0</pose>
          <geometry>
            <mesh>
              <scale>1 1 1</scale>
              <uri>model://gball/meshes/powerball1.stl</uri>
            </mesh>
          </geometry>
          <material>
            <script>
              <name>Gazebo/Grey</name>
              <uri>__default__</uri>
            </script>
          </material>
        </visual>
        <gravity>1</gravity>
        <velocity_decay>
          <linear>0</linear>
          <angular>0</angular>
        </velocity_decay>
        <self_collide>0</self_collide>
        <gravity>1</gravity>
        <kinematic>0</kinematic>
      </link>
      <joint name='arm_1_joint' type='revolute'>
        <child>arm_1_link</child>
        <parent>base_footprint</parent>
        <axis>
          <xyz>0 0 1</xyz>
          <limit>
            <lower>-6.28319</lower>
            <upper>6.28319</upper>
            <effort>370</effort>
            <velocity>2</velocity>
          </limit>
          <dynamics>
            <damping>10</damping>
          </dynamics>
        </axis>
      </joint>
      <link name='arm_2_link'>
        <pose>0.1 4.807e-09 0.6447 -1.57079 0 0</pose>
        <inertial>
          <pose>0 0 0 0 -0 0</pose>
          <mass>1.68311</mass>
          <inertia>
            <ixx>0.03</ixx>
            <ixy>0</ixy>
            <ixz>0</ixz>
            <iyy>0.03</iyy>
            <iyz>0</iyz>
            <izz>0.03</izz>
          </inertia>
        </inertial>
        <collision name='arm_2_link_collision'>
          <pose>0 0 0 0 -0 0</pose>
          <geometry>
            <mesh>
              <scale>1 1 1</scale>
              <uri>model://gball/meshes/powerball2.stl</uri>
            </mesh>
          </geometry>
          <surface>
            <contact>
              <ode/>
            </contact>
            <friction>
              <ode/>
            </friction>
            <bounce/>
          </surface>
          <max_contacts>10</max_contacts>
        </collision>
        <visual name='arm_2_link_visual'>
          <pose>0 0 0 0 -0 0</pose>
          <geometry>
            <mesh>
              <scale>1 1 1</scale>
              <uri>model://gball/meshes/powerball2.stl</uri>
            </mesh>
          </geometry>
          <material>
            <ambient>0 0.13 0.28 1</ambient>
            <diffuse>0 0.13 0.28 1</diffuse>
            <specular>0 0.13 0.28 1</specular>
            <emissive>0 0 0 0</emissive>
          </material>
        </visual>
        <gravity>1</gravity>
        <velocity_decay>
          <linear>0</linear>
          <angular>0</angular>
        </velocity_decay>
        <self_collide>0</self_collide>
        <gravity>1</gravity>
        <kinematic>0</kinematic>
      </link>
      <joint name='arm_2_joint' type='revolute'>
        <child>arm_2_link</child>
        <parent>arm_1_link</parent>
        <axis>
          <xyz>0 -1 -4e-06</xyz>
          <limit>
            <lower>-2.0944</lower>
            <upper>2.0944</upper>
            <effort>370</effort>
            <velocity>2</velocity>
          </limit>
          <dynamics>
            <damping>10</damping>
          </dynamics>
        </axis>
      </joint>
      <link name='arm_3_link'>
        <pose>0.098 0 0.996 -3.14159 1.57079 1.57079</pose>
        <inertial>
          <pose>0 0 0 0 -0 0</pose>
          <mass>2.1</mass>
          <inertia>
            <ixx>0.03</ixx>
            <ixy>0</ixy>
            <ixz>0</ixz>
            <iyy>0.03</iyy>
            <iyz>0</iyz>
            <izz>0.03</izz>
          </inertia>
        </inertial>
        <collision name='arm_3_link_collision'>
          <pose>0 0 0 0 -0 0</pose>
          <geometry>
            <mesh>
              <scale>1 1 1</scale>
              <uri>model://gball/meshes/powerball3.stl</uri>
            </mesh>
          </geometry>
          <surface>
            <contact>
              <ode/>
            </contact>
            <friction>
              <ode/>
            </friction>
            <bounce/>
          </surface>
          <max_contacts>10</max_contacts>
        </collision>
        <visual name='arm_3_link_visual'>
          <pose>0 0 0 0 -0 0</pose>
          <geometry>
            <mesh>
              <scale>1 1 1</scale>
              <uri>model://gball/meshes/powerball3.stl</uri>
            </mesh>
          </geometry>
          <material>
            <script>
              <name>Gazebo/Grey</name>
              <uri>__default__</uri>
            </script>
          </material>
        </visual>
        <gravity>1</gravity>
        <velocity_decay>
          <linear>0</linear>
          <angular>0</angular>
        </velocity_decay>
        <self_collide>0</self_collide>
        <gravity>1</gravity>
        <kinematic>0</kinematic>
      </link>
      <joint name='arm_3_joint' type='revolute'>
        <child>arm_3_link</child>
        <parent>arm_2_link</parent>
        <axis>
          <xyz>0 1 1e-06</xyz>
          <limit>
            <lower>-6.28319</lower>
            <upper>6.28319</upper>
            <effort>176</effort>
            <velocity>2</velocity>
          </limit>
          <dynamics>
            <damping>5</damping>
          </dynamics>
        </axis>
      </joint>
      <link name='arm_4_link'>
        <pose>0.098 0 0.996 1.57079 -1.57079 -1.57079</pose>
        <inertial>
          <pose>0 0 0 0 -0 0</pose>
          <mass>1.68311</mass>
          <inertia>
            <ixx>0.03</ixx>
            <ixy>0</ixy>
            <ixz>0</ixz>
            <iyy>0.03</iyy>
            <iyz>0</iyz>
            <izz>0.03</izz>
          </inertia>
        </inertial>
        <collision name='arm_4_link_collision'>
          <pose>0 0 0 0 -0 0</pose>
          <geometry>
            <mesh>
              <scale>1 1 1</scale>
              <uri>model://gball/meshes/powerball4_robotnik.stl</uri>
            </mesh>
          </geometry>
          <surface>
            <contact>
              <ode/>
            </contact>
            <friction>
              <ode/>
            </friction>
            <bounce/>
          </surface>
          <max_contacts>10</max_contacts>
        </collision>
        <visual name='arm_4_link_visual'>
          <pose>0 0 0 0 -0 0</pose>
          <geometry>
            <mesh>
              <scale>1 1 1</scale>
              <uri>model://gball/meshes/powerball4_robotnik.stl</uri>
            </mesh>
          </geometry>
          <material>
            <ambient>0 0.13 0.28 1</ambient>
            <diffuse>0 0.13 0.28 1</diffuse>
            <specular>0 0.13 0.28 1</specular>
            <emissive>0 0 0 0</emissive>
          </material>
        </visual>
        <gravity>1</gravity>
        <velocity_decay>
          <linear>0</linear>
          <angular>0</angular>
        </velocity_decay>
        <self_collide>0</self_collide>
        <gravity>1</gravity>
        <kinematic>0</kinematic>
      </link>
      <joint name='arm_4_joint' type='revolute'>
        <child>arm_4_link</child>
        <parent>arm_3_link</parent>
        <axis>
          <xyz>0 -3e-06 -1</xyz>
          <limit>
            <lower>-2.0944</lower>
            <upper>2.0944</upper>
            <effort>176</effort>
            <velocity>2</velocity>
          </limit>
          <dynamics>
            <damping>5</damping>
          </dynamics>
        </axis>
      </joint>
      <link name='arm_5_link'>
        <pose>0.4593 -0.0098 0.996 -1.5708 -0 3.1415</pose>
        <inertial>
          <pose>0 0 0 0 -0 0</pose>
          <mass>0.807</mass>
          <inertia>
            <ixx>0.03</ixx>
            <ixy>0</ixy>
            <ixz>0</ixz>
            <iyy>0.03</iyy>
            <iyz>0</iyz>
            <izz>0.03</izz>
          </inertia>
        </inertial>
        <collision name='arm_5_link_collision'>
          <pose>0 0 0 0 -0 0</pose>
          <geometry>
            <mesh>
              <scale>1 1 1</scale>
              <uri>model://gball/meshes/powerball5.stl</uri>
            </mesh>
          </geometry>
          <surface>
            <contact>
              <ode/>
            </contact>
            <friction>
              <ode/>
            </friction>
            <bounce/>
          </surface>
          <max_contacts>10</max_contacts>
        </collision>
        <visual name='arm_5_link_visual'>
          <pose>0 0 0 0 -0 0</pose>
          <geometry>
            <mesh>
              <scale>1 1 1</scale>
              <uri>model://gball/meshes/powerball5.stl</uri>
            </mesh>
          </geometry>
          <material>
            <script>
              <name>Gazebo/Grey</name>
              <uri>__default__</uri>
            </script>
          </material>
        </visual>
        <gravity>1</gravity>
        <velocity_decay>
          <linear>0</linear>
          <angular>0</angular>
        </velocity_decay>
        <self_collide>0</self_collide>
        <gravity>1</gravity>
        <kinematic>0</kinematic>
      </link>
      <joint name='arm_5_joint' type='revolute'>
        <child>arm_5_link</child>
        <parent>arm_4_link</parent>
        <axis>
          <xyz>3e-06 1 -6e-06</xyz>
          <limit>
            <lower>-6.28319</lower>
            <upper>6.28319</upper>
            <effort>41.6</effort>
            <velocity>2</velocity>
          </limit>
          <dynamics>
            <damping>5</damping>
          </dynamics>
        </axis>
      </joint>
      <link name='arm_6_link'>
        <pose>0.4593 -0.0098 0.996 3.1415 -0 0</pose>
        <inertial>
          <pose>0 0 0 0 -0 0</pose>
          <mass>0.819</mass>
          <inertia>
            <ixx>0.01</ixx>
            <ixy>0</ixy>
            <ixz>0</ixz>
            <iyy>0.01</iyy>
            <iyz>0</iyz>
            <izz>0.01</izz>
          </inertia>
        </inertial>
        <collision name='arm_6_link_collision'>
          <pose>0 0 0 0 -0 0</pose>
          <geometry>
            <mesh>
              <scale>1 1 1</scale>
              <uri>model://gball/meshes/powerball6.stl</uri>
            </mesh>
          </geometry>
          <surface>
            <contact>
              <ode/>
            </contact>
            <friction>
              <ode/>
            </friction>
            <bounce/>
          </surface>
          <max_contacts>10</max_contacts>
        </collision>
        <visual name='arm_6_link_visual'>
          <pose>0 0 0 0 -0 0</pose>
          <geometry>
            <mesh>
              <scale>1 1 1</scale>
              <uri>model://gball/meshes/powerball6.stl</uri>
            </mesh>
          </geometry>
          <material>
            <ambient>0 0.13 0.28 1</ambient>
            <diffuse>0 0.13 0.28 1</diffuse>
            <specular>0 0.13 0.28 1</specular>
            <emissive>0 0 0 0</emissive>
          </material>
        </visual>
        <gravity>1</gravity>
        <velocity_decay>
          <linear>0</linear>
          <angular>0</angular>
        </velocity_decay>
        <self_collide>0</self_collide>
        <gravity>1</gravity>
        <kinematic>0</kinematic>
      </link>
      <joint name='arm_6_joint' type='revolute'>
        <child>arm_6_link</child>
        <parent>arm_5_link</parent>
        <axis>
          <xyz>0 3e-06 1</xyz>
          <limit>
            <lower>-2.0944</lower>
            <upper>2.0944</upper>
            <effort>20.1</effort>
            <velocity>2</velocity>
          </limit>
          <dynamics>
            <damping>5</damping>
          </dynamics>
        </axis>
      </joint>
      <link name='projector'>
        <pose>0.4593 -0.0098 1.1 0 -0 0</pose>
        <inertial>
          <pose>0 0 0 0 -0 0</pose>
          <mass>2</mass>
          <inertia>
            <ixx>0.01</ixx>
            <ixy>0</ixy>
            <ixz>0</ixz>
            <iyy>0.01</iyy>
            <iyz>0</iyz>
            <izz>0.01</izz>
          </inertia>
        </inertial>
        <collision name='collision'>
          <pose>0 0 0 0 -0 0</pose>
          <geometry>
            <mesh>
              <scale>1 1 1</scale>
              <uri>model://gball/meshes/asus_b1m.stl</uri>
            </mesh>
          </geometry>
          <surface>
            <contact>
              <ode/>
            </contact>
            <friction>
              <ode/>
            </friction>
            <bounce/>
          </surface>
          <max_contacts>10</max_contacts>
        </collision>
        <visual name='visual'>
          <pose>0 0 0 0 -0 0</pose>
          <geometry>
            <mesh>
              <scale>1 1 1</scale>
              <uri>model://gball/meshes/asus_b1m.stl</uri>
            </mesh>
          </geometry>
          <material>
            <script>
              <name>Gazebo/DarkGrey</name>
              <uri>__default__</uri>
            </script>
          </material>
        </visual>
        <gravity>1</gravity>
        <velocity_decay>
          <linear>0</linear>
          <angular>0</angular>
        </velocity_decay>
        <self_collide>0</self_collide>
        <gravity>1</gravity>
        <kinematic>0</kinematic>
      </link>
      <link name='camera_pan_link'>
        <pose>0.18 0 0.45 0 -0 0</pose>
        <inertial>
          <pose>0 0 0 0 -0 0</pose>
          <mass>0.1</mass>
          <inertia>
            <ixx>0.1</ixx>
            <ixy>0</ixy>
            <ixz>0</ixz>
            <iyy>0.1</iyy>
            <iyz>0</iyz>
            <izz>0.1</izz>
          </inertia>
        </inertial>
        <velocity_decay>
          <linear>0</linear>
          <angular>0</angular>
        </velocity_decay>
        <self_collide>0</self_collide>
        <kinematic>0</kinematic>
        <gravity>1</gravity>
      </link>
      <joint name='joint_camera_pan' type='revolute'>
        <child>camera_pan_link</child>
        <parent>base_footprint</parent>
        <axis>
          <xyz>0 0 1</xyz>
          <limit>
            <lower>-1e+16</lower>
            <upper>1e+16</upper>
          </limit>
          <dynamics/>
        </axis>
      </joint>
      <link name='camera_tilt_link'>
        <pose>0.18 0 0.45 0 -0 0</pose>
        <inertial>
          <pose>0 0 0 0 -0 0</pose>
          <mass>0.1</mass>
          <inertia>
            <ixx>0.1</ixx>
            <ixy>0</ixy>
            <ixz>0</ixz>
            <iyy>0.1</iyy>
            <iyz>0</iyz>
            <izz>0.1</izz>
          </inertia>
        </inertial>
        <velocity_decay>
          <linear>0</linear>
          <angular>0</angular>
        </velocity_decay>
        <self_collide>0</self_collide>
        <kinematic>0</kinematic>
        <gravity>1</gravity>
      </link>
      <joint name='joint_camera_tilt' type='revolute'>
        <child>camera_tilt_link</child>
        <parent>camera_pan_link</parent>
        <axis>
          <xyz>0 1 0</xyz>
          <limit>
            <lower>-1e+16</lower>
            <upper>1e+16</upper>
          </limit>
          <dynamics/>
        </axis>
      </joint>
      <pose>0.403429 -1.41352 0.15 0 -0 0</pose>
    </model>
  </world>
</sdf>
